Workbook

Sheet JAN25
C1: LGSP - Lufthansa Ground Services Portugal NIF : 509 842 593 Atividade: CAE 52230.R3 Sede e local de trabalho: Avenida da Boavista ED.Burgo, 1837 sala 13.1 Horario de Funcionamento: 24/7 IRT: Não Aplicável
A2: Hubs Services | C2: Janeiro | AI2: Ferias 2024 | AM2: Ferias 2025
C3: Qua | D3: Qui | E3: Sex | F3: Sab | G3: Dom | H3: Seg | I3: Ter | J3: Qua | K3: Qui | L3: Sex | M3: Sab | N3: Dom | O3: Seg | P3: Ter | Q3: Qua | R3: Qui | S3: Sex | T3: Sab | U3: Dom | V3: Seg | W3: Ter | X3: Qua | Y3: Qui | Z3: Sex | AA3: Sab | AB3: Dom | AC3: Seg | AD3: Ter | AE3: Qua | AF3: Qui | AG3: Sex | AI3: 2024 | AJ3: Used | AK3: LEFT | AM3: 2025 | AN3: Used | AO3: LEFT
A4: NOME | B4: NOME GENESYS | C4: 1 | D4: 2 | E4: 3 | F4: 4 | G4: 5 | H4: 6 | I4: 7 | J4: 8 | K4: 9 | L4: 10 | M4: 11 | N4: 12 | O4: 13 | P4: 14 | Q4: 15 | R4: 16 | S4: 17 | T4: 18 | U4: 19 | V4: 20 | W4: 21 | X4: 22 | Y4: 23 | Z4: 24 | AA4: 25 | AB4: 26 | AC4: 27 | AD4: 28 | AE4: 29 | AF4: 30 | AG4: 31
A5: Diana Reisinho | B5: REISINHO, DIANA | C5: K | D5: K | E5: K | F5: K | G5: K | H5: K | I5: K | J5: K | K5: K | L5: K | M5: K | N5: K | O5: K | P5: K | Q5: K | R5: K | S5: K | T5: K | U5: K | V5: K | W5: K | X5: K | Y5: K | Z5: K | AA5: K | AB5: K | AC5: K | AD5: K | AE5: K | AF5: K | AG5: K | AI5: 3 | AJ5: =COUNTIF(C5:AG5,"UA") -> 0 | AK5: =AI5-AJ5 -> 3 | AM5: 22 | AN5: =COUNTIF(C5:AG5,"U") -> 0 | AO5: =AM5-AN5 -> 22
A6: Catarina Ferreira | B6: FERREIRA, CATARINA | C6: P06 | D6: F | E6: F | F6: K | G6: K | H6: P14 | I6: P14 | J6: F | K6: F | L6: P06 | M6: P06 | N6: P06 | O6: P06 | P6: F | Q6: F | R6: P14 | S6: P14 | T6: F | U6: F | V6: TR-P08 | W6: TR-P08 | X6: TR-P08 | Y6: K | Z6: F | AA6: F | AB6: P06 | AC6: P06 | AD6: P06 | AE6: P06 | AF6: P14 | AG6: F | AI6: 0 | AJ6: =COUNTIF(C6:AG6,"UA") -> 0 | AK6: =AI6-AJ6 -> 0 | AM6: 19 | AN6: =COUNTIF(C6:AG6,"U") -> 0 | AO6: =AM6-AN6 -> 19
A7: João Santos Silva | B7: SANTOS SILVA, JOAO | E7: F | F7: F | G7: F | H7: K | I7: K | J7: K | K7: K | L7: K | M7: K | N7: K | O7: K | P7: K | Q7: K | R7: K | S7: K | T7: K | U7: K | V7: K | W7: K | X7: F | Y7: F | Z7: P06 | AA7: P06 | AB7: P06 | AC7: P06 | AD7: F | AE7: F | AF7: P06 | AG7: P06 | AI7: 0 | AJ7: =COUNTIF(C7:AG7,"UA") -> 0 | AK7: =AI7-AJ7 -> 0 | AM7: 22 | AN7: =COUNTIF(C7:AG7,"U") -> 0 | AO7: =AM7-AN7 -> 22
A8: Ana Magalhães | B8: MAGALHAES, ANA CATARINA | C8: H | D8: F | E8: F | F8: UA | G8: UA | H8: P14 | I8: P14 | J8: F | K8: F | L8: P06 | M8: P06 | N8: P06 | O8: P06 | P8: F | Q8: F | R8: P14 | S8: P14 | T8: P14 | U8: P14 | V8: F | W8: F | X8: P06 | Y8: P06 | Z8: P06 | AA8: P06 | AB8: F | AC8: F | AD8: P06 | AE8: P06 | AF8: P06 | AG8: P06 | AI8: 2 | AJ8: =COUNTIF(C8:AG8,"UA") -> 2 | AK8: =AI8-AJ8 -> 0 | AM8: 23 | AN8: =COUNTIF(C8:AG8,"U") -> 0 | AO8: =AM8-AN8 -> 23
A9: Jorge Gonçalves | B9: GONCALVES, JORGE | C9: F | D9: P06 | E9: P06 | F9: P06 | G9: P06 | H9: F | I9: F | J9: P14 | K9: P14 | L9: P14 | M9: P14 | N9: F | O9: F | P9: P06 | Q9: P06 | R9: P06 | S9: P06 | T9: F | U9: F | V9: P14 | W9: P14 | X9: P14 | Y9: U | Z9: F | AA9: F | AB9: U | AC9: U | AD9: U | AE9: U | AF9: F | AG9: F | AI9: 0 | AJ9: =COUNTIF(C9:AG9,"UA") -> 0 | AK9: =AI9-AJ9 -> 0 | AM9: 22 | AN9: =COUNTIF(C9:AG9,"U") -> 5 | AO9: =AM9-AN9 -> 17
A10: Catarina Pereira | B10: PEREIRA, CATARINA | C10: P14 | D10: P14 | E10: P14 | F10: F | G10: F | H10: P06 | I10: P06 | J10: P06 | K10: P06 | L10: F | M10: F | N10: P14 | O10: P14 | P10: P14 | Q10: P14 | R10: P14 | S10: F | T10: F | U10: P06 | V10: P06 | W10: P06 | X10: F | Y10: F | Z10: P14 | AA10: P14 | AB10: P14 | AC10: P14 | AD10: F | AE10: F | AF10: P06 | AG10: P06 | AI10: 0 | AJ10: =COUNTIF(C10:AG10,"UA") -> 0 | AK10: =AI10-AJ10 -> 0 | AM10: 22 | AN10: =COUNTIF(C10:AG10,"U") -> 0 | AO10: =AM10-AN10 -> 22
A11: Sara Medeiros | B11: MEDEIROS, SARA | C11: F | D11: P14 | E11: P14 | F11: P14 | G11: S3 | H11: P14 | I11: F | J11: F | K11: TR-P08/ | L11: TR-P07 | M11: P06 | N11: P06 | O11: P06 | P11: F | Q11: F | R11: P14 | S11: P14 | T11: P09 | U11: P14 | V11: F | W11: F | X11: P06 | Y11: P06 | Z11: P06 | AA11: P06 | AB11: F | AC11: F | AD11: P14 | AE11: P14 | AF11: P14 | AG11: P14 | AI11: 0 | AJ11: =COUNTIF(C11:AG11,"UA") -> 0 | AK11: =AI11-AJ11 -> 0 | AM11: 22 | AN11: =COUNTIF(C11:AG11,"U") -> 0 | AO11: =AM11-AN11 -> 22
A12: Catia Martins | B12: MARTINS, CATIA | C12: F | D12: P06 | E12: P06 | F12: P06 | G12: P14 | H12: F | I12: F | J12: P14 | K12: P14 | L12: P14 | M12: P14 | N12: F | O12: F | P12: P06 | Q12: P06 | R12: P06 | S12: P09 | T12: F | U12: F | V12: P14 | W12: P14 | X12: P14 | Y12: P14 | Z12: F | AA12: F | AB12: P14 | AC12: P14 | AD12: P14 | AE12: P14 | AF12: F | AG12: F | AI12: 0 | AJ12: =COUNTIF(C12:AG12,"UA") -> 0 | AK12: =AI12-AJ12 -> 0 | AM12: 22 | AN12: =COUNTIF(C12:AG12,"U") -> 0 | AO12: =AM12-AN12 -> 22
A14: INAD HUBs RST
A15: Cristiana Ferreira | B15: FERREIRA, CRISTIANA MARGARIDA | C15: H | D15: UA | E15: UA | F15: F | G15: F | H15: P09/ | I15: P09/ | J15: P09/ | K15: P09/ | L15: P09/ | M15: F | N15: F | O15: P09/ | P15: P09/ | Q15: K1 | R15: K1 | S15: K1 | T15: F | U15: F | V15: TR-P08 | W15: TR-P08 | X15: TR-P08 | Y15: TR-P08 | Z15: H06 | AA15: F | AB15: F | AC15: P09/ | AD15: P09/ | AE15: P09/ | AF15: P09/ | AG15: P09/ | AI15: 4 | AJ15: 2 | AK15: =AI15-AJ15 -> 2 | AM15: 22 | AN15: =COUNTIF(C15:AG15,"U") -> 0 | AO15: =AM15-AN15 -> 22
A16: Tiago Abreu | B16: ABREU, TIAGO | C16: H | D16: F | E16: P06 | F16: P14 | G16: P14 | H16: F | I16: P06 | J16: P06 | K16: P14 | L16: P14 | M16: F | N16: F | O16: S3 | P16: B | Q16: P14 | R16: P14 | S16: F | T16: F | U16: P06 | V16: P06 | W16: P14 | X16: P14 | Y16: F | Z16: F | AA16: P14 | AB16: P14 | AC16: P14 | AD16: P14 | AE16: F | AF16: F | AG16: U | AI16: 0 | AJ16: =COUNTIF(C16:AG16,"UA") -> 0 | AK16: =AI16-AJ16 -> 0 | AM16: 22 | AN16: =COUNTIF(C16:AG16,"U") -> 1 | AO16: =AM16-AN16 -> 21
A17: Maria Burca | B17: BURCA, MARIA | C17: H | D17: P06 | E17: F | F17: P06 | G17: P06 | H17: P06 | I17: F | J17: F | K17: P06 | L17: P06 | M17: P14 | N17: P14 | O17: F | P17: F | Q17: P06 | R17: P06 | S17: P06 | T17: P06 | U17: F | V17: F | W17: P06 | X17: P06 | Y17: P14 | Z17: S3 | AA17: F | AB17: F | AC17: P06 | AD17: P06 | AE17: P06 | AF17: P06 | AG17: F | AI17: 1 | AJ17: =COUNTIF(C17:AG17,"UA") -> 0 | AK17: =AI17-AJ17 -> 1 | AM17: 23 | AN17: =COUNTIF(C17:AG17,"U") -> 0 | AO17: =AM17-AN17 -> 23
A18: Catarina Mendes | B18: MENDES, CATARINA | C18: P10M | D18: P10M | E18: P10M | F18: F | G18: F | H18: P10M | I18: P10M | J18: P10M | K18: TR-P10/ | L18: TR-P10/ | M18: F | N18: F | O18: P10M | P18: P10M | Q18: F | R18: F | S18: P10M | T18: K | U18: P10M | V18: P10M | W18: F | X18: F | Y18: P10M | Z18: P10M | AA18: P10M | AB18: P10M | AC18: F | AD18: F | AE18: P10M | AF18: P10M | AG18: P10M | AI18: 0 | AJ18: =COUNTIF(C18:AG18,"UA") -> 0 | AK18: =AI18-AJ18 -> 0 | AM18: 22 | AN18: =COUNTIF(C18:AG18,"U") -> 0 | AO18: =AM18-AN18 -> 22
A20: RST Team
A21: Diana Salome Sousa | B21: SOUSA, DIANA SALOME | C21: P06 | D21: P06 | E21: P06 | F21: F | G21: F | H21: UA | I21: UA | J21: UA | K21: UA | L21: F | M21: F | N21: P06 | O21: P06 | P21: P06 | Q21: P06 | R21: F | S21: F | T21: P14 | U21: P14 | V21: P14 | W21: P14 | X21: F | Y21: F | Z21: P06 | AA21: P06 | AB21: P06 | AC21: P06 | AD21: F | AE21: F | AF21: P22 | AG21: P22 | AI21: 4 | AJ21: =COUNTIF(C21:AG21,"ua") -> 4 | AK21: =AI21-AJ21 -> 0 | AM21: 22 | AN21: =COUNTIF(C21:AG21,"U") -> 0 | AO21: =AM21-AN21 -> 22
A22: Ricardo Medeiros | B22: MEDEIROS, RICARDO | C22: H | D22: F | E22: F | F22: P22 | G22: P22 | H22: P22 | I22: P22 | J22: F | K22: F | L22: P14 | M22: P14 | N22: P14 | O22: P14 | P22: F | Q22: F | R22: P06 | S22: P06 | T22: P06 | U22: P06 | V22: F | W22: F | X22: S3 | Y22: P14 | Z22: P14 | AA22: F | AB22: F | AC22: TR-P07 | AD22: TR-P07 | AE22: TR-P07 | AF22: TR-P07 | AG22: TR-P07 | AI22: 2 | AJ22: =COUNTIF(C22:AG22,"ua") -> 0 | AK22: =AI22-AJ22 -> 2 | AM22: 22 | AN22: =COUNTIF(C22:AG22,"U") -> 0 | AO22: =AM22-AN22 -> 22
A23: Ricardo Bessa | B23: BESSA, RICARDO | C23: F | D23: P14 | E23: P14 | F23: P14 | G23: P14 | H23: F | I23: F | J23: P22 | K23: P22 | L23: P22 | M23: P22 | N23: F | O23: F | P23: P14 | Q23: P14 | R23: P14 | S23: P14 | T23: F | U23: F | V23: P06 | W23: P06 | X23: P06 | Y23: P06 | Z23: F | AA23: F | AB23: UA | AC23: TR-P07 | AD23: TR-P07 | AE23: TR-P07 | AF23: TR-P07 | AG23: FINJ | AI23: 1 | AJ23: =COUNTIF(C23:AG23,"ua") -> 1 | AK23: =AI23-AJ23 -> 0 | AM23: 22 | AN23: =COUNTIF(C23:AG23,"U") -> 0 | AO23: =AM23-AN23 -> 22
A24: Samuel Neves | B24: NEVES, SAMUEL | C24: P22 | D24: P22 | E24: P22 | F24: F | G24: F | H24: P14 | I24: P14 | J24: P14 | K24: P14 | L24: F | M24: F | N24: P22 | O24: P22 | P24: P22 | Q24: P22 | R24: F | S24: F | T24: P14 | U24: P14 | V24: P14 | W24: P14 | X24: F | Y24: F | Z24: P06 | AA24: F | AB24: F | AC24: TR-P07 | AD24: TR-P07 | AE24: TR-P07 | AF24: TR-P07 | AG24: TR-P07 | AI24: 7 | AJ24: =COUNTIF(C24:AG24,"ua") -> 0 | AK24: =AI24-AJ24 -> 7 | AM24: 11 | AN24: =COUNTIF(C24:AG24,"U") -> 0 | AO24: =AM24-AN24 -> 11
A25: Carlos Carvalhais | B25: CARVALHAIS, CARLOS | C25: P06 | D25: F | E25: F | F25: P06 | G25: P06 | H25: P06 | I25: P06 | J25: F | K25: F | L25: P14 | M25: P14 | N25: P14 | O25: P14 | P25: F | Q25: F | R25: P22 | S25: P22 | T25: P22 | U25: P22 | V25: F | W25: F | X25: P14 | Y25: P14 | Z25: P14 | AA25: F | AB25: F | AC25: TR-P07 | AD25: TR-P07 | AE25: TR-P07 | AF25: TR-P07 | AG25: TR-P07 | AI25: 0 | AJ25: =COUNTIF(C25:AG25,"ua") -> 0 | AK25: =AI25-AJ25 -> 0 | AM25: 12 | AN25: =COUNTIF(C25:AG25,"U") -> 0 | AO25: =AM25-AN25 -> 12
A26: Alefe Sobral | B26: SOBRAL, ALEFE | C26: F | D26: P14 | E26: P14 | F26: P14 | G26: P14 | H26: F | I26: F | J26: P06 | K26: P06 | L26: P06 | M26: P06 | N26: F | O26: F | P26: P14 | Q26: P14 | R26: P14 | S26: P14 | T26: F | U26: F | V26: P06 | W26: P06 | X26: P06 | Y26: P06 | Z26: FINJ | AA26: F | AB26: F | AC26: TR-P07 | AD26: TR-P07 | AE26: TR-P07 | AF26: TR-P07 | AG26: TR-P07 | AI26: 5 | AJ26: =COUNTIF(C26:AG26,"ua") -> 0 | AK26: =AI26-AJ26 -> 5 | AM26: 10 | AN26: =COUNTIF(C26:AG26,"U") -> 0 | AO26: =AM26-AN26 -> 10
A27: Jose Alves | B27: ALVES, JOSE | C27: H | D27: P06 | E27: P14 | F27: F | G27: F | H27: P14 | I27: P14 | J27: P14 | K27: P14 | L27: F | M27: F | N27: P06 | O27: P06 | P27: P06 | Q27: P06 | R27: F | S27: F | T27: UA | U27: P14 | V27: P14 | W27: P14 | X27: F | Y27: F | Z27: P22 | AA27: P22 | AB27: P22 | AC27: P22 | AD27: F | AE27: F | AF27: P14 | AG27: P14 | AI27: 3 | AJ27: =COUNTIF(C27:AG27,"ua") -> 1 | AK27: =AI27-AJ27 -> 2 | AM27: 22 | AN27: =COUNTIF(C27:AG27,"U") -> 0 | AO27: =AM27-AN27 -> 22
A28: Ines Pilre | B28: PILRE, INES | C28: H | D28: F | E28: F | F28: P06 | G28: P06 | H28: P06 | I28: P06 | J28: F | K28: F | L28: P14 | M28: P14 | N28: P14 | O28: P14 | P28: F | Q28: F | R28: P06 | S28: P06 | T28: P06 | U28: P06 | V28: F | W28: F | X28: P14 | Y28: P14 | Z28: P14 | AA28: P14 | AB28: F | AC28: F | AD28: P22 | AE28: P22 | AF28: P22 | AG28: P22 | AI28: 0 | AJ28: =COUNTIF(C28:AG28,"ua") -> 0 | AK28: =AI28-AJ28 -> 0 | AM28: 22 | AN28: =COUNTIF(C28:AG28,"U") -> 0 | AO28: =AM28-AN28 -> 22
A29: Bruna Lima | B29: LIMA, BRUNA | C29: F | D29: S3 | E29: UA | F29: P06 | G29: P06 | H29: F | I29: F | J29: P06 | K29: P06 | L29: P06 | M29: P06 | N29: F | O29: F | P29: P14 | Q29: P14 | R29: P14 | S29: P14 | T29: F | U29: F | V29: P06 | W29: P06 | X29: P06 | Y29: P06 | Z29: F | AA29: F | AB29: P14 | AC29: P14 | AD29: P14 | AE29: P14 | AF29: F | AG29: F | AI29: 11 | AJ29: =COUNTIF(C29:AG29,"ua") -> 1 | AK29: =AI29-AJ29 -> 10 | AM29: 22 | AN29: =COUNTIF(C29:AG29,"U") -> 0 | AO29: =AM29-AN29 -> 22
A30: Gonçalo Pereira | B30: PEREIRA, GONCALO | C30: P14 | D30: P13 | E30: F | F30: F | G30: S3 | H30: E | I30: P06 | J30: P06 | K30: TR-P08/ | L30: E | M30: F | N30: F | O30: S3 | P30: E | Q30: UA | R30: F | S30: F | T30: P06 | U30: P14 | V30: P14 | W30: P14 | X30: F | Y30: F | Z30: P06 | AA30: P06 | AB30: P06 | AC30: P06 | AD30: F | AE30: F | AF30: P06 | AG30: P06 | AI30: 5 | AJ30: =COUNTIF(C30:AG30,"ua") -> 1 | AK30: =AI30-AJ30 -> 4 | AM30: 22 | AN30: =COUNTIF(C30:AG30,"U") -> 0 | AO30: =AM30-AN30 -> 22
A31: Joana Pinheiro | B31: PINHEIRO, JOANA | C31: H | D31: F | E31: F | F31: P06 | G31: P06 | H31: P06 | I31: P06 | J31: F | K31: F | L31: P22 | M31: P22 | N31: P22 | O31: P22 | P31: F | Q31: F | R31: P06 | S31: P06 | T31: P06 | U31: P06 | V31: F | W31: F | X31: P14 | Y31: P14 | Z31: P14 | AA31: P14 | AB31: F | AC31: F | AD31: P06 | AE31: P06 | AF31: P06 | AG31: P06 | AI31: 0 | AJ31: =COUNTIF(C31:AG31,"ua") -> 0 | AK31: =AI31-AJ31 -> 0 | AM31: 22 | AN31: =COUNTIF(C31:AG31,"U") -> 0 | AO31: =AM31-AN31 -> 22
A32: Inês Coelho | B32: COELHO, INES | C32: F | D32: F | E32: P14 | F32: P14 | G32: P14 | H32: F | I32: F | J32: P06 | K32: TR-P08/ | L32: TR-P07 | M32: P06 | N32: F | O32: F | P32: P22 | Q32: P22 | R32: P22 | S32: P22 | T32: F | U32: F | V32: S3 | W32: K | X32: K | Y32: NO | Z32: F | AA32: F | AB32: P14 | AC32: P14 | AD32: P14 | AE32: P14 | AF32: F | AG32: F | AI32: 2 | AJ32: =COUNTIF(C32:AG32,"ua") -> 0 | AK32: =AI32-AJ32 -> 2 | AM32: 22 | AN32: =COUNTIF(C32:AG32,"U") -> 0 | AO32: =AM32-AN32 -> 22
... A35: Catia Neves | B35: NEVES, CATIA | C35: F | D35: P06 | E35: P06 | F35: P06 | G35: S3 | H35: F | I35: F | J35: P06 | K35: P06 | L35: P06 | M35: P06 | N35: F | O35: F | P35: P14 | Q35: P14 | R35: UA | S35: CM1 | T35: F | U35: F | V35: P22 | W35: P22 | X35: P22 | Y35: P22 | Z35: F | AA35: F | AB35: F | AC35: TR-P07 | AD35: TR-P07 | AE35: TR-P07 | AF35: TR-P07 | AG35: TR-P07 | AI35: 4 | AJ35: =COUNTIF(C35:AG35,"ua") -> 1 | AK35: =AI35-AJ35 -> 3 | AM35: 22 | AN35: =COUNTIF(C35:AG35,"U") -> 0 | AO35: =AM35-AN35 -> 22
A37: Hubs Services Team
A38: Carla Ferreira | B38: FERREIRA, CARLA | C38: P06 | D38: P06 | E38: F | F38: F | G38: P07 | H38: P07 | I38: P07 | J38: P07 | K38: F | L38: F | M38: P22 | N38: P22 | O38: P22 | P38: P22 | Q38: F | R38: F | S38: P13 | T38: P13 | U38: P13 | V38: P13 | W38: F | X38: F | Y38: P07 | Z38: P07 | AA38: P07 | AB38: P07 | AC38: F | AD38: F | AE38: P13 | AF38: P13 | AG38: P13 | AI38: 3 | AJ38: =COUNTIF(C38:AG38,"ua") -> 0 | AK38: =AI38-AJ38 -> 3 | AM38: 22 | AN38: =COUNTIF(C38:AG38,"U") -> 0 | AO38: =AM38-AN38 -> 22
A39: Jorge Costa | B39: COSTA, JORGE | C39: F | D39: F | E39: P05 | F39: P05 | G39: P05 | H39: P05 | I39: F | J39: F | K39: P07 | L39: P07 | M39: P07 | N39: P07 | O39: F | P39: F | Q39: P22 | R39: P22 | S39: P22 | T39: P22 | U39: F | V39: F | W39: P13 | X39: P13 | Y39: P13 | Z39: P13 | AA39: F | AB39: F | AC39: P07 | AD39: P07 | AE39: P07 | AF39: P07 | AG39: F | AI39: 0 | AJ39: =COUNTIF(C39:AG39,"ua") -> 0 | AK39: =AI39-AJ39 -> 0 | AM39: 12 | AN39: =COUNTIF(C39:AG39,"U") -> 0 | AO39: =AM39-AN39 -> 12
A40: Ruben Pinheiro | B40: PINHEIRO, RUBEN | C40: P13 | D40: P13 | E40: P13 | F40: P13 | G40: F | H40: F | I40: P05 | J40: P05 | K40: P05 | L40: P05 | M40: F | N40: F | O40: P07 | P40: P07 | Q40: P07 | R40: P07 | S40: F | T40: F | U40: P22 | V40: P22 | W40: P22 | X40: P22 | Y40: F | Z40: F | AA40: UA | AB40: UA | AC40: UA | AD40: UA | AE40: F | AF40: F | AG40: UA | AI40: 14 | AJ40: =COUNTIF(C40:AG40,"ua") -> 5 | AK40: =AI40-AJ40 -> 9 | AM40: 8 | AN40: =COUNTIF(C40:AG40,"U") -> 0 | AO40: =AM40-AN40 -> 8
A41: Bruna Queiroz | B41: QUEIROZ, BRUNA | C41: APT | D41: APT | E41: APT | F41: APT | G41: APT | H41: APT | I41: APT | J41: APT | K41: APT | L41: APT | M41: F | N41: F | O41: UA | P41: U | Q41: U | R41: S3 | S41: F | T41: F | U41: U | V41: U | W41: U | X41: U | Y41: F | Z41: F | AA41: U | AB41: U | AC41: U | AD41: U | AE41: F | AF41: F | AG41: U | AI41: 1 | AJ41: =COUNTIF(C41:AG41,"ua") -> 1 | AK41: =AI41-AJ41 -> 0 | AM41: 22 | AN41: =COUNTIF(C41:AG41,"U") -> 11 | AO41: =AM41-AN41 -> 11
A42: Ana Ferreira | B42: FERREIRA, ANA SOFIA | O42: TR-P08 | P42: TR-P08 | Q42: TR-P08 | R42: TR-P08 | S42: TR-P08 | T42: F | U42: F | V42: TR-P08 | W42: TR-P08 | X42: TR-P08 | Y42: F | Z42: P07 | AA42: P07 | AB42: P07 | AC42: F | AD42: F | AE42: P13 | AF42: P13 | AG42: P13 | AI42: 3 | AJ42: =COUNTIF(C42:AG42,"ua") -> 0 | AK42: =AI42-AJ42 -> 3 | AM42: 22 | AN42: 0 | AO42: 22
A43: Barbara Pereira | B43: PEREIRA, BARBARA | M43: F | N43: F | O43: TR-P08 | P43: TR-P08 | Q43: TR-P08 | R43: TR-P08 | S43: TR-P08 | T43: F | U43: F | V43: TR-P08 | W43: TR-P08 | X43: TR-P08 | Y43: FINJ | Z43: P07 | AA43: F | AB43: F | AC43: P22 | AD43: P22 | AE43: P22 | AF43: P22 | AG43: F | AI43: 11 | AJ43: =COUNTIF(C43:AG43,"ua") -> 0 | AK43: =AI43-AJ43 -> 11 | AM43: 22 | AN43: =COUNTIF(C43:AG43,"U") -> 0 | AO43: =AM43-AN43 -> 22
A44: Jessica Martins | B44: MARTINS, JESSICA | C44: P22 | D44: P22 | E44: P22 | F44: P22 | G44: F | H44: F | I44: P07 | J44: P07 | K44: P07 | L44: P07 | M44: F | N44: F | O44: P13 | P44: P13 | Q44: P13 | R44: P13 | S44: F | T44: F | U44: P05 | V44: P05 | W44: P05 | X44: P05 | Y44: F | Z44: F | AA44: K | AB44: K | AC44: K | AD44: K | AE44: K | AF44: F | AG44: P22 | AI44: 11 | AJ44: =COUNTIF(C44:AG44,"ua") -> 0 | AK44: =AI44-AJ44 -> 11 | AM44: 11 | AN44: =COUNTIF(C44:AG44,"U") -> 0 | AO44: =AM44-AN44 -> 11
A45: Tiago Mendes | B45: MENDES, TIAGO ANDRE | C45: P06 | D45: P05 | E45: F | F45: F | G45: P22 | H45: P22 | I45: P22 | J45: P22 | K45: P22 | L45: F | M45: F | N45: P07 | O45: S3 | P45: P07 | Q45: F | R45: F | S45: P13 | T45: P13 | U45: P13 | V45: P13 | W45: F | X45: F | Y45: P05 | Z45: P05 | AA45: P05 | AB45: P05 | AC45: F | AD45: F | AE45: P07 | AF45: P07 | AG45: P07 | AI45: 10 | AJ45: =COUNTIF(C45:AG45,"ua") -> 0 | AK45: =AI45-AJ45 -> 10 | AM45: 11 | AN45: =COUNTIF(C45:AG45,"U") -> 0 | AO45: =AM45-AN45 -> 11
...

Sheet FEB25
C1: LGSP - Lufthansa Ground Services Portugal NIF : 509 842 593 Atividade: CAE 52230.R3 Sede e local de trabalho: Avenida da Boavista ED.Burgo, 1837 sala 13.1 Horario de Funcionamento: 24/7 IRT: Não Aplicável
A2: Hubs Services | C2: Fevereiro | AF2: Ferias 2024 | AJ2: Ferias 2025
C3: Sab | D3: Dom | E3: Seg | F3: Ter | G3: Qua | H3: Qui | I3: Sex | J3: Sab | K3: Dom | L3: Seg | M3: Ter | N3: Qua | O3: Qui | P3: Sex | Q3: Sab | R3: Dom | S3: Seg | T3: Ter | U3: Qua | V3: Qui | W3: Sex | X3: Sab | Y3: Dom | Z3: Seg | AA3: Ter | AB3: Qua | AC3: Qui | AD3: Sex | AF3: 2024 | AG3: Used | AH3: LEFT | AJ3: 2025 | AK3: Used | AL3: LEFT
A4: NOME | B4: NOME GENESYS | C4: 1 | D4: 2 | E4: 3 | F4: 4 | G4: 5 | H4: 6 | I4: 7 | J4: 8 | K4: 9 | L4: 10 | M4: 11 | N4: 12 | O4: 13 | P4: 14 | Q4: 15 | R4: 16 | S4: 17 | T4: 18 | U4: 19 | V4: 20 | W4: 21 | X4: 22 | Y4: 23 | Z4: 24 | AA4: 25 | AB4: 26 | AC4: 27 | AD4: 28
A5: Diana Reisinho | B5: REISINHO, DIANA | C5: K | D5: K | E5: K | F5: K | G5: K | H5: K | I5: K | J5: K | K5: K | L5: K | M5: K | N5: K | O5: K | P5: K | Q5: K | R5: K | S5: K | T5: K | U5: K | V5: K | W5: K | X5: K | Y5: K | Z5: K | AA5: K | AB5: K | AC5: K | AD5: K | AF5: =VLOOKUP(B5,'JAN25'!$B:$AO,36,0) -> 3 | AG5: =COUNTIF(C5:AD5,"UA") -> 0 | AH5: =AF5-AG5 -> 3 | AJ5: =VLOOKUP(B5,'JAN25'!$B:$AO,40,0) -> 22 | AK5: =COUNTIF(C5:AD5,"u") -> 0 | AL5: =AJ5-AK5 -> 22
A6: Catarina Ferreira | B6: FERREIRA, CATARINA | C6: F | D6: P06 | E6: P06 | F6: P06 | G6: P06 | H6: P06 | I6: F | J6: F | K6: P14 | L6: P14 | M6: P13 | N6: P08 | O6: F | P6: F | Q6: P09 | R6: CN8 | S6: P09 | T6: P09 | U6: F | V6: F | W6: P14 | X6: P14 | Y6: P14 | Z6: P11 | AA6: F | AB6: F | AC6: P06 | AD6: P06 | AF6: =VLOOKUP(B6,'JAN25'!$B:$AO,36,0) -> 0 | AG6: =COUNTIF(C6:AD6,"UA") -> 0 | AH6: =AF6-AG6 -> 0 | AJ6: =VLOOKUP(B6,'JAN25'!$B:$AO,40,0) -> 19 | AK6: =COUNTIF(C6:AD6,"u") -> 0 | AL6: =AJ6-AK6 -> 19
A7: João Santos Silva | B7: SANTOS SILVA, JOAO | C7: P06 | D7: P06 | E7: F | F7: F | G7: P14 | H7: P14 | I7: P14 | J7: P14 | K7: F | L7: F | M7: P06 | N7: P06 | O7: P06 | P7: P06 | Q7: F | R7: F | S7: S3 | T7: P14 | U7: P14 | V7: P14 | W7: F | X7: F | Y7: P06 | Z7: P06 | AA7: P06 | AB7: P06 | AC7: F | AD7: F | AF7: =VLOOKUP(B7,'JAN25'!$B:$AO,36,0) -> 0 | AG7: =COUNTIF(C7:AD7,"UA") -> 0 | AH7: =AF7-AG7 -> 0 | AJ7: =VLOOKUP(B7,'JAN25'!$B:$AO,40,0) -> 22 | AK7: =COUNTIF(C7:AD7,"u") -> 0 | AL7: =AJ7-AK7 -> 22
A8: Ana Magalhães | B8: MAGALHAES, ANA CATARINA | C8: F | D8: F | E8: P06 | F8: P06 | G8: P06 | H8: P06 | I8: F | J8: F | K8: S3 | L8: P08 | M8: P06 | N8: P14 | O8: F | P8: F | Q8: P06 | R8: P10 | S8: P06 | T8: P06 | U8: F | V8: F | W8: P14 | X8: P14 | Y8: P14 | Z8: P14 | AA8: F | AB8: F | AC8: P06 | AD8: P06 | AF8: =VLOOKUP(B8,'JAN25'!$B:$AO,36,0) -> 0 | AG8: =COUNTIF(C8:AD8,"UA") -> 0 | AH8: =AF8-AG8 -> 0 | AJ8: =VLOOKUP(B8,'JAN25'!$B:$AO,40,0) -> 23 | AK8: =COUNTIF(C8:AD8,"u") -> 0 | AL8: =AJ8-AK8 -> 23
A9: Jorge Gonçalves | B9: GONCALVES, JORGE | C9: U | D9: U | E9: U | F9: U | G9: F | H9: F | I9: U | J9: P06 | K9: P06 | L9: P06 | M9: F | N9: F | O9: P14 | P9: P14 | Q9: P14 | R9: P14 | S9: F | T9: F | U9: P06 | V9: P06 | W9: P05 | X9: P06 | Y9: F | Z9: F | AA9: P14 | AB9: P14 | AC9: P14 | AD9: P14 | AF9: =VLOOKUP(B9,'JAN25'!$B:$AO,36,0) -> 0 | AG9: =COUNTIF(C9:AD9,"UA") -> 0 | AH9: =AF9-AG9 -> 0 | AJ9: =VLOOKUP(B9,'JAN25'!$B:$AO,40,0) -> 17 | AK9: =COUNTIF(C9:AD9,"u") -> 5 | AL9: =AJ9-AK9 -> 12
A10: Catarina Pereira | B10: PEREIRA, CATARINA | C10: P14 | D10: P14 | E10: F | F10: F | G10: P14 | H10: P14 | I10: P14 | J10: P14 | K10: F | L10: F | M10: P06 | N10: P06 | O10: P06 | P10: P06 | Q10: F | R10: F | S10: P14 | T10: P14 | U10: P14 | V10: P14 | W10: F | X10: F | Y10: P06 | Z10: P06 | AA10: P06 | AB10: P06 | AC10: F | AD10: F | AF10: =VLOOKUP(B10,'JAN25'!$B:$AO,36,0) -> 0 | AG10: =COUNTIF(C10:AD10,"UA") -> 0 | AH10: =AF10-AG10 -> 0 | AJ10: =VLOOKUP(B10,'JAN25'!$B:$AO,40,0) -> 22 | AK10: =COUNTIF(C10:AD10,"u") -> 0 | AL10: =AJ10-AK10 -> 22
A11: Sara Medeiros | B11: MEDEIROS, SARA | C11: F | D11: F | E11: P06 | F11: P06 | G11: P06 | H11: P06 | I11: F | J11: F | K11: P14 | L11: P14 | M11: P14 | N11: P14 | O11: F | P11: F | Q11: P06 | R11: P06 | S11: P06 | T11: P06 | U11: F | V11: F | W11: P14 | X11: P14 | Y11: P14 | Z11: P14 | AA11: F | AB11: F | AC11: P06 | AD11: P06 | AF11: =VLOOKUP(B11,'JAN25'!$B:$AO,36,0) -> 0 | AG11: =COUNTIF(C11:AD11,"UA") -> 0 | AH11: =AF11-AG11 -> 0 | AJ11: =VLOOKUP(B11,'JAN25'!$B:$AO,40,0) -> 22 | AK11: =COUNTIF(C11:AD11,"u") -> 0 | AL11: =AJ11-AK11 -> 22
A12: Catia Martins | B12: MARTINS, CATIA | C12: P06 | D12: P06 | E12: P14 | F12: P14 | G12: F | H12: F | I12: P06 | J12: S3 | K12: U | L12: B* | M12: B | N12: F | O12: U | P12: U | Q12: U | R12: U | S12: F | T12: F | U12: P06 | V12: P06 | W12: P06 | X12: P06 | Y12: F | Z12: F | AA12: P14 | AB12: P14 | AC12: P14 | AD12: P14 | AF12: =VLOOKUP(B12,'JAN25'!$B:$AO,36,0) -> 0 | AG12: =COUNTIF(C12:AD12,"UA") -> 0 | AH12: =AF12-AG12 -> 0 | AJ12: =VLOOKUP(B12,'JAN25'!$B:$AO,40,0) -> 22 | AK12: =COUNTIF(C12:AD12,"u") -> 5 | AL12: =AJ12-AK12 -> 17
A14: INAD HUBs RST
A15: Cristiana Ferreira | B15: FERREIRA, CRISTIANA MARGARIDA | C15: F | D15: F | E15: P09/ | F15: P09/ | G15: P09/ | H15: P09/ | I15: P09/ | J15: F | K15: F | L15: P09/ | M15: P09/ | N15: P09/ | O15: P09/ | P15: P09/ | Q15: F | R15: F | S15: P09 | T15: P09 | U15: P09 | V15: P09 | W15: P09/ | X15: F | Y15: F | Z15: P09/ | AA15: H08 | AB15: P09/ | AC15: P09/ | AD15: P09/ | AF15: =VLOOKUP(B15,'JAN25'!$B:$AO,36,0) -> 2 | AG15: =COUNTIF(C15:AD15,"UA") -> 0 | AH15: =AF15-AG15 -> 2 | AJ15: =VLOOKUP(B15,'JAN25'!$B:$AO,40,0) -> 22 | AK15: =COUNTIF(C15:AD15,"U") -> 0 | AL15: =AJ15-AK15 -> 22
A16: Tiago Abreu | B16: ABREU, TIAGO | C16: U | D16: U | E16: U | F16: F | G16: F | H16: U | I16: U | J16: U | K16: U | L16: F | M16: F | N16: U | O16: U | P16: P14 | Q16: P14 | R16: F | S16: F | T16: P12 | U16: P11 | V16: P14 | W16: P14 | X16: F | Y16: F | Z16: P06 | AA16: P06 | AB16: P14 | AC16: P14 | AD16: F | AF16: =VLOOKUP(B16,'JAN25'!$B:$AO,36,0) -> 0 | AG16: =COUNTIF(C16:AD16,"UA") -> 0 | AH16: =AF16-AG16 -> 0 | AJ16: =VLOOKUP(B16,'JAN25'!$B:$AO,40,0) -> 21 | AK16: =COUNTIF(C16:AD16,"U") -> 9 | AL16: =AJ16-AK16 -> 12
A17: Maria Burca | B17: BURCA, MARIA | C17: F | D17: P14 | E17: P14 | F17: P14 | G17: P14 | H17: F | I17: F | J17: P06 | K17: P06 | L17: P06 | M17: P06 | N17: F | O17: F | P17: P06 | Q17: P06 | R17: P14 | S17: P14 | T17: F | U17: F | V17: P06 | W17: P06 | X17: P06 | Y17: P06 | Z17: F | AA17: F | AB17: P06 | AC17: P06 | AD17: P14 | AF17: =VLOOKUP(B17,'JAN25'!$B:$AO,36,0) -> 1 | AG17: =COUNTIF(C17:AD17,"UA") -> 0 | AH17: =AF17-AG17 -> 1 | AJ17: =VLOOKUP(B17,'JAN25'!$B:$AO,40,0) -> 23 | AK17: =COUNTIF(C17:AD17,"U") -> 0 | AL17: =AJ17-AK17 -> 23
A18: Catarina Mendes | B18: MENDES, CATARINA | C18: P10M | D18: F | E18: F | F18: P10M | G18: P10M | H18: P10M | I18: P10M | J18: F | K18: F | L18: P10M | M18: P10M | N18: K | O18: P10M | P18: F | Q18: F | R18: P10M | S18: P10M | T18: P10M | U18: P10M | V18: P10M | W18: F | X18: P10M | Y18: F | Z18: B | AA18: U | AB18: F | AC18: F | AD18: P10M | AF18: =VLOOKUP(B18,'JAN25'!$B:$AO,36,0) -> 0 | AG18: =COUNTIF(C18:AD18,"UA") -> 0 | AH18: =AF18-AG18 -> 0 | AJ18: =VLOOKUP(B18,'JAN25'!$B:$AO,40,0) -> 22 | AK18: =COUNTIF(C18:AD18,"U") -> 1 | AL18: =AJ18-AK18 -> 21
A20: RST Team
A21: Diana Salome Sousa | B21: SOUSA, DIANA SALOME | C21: P22 | D21: P22 | E21: F | F21: F | G21: P14 | H21: P14 | I21: P14 | J21: P14 | K21: F | L21: F | M21: P06 | N21: P06 | O21: P06 | P21: P06 | Q21: F | R21: F | S21: P14 | T21: P14 | U21: P14 | V21: S3 | W21: F | X21: F | Y21: U | Z21: B | AA21: U | AB21: U | AC21: F | AD21: F | AF21: =VLOOKUP(B21,'JAN25'!$B:$AO,36,0) -> 0 | AG21: =COUNTIF(C21:AD21,"UA") -> 0 | AH21: =AF21-AG21 -> 0 | AJ21: =VLOOKUP(B21,'JAN25'!$B:$AO,40,0) -> 22 | AK21: =COUNTIF(C21:AD21,"u") -> 3 | AL21: =AJ21-AK21 -> 19
A22: Ricardo Medeiros | B22: MEDEIROS, RICARDO | C22: F | D22: F | E22: P22 | F22: P22 | G22: P22 | H22: P22 | I22: F | J22: F | K22: P14 | L22: P14 | M22: P14 | N22: P14 | O22: F | P22: F | Q22: P06 | R22: P06 | S22: P06 | T22: P06 | U22: F | V22: F | W22: P14 | X22: P14 | Y22: P14 | Z22: P14 | AA22: F | AB22: F | AC22: P06 | AD22: P06 | AF22: =VLOOKUP(B22,'JAN25'!$B:$AO,36,0) -> 2 | AG22: =COUNTIF(C22:AD22,"UA") -> 0 | AH22: =AF22-AG22 -> 2 | AJ22: =VLOOKUP(B22,'JAN25'!$B:$AO,40,0) -> 22 | AK22: =COUNTIF(C22:AD22,"u") -> 0 | AL22: =AJ22-AK22 -> 22
A23: Ricardo Bessa | B23: BESSA, RICARDO | C23: F | D23: F | E23: P06 | F23: P06 | G23: F | H23: F | I23: P22 | J23: P22 | K23: P22 | L23: P22 | M23: F | N23: F | O23: P14 | P23: P14 | Q23: P14 | R23: P14 | S23: F | T23: F | U23: P06 | V23: P06 | W23: P06 | X23: P06 | Y23: F | Z23: F | AA23: P14 | AB23: P14 | AC23: P14 | AD23: P14 | AF23: =VLOOKUP(B23,'JAN25'!$B:$AO,36,0) -> 0 | AG23: =COUNTIF(C23:AD23,"UA") -> 0 | AH23: =AF23-AG23 -> 0 | AJ23: =VLOOKUP(B23,'JAN25'!$B:$AO,40,0) -> 22 | AK23: =COUNTIF(C23:AD23,"u") -> 0 | AL23: =AJ23-AK23 -> 22
A24: Samuel Neves | B24: NEVES, SAMUEL | C24: F | D24: F | E24: F | F24: P06 | G24: P06 | H24: P06 | I24: P06 | J24: P06 | K24: F | L24: F | M24: P22 | N24: P22 | O24: P22 | P24: P22 | Q24: F | R24: F | S24: P14 | T24: P14 | U24: P14 | V24: P14 | W24: F | X24: F | Y24: P06 | Z24: P06 | AA24: P06 | AB24: P06 | AC24: F | AD24: F | AF24: =VLOOKUP(B24,'JAN25'!$B:$AO,36,0) -> 7 | AG24: =COUNTIF(C24:AD24,"UA") -> 0 | AH24: =AF24-AG24 -> 7 | AJ24: =VLOOKUP(B24,'JAN25'!$B:$AO,40,0) -> 11 | AK24: =COUNTIF(C24:AD24,"u") -> 0 | AL24: =AJ24-AK24 -> 11
A25: Carlos Carvalhais | B25: CARVALHAIS, CARLOS | C25: F | D25: F | E25: P14 | F25: P14 | G25: P14 | H25: P14 | I25: F | J25: F | K25: P06 | L25: P06 | M25: P06 | N25: P06 | O25: F | P25: F | Q25: P22 | R25: P22 | S25: P22 | T25: P22 | U25: F | V25: F | W25: P14 | X25: P14 | Y25: P14 | Z25: P14 | AA25: F | AB25: F | AC25: P06 | AD25: P06 | AF25: =VLOOKUP(B25,'JAN25'!$B:$AO,36,0) -> 0 | AG25: =COUNTIF(C25:AD25,"UA") -> 0 | AH25: =AF25-AG25 -> 0 | AJ25: =VLOOKUP(B25,'JAN25'!$B:$AO,40,0) -> 12 | AK25: =COUNTIF(C25:AD25,"u") -> 0 | AL25: =AJ25-AK25 -> 12
A26: Alefe Sobral | B26: SOBRAL, ALEFE | C26: F | D26: F | E26: P06 | F26: P06 | G26: F | H26: F | I26: P14 | J26: P10 | K26: P14 | L26: P14 | M26: F | N26: F | O26: P06 | P26: P06 | Q26: P06 | R26: P06 | S26: F | T26: F | U26: P22 | V26: P22 | W26: P22 | X26: P22 | Y26: F | Z26: F | AA26: P06 | AB26: P06 | AC26: P06 | AD26: P06 | AF26: =VLOOKUP(B26,'JAN25'!$B:$AO,36,0) -> 5 | AG26: =COUNTIF(C26:AD26,"UA") -> 0 | AH26: =AF26-AG26 -> 5 | AJ26: =VLOOKUP(B26,'JAN25'!$B:$AO,40,0) -> 10 | AK26: =COUNTIF(C26:AD26,"u") -> 0 | AL26: =AJ26-AK26 -> 10
A27: Jose Alves | B27: ALVES, JOSE | C27: P14 | D27: P14 | E27: F | F27: F | G27: P06 | H27: P06 | I27: P06 | J27: P06 | K27: P06 | L27: F | M27: F | N27: P14 | O27: P14 | P27: P14 | Q27: F | R27: F | S27: P06 | T27: P06 | U27: P06 | V27: P06 | W27: F | X27: F | Y27: P22 | Z27: P22 | AA27: P22 | AB27: P22 | AC27: F | AD27: F | AF27: =VLOOKUP(B27,'JAN25'!$B:$AO,36,0) -> 2 | AG27: =COUNTIF(C27:AD27,"UA") -> 0 | AH27: =AF27-AG27 -> 2 | AJ27: =VLOOKUP(B27,'JAN25'!$B:$AO,40,0) -> 22 | AK27: =COUNTIF(C27:AD27,"u") -> 0 | AL27: =AJ27-AK27 -> 22
A28: Ines Pilre | B28: PILRE, INES | C28: F | D28: F | E28: P14 | F28: P14 | G28: P12 | H28: P14 | I28: F | J28: F | K28: P06 | L28: P06 | M28: P06 | N28: P06 | O28: F | P28: F | Q28: P14 | R28: P14 | S28: P14 | T28: P14 | U28: F | V28: F | W28: P06 | X28: P06 | Y28: P06 | Z28: P06 | AA28: F | AB28: F | AC28: P22 | AD28: P22 | AF28: =VLOOKUP(B28,'JAN25'!$B:$AO,36,0) -> 0 | AG28: =COUNTIF(C28:AD28,"UA") -> 0 | AH28: =AF28-AG28 -> 0 | AJ28: =VLOOKUP(B28,'JAN25'!$B:$AO,40,0) -> 22 | AK28: =COUNTIF(C28:AD28,"u") -> 0 | AL28: =AJ28-AK28 -> 22
A29: Bruna Lima | B29: LIMA, BRUNA | C29: P22 | D29: P22 | E29: P22 | F29: P22 | G29: F | H29: F | I29: P14 | J29: P14 | K29: P14 | L29: P14 | M29: F | N29: F | O29: P06 | P29: P06 | Q29: P06 | R29: P06 | S29: F | T29: F | U29: P14 | V29: P14 | W29: P14 | X29: P14 | Y29: F | Z29: F | AA29: P14 | AB29: P14 | AC29: P14 | AD29: P14 | AF29: =VLOOKUP(B29,'JAN25'!$B:$AO,36,0) -> 10 | AG29: =COUNTIF(C29:AD29,"UA") -> 0 | AH29: =AF29-AG29 -> 10 | AJ29: =VLOOKUP(B29,'JAN25'!$B:$AO,40,0) -> 22 | AK29: =COUNTIF(C29:AD29,"u") -> 0 | AL29: =AJ29-AK29 -> 22
A30: Gonçalo Pereira | B30: PEREIRA, GONCALO | C30: P06 | D30: P06 | E30: F | F30: F | G30: P22 | H30: P22 | I30: P22 | J30: P22 | K30: F | L30: F | M30: P14 | N30: P14 | O30: P14 | P30: P14 | Q30: F | R30: F | S30: P06 | T30: P06 | U30: P06 | V30: P06 | W30: F | X30: F | Y30: P14 | Z30: P14 | AA30: P14 | AB30: P14 | AC30: F | AD30: F | AF30: =VLOOKUP(B30,'JAN25'!$B:$AO,36,0) -> 4 | AG30: =COUNTIF(C30:AD30,"UA") -> 0 | AH30: =AF30-AG30 -> 4 | AJ30: =VLOOKUP(B30,'JAN25'!$B:$AO,40,0) -> 22 | AK30: =COUNTIF(C30:AD30,"u") -> 0 | AL30: =AJ30-AK30 -> 22
A31: Joana Pinheiro | B31: PINHEIRO, JOANA | C31: F | D31: F | E31: P14 | F31: P14 | G31: P14 | H31: P14 | I31: F | J31: F | K31: P22 | L31: P22 | M31: P22 | N31: P22 | O31: F | P31: F | Q31: P14 | R31: P14 | S31: P14 | T31: P14 | U31: F | V31: F | W31: P06 | X31: P06 | Y31: P06 | Z31: P06 | AA31: F | AB31: F | AC31: P14 | AD31: P14 | AF31: =VLOOKUP(B31,'JAN25'!$B:$AO,36,0) -> 0 | AG31: =COUNTIF(C31:AD31,"UA") -> 0 | AH31: =AF31-AG31 -> 0 | AJ31: =VLOOKUP(B31,'JAN25'!$B:$AO,40,0) -> 22 | AK31: =COUNTIF(C31:AD31,"u") -> 0 | AL31: =AJ31-AK31 -> 22
A32: Inês Coelho | B32: COELHO, INES | C32: P06 | D32: P06 | E32: P06 | F32: U | G32: F | H32: F | I32: UA | J32: UA | K32: U | L32: U | M32: F | N32: F | O32: P22 | P32: P22 | Q32: P22 | R32: P22 | S32: F | T32: F | U32: K | V32: K | W32: K | X32: P14 | Y32: F | Z32: F | AA32: P06 | AB32: P06 | AC32: P06 | AD32: P06 | AF32: =VLOOKUP(B32,'JAN25'!$B:$AO,36,0) -> 2 | AG32: =COUNTIF(C32:AD32,"UA") -> 2 | AH32: =AF32-AG32 -> 0 | AJ32: =VLOOKUP(B32,'JAN25'!$B:$AO,40,0) -> 22 | AK32: =COUNTIF(C32:AD32,"u") -> 3 | AL32: =AJ32-AK32 -> 19
... A35: Catia Neves | B35: NEVES, CATIA | C35: F | D35: F | E35: P06 | F35: P06 | G35: P06 | H35: F | I35: P14 | J35: P14 | K35: P14 | L35: P14 | M35: F | N35: F | O35: P06 | P35: P06 | Q35: P06 | R35: P06 | S35: F | T35: F | U35: P14 | V35: P14 | W35: P14 | X35: P14 | Y35: F | Z35: F | AA35: P22 | AB35: P22 | AC35: P22 | AD35: P22 | AF35: =VLOOKUP(B35,'JAN25'!$B:$AO,36,0) -> 3 | AG35: =COUNTIF(C35:AD35,"UA") -> 0 | AH35: =AF35-AG35 -> 3 | AJ35: =VLOOKUP(B35,'JAN25'!$B:$AO,40,0) -> 22 | AK35: =COUNTIF(C35:AD35,"u") -> 0 | AL35: =AJ35-AK35 -> 22
A37: Hubs Services Team
A38: Carla Ferreira | B38: FERREIRA, CARLA | C38: P13 | D38: F | E38: F | F38: P05 | G38: P05 | H38: P05 | I38: P05 | J38: F | K38: F | L38: P07 | M38: P07 | N38: P07 | O38: S3 | P38: F | Q38: F | R38: P05 | S38: P05 | T38: P05 | U38: P05 | V38: F | W38: F | X38: P13 | Y38: P13 | Z38: P13 | AA38: P13 | AB38: P13 | AC38: F | AD38: P07 | AF38: =VLOOKUP(B38,'JAN25'!$B:$AO,36,0) -> 3 | AG38: =COUNTIF(C38:AD38,"UA") -> 0 | AH38: =AF38-AG38 -> 3 | AJ38: =VLOOKUP(B38,'JAN25'!$B:$AO,40,0) -> 22 | AK38: =COUNTIF(C38:AD38,"u") -> 0 | AL38: =AJ38-AK38 -> 22
A39: Bruna Queiroz | B39: QUEIROZ, BRUNA | C39: U | D39: U | E39: U | F39: F | G39: F | H39: U | I39: U | J39: U | K39: U | L39: F | M39: F | N39: U | O39: U | P39: U | Q39: U | R39: F | S39: F | T39: U | U39: U | V39: U | W39: U | X39: F | Y39: F | Z39: S3 | AA39: S3 | AB39: P09 | AC39: P08 | AD39: P08 | AF39: =VLOOKUP(B39,'JAN25'!$B:$AO,36,0) -> 0 | AG39: =COUNTIF(C39:AD39,"UA") -> 0 | AH39: =AF39-AG39 -> 0 | AJ39: =VLOOKUP(B39,'JAN25'!$B:$AO,40,0) -> 11
A40: Tiago Mendes | B40: MENDES, TIAGO ANDRE | C40: F | D40: P13 | E40: P13 | F40: P13 | G40: P12 | H40: F | I40: F | J40: P05 | K40: F | Z40: F | AA40: F | AB40: UA | AC40: UA | AD40: UA | AF40: =VLOOKUP(B40,'JAN25'!$B:$AO,36,0) -> 10 | AG40: =COUNTIF(C40:AD40,"UA") -> 3 | AH40: =AF40-AG40 -> 7 | AJ40: =VLOOKUP(B40,'JAN25'!$B:$AO,40,0) -> 11 | AK40: =COUNTIF(C40:AD40,"u") -> 0 | AL40: =AJ40-AK40 -> 11
A41: Ruben Pinheiro | B41: PINHEIRO, RUBEN | C41: UA | D41: UA | E41: UA | F41: F | G41: F | H41: P13 | I41: P13 | J41: K1 | K41: K1 | L41: K1 | M41: F | N41: P05 | O41: P05 | P41: P05 | Q41: P05 | R41: F | S41: F | T41: P07 | U41: P07 | V41: P07 | W41: P07 | X41: F | Y41: P22 | Z41: P22 | AA41: K | AB41: K | AC41: K | AD41: K | AF41: =VLOOKUP(B41,'JAN25'!$B:$AO,36,0) -> 9 | AG41: =COUNTIF(C41:AD41,"UA") -> 3 | AH41: =AF41-AG41 -> 6 | AJ41: =VLOOKUP(B41,'JAN25'!$B:$AO,40,0) -> 8 | AK41: =COUNTIF(C41:AD41,"u") -> 0 | AL41: =AJ41-AK41 -> 8
A42: Ana Ferreira | B42: FERREIRA, ANA SOFIA | C42: F | D42: F | E42: F | F42: S3 | G42: UA | H42: UA | I42: S3 | J42: F | K42: F | L42: P13 | M42: P13 | N42: P13 | O42: P13 | P42: F | Q42: F | R42: P22 | S42: P22 | T42: P22 | U42: P22 | V42: F | W42: F | X42: P07 | Y42: P07 | Z42: P07 | AA42: P07 | AB42: F | AC42: F | AD42: P22 | AF42: =VLOOKUP(B42,'JAN25'!$B:$AO,36,0) -> 3 | AG42: =COUNTIF(C42:AD42,"UA") -> 2 | AH42: =AF42-AG42 -> 1 | AJ42: =VLOOKUP(B42,'JAN25'!$B:$AO,40,0) -> 22 | AK42: =COUNTIF(C42:AD42,"u") -> 0 | AL42: =AJ42-AK42 -> 22
A43: Barbara Pereira | B43: PEREIRA, BARBARA | C43: F | D43: P13 | E43: P13 | F43: P13 | G43: P13 | H43: F | I43: F | J43: P07 | K43: P07 | L43: P07 | M43: P07 | N43: F | O43: F | P43: P13 | Q43: P13 | R43: P13 | S43: S3 | T43: F | U43: F | V43: P05 | W43: P05 | X43: P05 | Y43: P05 | Z43: F | AA43: F | AB43: P07 | AC43: P07 | AD43: P07 | AF43: =VLOOKUP(B43,'JAN25'!$B:$AO,36,0) -> 11 | AG43: =COUNTIF(C43:AD43,"UA") -> 0 | AH43: =AF43-AG43 -> 11 | AJ43: =VLOOKUP(B43,'JAN25'!$B:$AO,40,0) -> 22 | AK43: =COUNTIF(C43:AD43,"u") -> 0 | AL43: =AJ43-AK43 -> 22
A44: Jessica Martins | B44: MARTINS, JESSICA | C44: P22 | D44: P22 | E44: P22 | F44: F | G44: F | H44: P13 | I44: P13 | J44: P13 | K44: P13 | L44: F | M44: F | N44: B | O44: UA | P44: UA | Q44: UA | R44: F | S44: F | T44: UA | U44: UA | V44: UA | W44: UA | X44: F | Y44: F | Z44: UA | AA44: UA | AB44: UA | AC44: UA | AD44: F | AF44: =VLOOKUP(B44,'JAN25'!$B:$AO,36,0) -> 11 | AG44: =COUNTIF(C44:AD44,"UA") -> 11 | AH44: =AF44-AG44 -> 0 | AJ44: =VLOOKUP(B44,'JAN25'!$B:$AO,40,0) -> 11 | AK44: =COUNTIF(C44:AD44,"u") -> 0 | AL44: =AJ44-AK44 -> 11
A45: Jorge Costa | B45: COSTA, JORGE | C45: P07 | D45: P07 | E45: F | F45: F | G45: P07 | H45: P07 | I45: P07 | J45: F | K45: F | AF45: =VLOOKUP(B45,'JAN25'!$B:$AO,36,0) -> 0 | AG45: =COUNTIF(C45:AD45,"UA") -> 0 | AH45: =AF45-AG45 -> 0 | AJ45: =VLOOKUP(B45,'JAN25'!$B:$AO,40,0) -> 12 | AK45: =COUNTIF(C45:AD45,"u") -> 0 | AL45: =AJ45-AK45 -> 12
...

Sheet MAR25
C1: LGSP - Lufthansa Ground Services Portugal NIF : 509 842 593 Atividade: CAE 52230.R3 Sede e local de trabalho: Avenida da Boavista ED.Burgo, 1837 sala 13.1 Horario de Funcionamento: 24/7 IRT: Não Aplicável
A2: Hubs Services | C2: Março | AI2: Ferias 2024 | AM2: Ferias 2025
C3: Sab | D3: Dom | E3: Seg | F3: Ter | G3: Qua | H3: Qui | I3: Sex | J3: Sab | K3: Dom | L3: Seg | M3: Ter | N3: Qua | O3: Qui | P3: Sex | Q3: Sab | R3: Dom | S3: Seg | T3: Ter | U3: Qua | V3: Qui | W3: Sex | X3: Sab | Y3: Dom | Z3: Seg | AA3: Ter | AB3: Qua | AC3: Qui | AD3: Sex | AE3: Sab | AF3: Dom | AG3: Seg | AI3: 2024 | AJ3: Used | AK3: LEFT | AM3: 2025 | AN3: Used | AO3: LEFT
A4: NOME | B4: NOME GENESYS | C4: 1 | D4: 2 | E4: 3 | F4: 4 | G4: 5 | H4: 6 | I4: 7 | J4: 8 | K4: 9 | L4: 10 | M4: 11 | N4: 12 | O4: 13 | P4: 14 | Q4: 15 | R4: 16 | S4: 17 | T4: 18 | U4: 19 | V4: 20 | W4: 21 | X4: 22 | Y4: 23 | Z4: 24 | AA4: 25 | AB4: 26 | AC4: 27 | AD4: 28 | AE4: 29 | AF4: 30 | AG4: 31
A5: Diana Reisinho | B5: REISINHO, DIANA | C5: K | D5: K | E5: K | F5: K | G5: K | H5: K | I5: K | J5: K | K5: K | L5: K | M5: K | N5: K | O5: K | P5: K | Q5: K | R5: K | S5: K | T5: K | U5: K | V5: K | W5: K | X5: K | Y5: K | Z5: K | AA5: K | AB5: K | AC5: K | AD5: K | AE5: K | AF5: K | AG5: K | AI5: =VLOOKUP($B5,'FEB25'!$B:$AL,33,0) -> 3 | AJ5: =COUNTIF(C5:AG5,"UA") -> 0 | AK5: =AI5-AJ5 -> 3 | AM5: ='FEB25'!AL5 -> 22 | AN5: =COUNTIF(C5:AG5,"u") -> 0 | AO5: =AM5-AN5 -> 22
A6: Catarina Ferreira | B6: FERREIRA, CATARINA | C6: P06 | D6: P06 | E6: F | F6: F | G6: P14 | H6: P14 | I6: P14 | J6: P14 | K6: F | L6: F | M6: P06 | N6: P06 | O6: P06 | P6: P06 | Q6: F | R6: F | S6: P14 | T6: P14 | U6: P14 | V6: P14 | W6: F | X6: F | Y6: P06 | Z6: P06 | AA6: P06 | AB6: P06 | AC6: F | AD6: F | AE6: P06 | AF6: P06 | AG6: P06 | AI6: =VLOOKUP($B6,'FEB25'!$B:$AL,33,0) -> 0 | AJ6: =COUNTIF(C6:AG6,"UA") -> 0 | AK6: =AI6-AJ6 -> 0 | AM6: ='FEB25'!AL6 -> 19 | AN6: =COUNTIF(C6:AG6,"u") -> 0 | AO6: =AM6-AN6 -> 19
A7: João Santos Silva | B7: SANTOS SILVA, JOAO | C7: U | D7: U | E7: U | F7: H | G7: F | H7: F | I7: U | J7: U | K7: U | L7: U | M7: F | N7: F | O7: U | P7: U | Q7: U | R7: F | S7: F | T7: P06 | U7: P06 | V7: P06 | W7: P06 | X7: P06 | Y7: F | Z7: F | AA7: P14 | AB7: P14 | AC7: P14 | AD7: P14 | AE7: F | AF7: F | AG7: P06 | AI7: =VLOOKUP($B7,'FEB25'!$B:$AL,33,0) -> 0 | AJ7: =COUNTIF(C7:AG7,"UA") -> 0 | AK7: =AI7-AJ7 -> 0 | AM7: ='FEB25'!AL7 -> 22 | AN7: =COUNTIF(C7:AG7,"u") -> 10 | AO7: =AM7-AN7 -> 12
A8: Ana Magalhães | B8: MAGALHAES, ANA CATARINA | C8: P06 | D8: P06 | E8: F | F8: F | G8: P14 | H8: P14 | I8: P14 | J8: P14 | K8: F | L8: F | M8: P06 | N8: P06 | O8: P06 | P8: P06 | Q8: F | R8: F | S8: P14 | T8: P14 | U8: P14 | V8: P14 | W8: F | X8: F | Y8: P06 | Z8: P06 | AA8: P06 | AB8: P06 | AC8: F | AD8: F | AE8: P14 | AF8: P14 | AG8: P14 | AI8: =VLOOKUP($B8,'FEB25'!$B:$AL,33,0) -> 0 | AJ8: =COUNTIF(C8:AG8,"UA") -> 0 | AK8: =AI8-AJ8 -> 0 | AM8: ='FEB25'!AL8 -> 23 | AN8: =COUNTIF(C8:AG8,"u") -> 0 | AO8: =AM8-AN8 -> 23
A9: Jorge Gonçalves | B9: GONCALVES, JORGE | C9: F | D9: F | E9: P06 | F9: P06 | G9: P06 | H9: P06 | I9: F | J9: F | K9: P14 | L9: P14 | M9: P14 | N9: P14 | O9: F | P9: F | Q9: P06 | R9: P06 | S9: P06 | T9: P06 | U9: F | V9: F | W9: P14 | X9: U | Y9: P14 | Z9: P14 | AA9: F | AB9: F | AC9: P06 | AD9: P06 | AE9: P06 | AF9: P06 | AG9: F | AI9: =VLOOKUP($B9,'FEB25'!$B:$AL,33,0) -> 0 | AJ9: =COUNTIF(C9:AG9,"UA") -> 0 | AK9: =AI9-AJ9 -> 0 | AM9: ='FEB25'!AL9 -> 12 | AN9: =COUNTIF(C9:AG9,"u") -> 1 | AO9: =AM9-AN9 -> 11
A10: Catarina Pereira | B10: PEREIRA, CATARINA | C10: P14 | D10: P14 | E10: P14 | F10: P14 | G10: F | H10: F | I10: P06 | J10: P06 | K10: P06 | L10: P06 | M10: F | N10: F | O10: P06 | P10: P11 | Q10: P14 | R10: P14 | S10: F | T10: F | U10: P06 | V10: P06 | W10: P06 | X10: P14 | Y10: F | Z10: F | AA10: P14 | AB10: P14 | AC10: P14 | AD10: P14 | AE10: F | AF10: F | AG10: U | AI10: =VLOOKUP($B10,'FEB25'!$B:$AL,33,0) -> 0 | AJ10: =COUNTIF(C10:AG10,"UA") -> 0 | AK10: =AI10-AJ10 -> 0 | AM10: ='FEB25'!AL10 -> 22 | AN10: =COUNTIF(C10:AG10,"u") -> 1 | AO10: =AM10-AN10 -> 21
A11: Sara Medeiros | B11: MEDEIROS, SARA | C11: P06 | D11: P06 | E11: F | F11: F | G11: P14 | H11: P14 | I11: P14 | J11: P09 | K11: F | L11: F | M11: P14 | N11: P14 | O11: P14 | P11: P14 | Q11: F | R11: F | S11: P14 | T11: P14 | U11: P14 | V11: P14 | W11: F | X11: F | Y11: P06 | Z11: P06 | AA11: P06 | AB11: P06 | AC11: F | AD11: F | AE11: P14 | AF11: P11 | AG11: P06 | AI11: =VLOOKUP($B11,'FEB25'!$B:$AL,33,0) -> 0 | AJ11: =COUNTIF(C11:AG11,"UA") -> 0 | AK11: =AI11-AJ11 -> 0 | AM11: ='FEB25'!AL11 -> 22 | AN11: =COUNTIF(C11:AG11,"u") -> 0 | AO11: =AM11-AN11 -> 22
A12: Catia Martins | B12: MARTINS, CATIA | C12: F | D12: F | E12: P06 | F12: P06 | G12: P06 | H12: P06 | I12: F | J12: F | K12: P14 | L12: P14 | M12: P14 | N12: P14 | O12: F | P12: F | Q12: P06 | R12: P06 | S12: P06 | T12: P11 | U12: F | V12: F | W12: P22 | X12: P22 | Y12: P22 | Z12: P22 | AA12: F | AB12: F | AC12: P14 | AD12: P14 | AE12: P14 | AF12: P14 | AG12: F | AI12: =VLOOKUP($B12,'FEB25'!$B:$AL,33,0) -> 0 | AJ12: =COUNTIF(C12:AG12,"UA") -> 0 | AK12: =AI12-AJ12 -> 0 | AM12: ='FEB25'!AL12 -> 17 | AN12: =COUNTIF(C12:AG12,"u") -> 0 | AO12: =AM12-AN12 -> 17
A14: Cgsupport
A15: Marcos Costa | B15: COSTA, MARCOS FELIPE | C15: B | D15: F | E15: B* | F15: K | G15: K | H15: K | I15: F | J15: F | K15: P06 | L15: P06 | M15: P06 | N15: P06 | O15: F | P15: F | Q15: P14 | R15: P14 | S15: P14 | T15: P14 | U15: F | V15: F | W15: P06 | X15: P06 | Y15: FINJ | Z15: FINJ | AA15: F | AB15: F | AC15: FINJ | AD15: FINJ | AE15: P08 | AF15: P06 | AG15: P06 | AI15: 0 | AJ15: =COUNTIF(C15:AG15,"UA") -> 0 | AK15: =AI15-AJ15 -> 0 | AM15: 22 | AN15: 0 | AO15: 22
A16: Tassiana Bastos | B16: BASTOS, TASSIANA | C16: UA | D16: P06 | E16: P06 | F16: F | G16: F | H16: P14 | I16: P14 | J16: P14 | K16: P14 | L16: F | M16: F | N16: P06 | O16: P06 | P16: P06 | Q16: P06 | R16: F | S16: F | T16: P14 | U16: P14 | V16: P14 | W16: P14 | X16: F | Y16: F | Z16: P06 | AA16: P06 | AB16: P06 | AC16: P14 | AD16: P14 | AE16: F | AF16: F | AG16: P14 | AI16: 1 | AJ16: =COUNTIF(C16:AG16,"UA") -> 1 | AK16: =AI16-AJ16 -> 0 | AM16: 22 | AN16: 0 | AO16: 22
A17: Tatiana Monteiro | B17: MONTEIRO, TATIANA | C17: P06 | D17: P06 | E17: F | F17: P06 | G17: P06 | H17: P06 | I17: F | J17: UA | K17: F | L17: F | M17: P06 | N17: P06 | O17: P14 | P17: P14 | Q17: F | R17: F | S17: P06 | T17: P06 | U17: P06 | V17: P06 | W17: F | X17: F | Y17: P06 | Z17: P06 | AA17: P14 | AB17: P14 | AC17: F | AD17: F | AE17: P14 | AF17: P14 | AG17: P14 | AI17: 1 | AJ17: =COUNTIF(C17:AG17,"UA") -> 1 | AK17: =AI17-AJ17 -> 0 | AM17: 22 | AN17: 0 | AO17: 22
A18: Raquel Teixeira | B18: TEIXEIRA, RAQUEL | C18: F | D18: F | E18: P14 | F18: P14 | G18: P14 | H18: P14 | I18: F | J18: F | K18: P14 | L18: P14 | M18: P14 | N18: P14 | O18: F | P18: F | Q18: P06 | R18: P06 | S18: P13 | T18: P14 | U18: F | V18: F | W18: P14 | X18: P14 | Y18: P14 | Z18: P14 | AA18: F | AB18: F | AC18: UA | AD18: UA | AE18: UA | AF18: UA | AG18: F | AI18: 6 | AJ18: =COUNTIF(C18:AG18,"UA") -> 4 | AK18: =AI18-AJ18 -> 2 | AM18: 23 | AN18: 0 | AO18: 23
A19: Filipa Moreira | B19: MOREIRA, FILIPA | C19: F | D19: F | E19: UA | F19: H | G19: UA | H19: UA | I19: UA | J19: F | K19: F | L19: P09/ | M19: P09/ | N19: P09/ | O19: P08 | P19: P08 | Q19: F | R19: F | S19: P06 | T19: P06 | U19: P06 | V19: P06 | W19: F | X19: F | Y19: P06 | Z19: P06 | AA19: P14 | AB19: P14 | AC19: F | AD19: F | AE19: P06 | AF19: P06 | AG19: P06 | AI19: 4 | AJ19: =COUNTIF(C19:AG19,"UA") -> 4 | AK19: =AI19-AJ19 -> 0 | AM19: 23 | AN19: 0 | AO19: 23
A21: INAD HUBs RST
A22: Cristiana Ferreira | B22: FERREIRA, CRISTIANA MARGARIDA | C22: F | D22: F | E22: UA | F22: H | G22: UA | H22: U | I22: U | J22: F | K22: F | L22: P09/ | M22: P09/ | N22: P09/ | O22: P09/ | P22: P09/ | Q22: F | R22: F | S22: P09/ | T22: P09/ | U22: P09/ | V22: P09/ | W22: K1 | X22: F | Y22: F | Z22: P09/ | AA22: P09/ | AB22: P09/ | AC22: P09/ | AD22: P09/ | AE22: P06 | AF22: F | AG22: P08 | AI22: =VLOOKUP($B22,'FEB25'!$B:$AL,33,0) -> 2 | AJ22: =COUNTIF(C22:AG22,"UA") -> 2 | AK22: =AI22-AJ22 -> 0 | AM22: ='FEB25'!AL15 -> 22 | AN22: =COUNTIF(C22:AG22,"u") -> 2 | AO22: =AM22-AN22 -> 20
A23: Tiago Abreu | B23: ABREU, TIAGO | C23: F | D23: P14 | E23: P14 | F23: P14 | G23: P14 | H23: F | I23: F | J23: P06 | K23: P06 | L23: P14 | M23: P14 | N23: F | O23: F | P23: P14 | Q23: P14 | R23: P14 | S23: P14 | T23: F | U23: F | V23: P06 | W23: P06 | X23: P14 | Y23: P14 | Z23: F | AA23: NO | AB23: NO | AC23: F | AD23: P14 | AE23: P10 | AF23: P06 | AG23: F | AI23: =VLOOKUP($B23,'FEB25'!$B:$AL,33,0) -> 0 | AJ23: =COUNTIF(C23:AG23,"UA") -> 0 | AK23: =AI23-AJ23 -> 0 | AM23: ='FEB25'!AL16 -> 12 | AN23: =COUNTIF(C23:AG23,"u") -> 0 | AO23: =AM23-AN23 -> 12
A24: Maria Burca | B24: BURCA, MARIA | C24: P14 | D24: F | E24: F | F24: H | G24: P06 | H24: P06 | I24: P06 | J24: F | K24: F | L24: P06 | M24: P06 | N24: P14 | O24: P14 | P24: F | Q24: F | R24: P06 | S24: P06 | T24: P06 | U24: P06 | V24: F | W24: F | X24: P06 | Y24: P06 | Z24: P14 | AA24: P14 | AB24: F | AC24: F | AD24: UA | AE24: B | AF24: U | AG24: U | AI24: =VLOOKUP($B24,'FEB25'!$B:$AL,33,0) -> 1 | AJ24: =COUNTIF(C24:AG24,"UA") -> 1 | AK24: =AI24-AJ24 -> 0 | AM24: ='FEB25'!AL17 -> 23 | AN24: =COUNTIF(C24:AG24,"u") -> 2 | AO24: =AM24-AN24 -> 21
A25: Catarina Mendes | B25: MENDES, CATARINA | C25: P10M | D25: P10M | E25: P10M | F25: F | G25: F | H25: P10M | I25: P10M | J25: P10M | K25: P10M | L25: P10M | M25: F | N25: F | O25: P10M | P25: P10M | Q25: P10M | R25: F | S25: F | T25: P10M | U25: P10M | V25: P10M | W25: P10M | X25: F | Y25: F | Z25: P10M | AA25: P10M | AB25: K | AC25: P10M | AD25: F | AE25: F | AF25: P10M | AG25: P08/ | AI25: =VLOOKUP($B25,'FEB25'!$B:$AL,33,0) -> 0 | AJ25: =COUNTIF(C25:AG25,"UA") -> 0 | AK25: =AI25-AJ25 -> 0 | AM25: ='FEB25'!AL18 -> 21 | AN25: =COUNTIF(C25:AG25,"u") -> 0 | AO25: =AM25-AN25 -> 21
A26: Barbara Martins | B26: MARTINS, BARBARA | C26: F | D26: P14 | E26: P14 | F26: P14 | G26: P14 | H26: F | I26: F | J26: P06 | K26: P06 | L26: P14 | M26: P14 | N26: F | O26: F | P26: P14 | Q26: P14 | R26: P14 | S26: P14 | T26: F | U26: F | V26: P06 | W26: P06 | X26: P06 | Y26: P06 | Z26: F | AA26: F | AB26: P14 | AC26: P14 | AD26: P14 | AE26: P14 | AF26: P14 | AG26: F | AI26: 5 | AJ26: 0 | AK26: 5 | AM26: 22 | AN26: 0 | AO26: 22
A28: RST Team
A29: Diana Salome Sousa | B29: SOUSA, DIANA SALOME | C29: P22 | D29: P22 | E29: P22 | F29: P22 | G29: F | H29: F | I29: P14 | J29: P14 | K29: P14 | L29: P14 | M29: F | N29: F | O29: P06 | P29: FINJ | Q29: P06 | R29: P06 | S29: F | T29: F | U29: P14 | V29: P14 | W29: P14 | X29: P14 | Y29: F | Z29: F | AA29: P06 | AB29: P06 | AC29: P06 | AD29: P06 | AE29: F | AF29: F | AG29: P22 | AI29: =VLOOKUP($B29,'FEB25'!$B:$AL,33,0) -> 0 | AJ29: =COUNTIF(C29:AG29,"UA") -> 0 | AK29: =AI29-AJ29 -> 0 | AM29: ='FEB25'!AL21 -> 19 | AN29: =COUNTIF(C29:AG29,"u") -> 0 | AO29: =AM29-AN29 -> 19
A30: Ricardo Medeiros | B30: MEDEIROS, RICARDO | C30: P06 | D30: P06 | E30: F | F30: F | G30: P06 | H30: P06 | I30: P06 | J30: P06 | K30: F | L30: F | M30: P22 | N30: P22 | O30: K | P30: K | Q30: F | R30: F | S30: P06 | T30: P06 | U30: P06 | V30: P06 | W30: F | X30: F | Y30: P14 | Z30: P14 | AA30: P14 | AB30: P14 | AC30: F | AD30: F | AE30: P06 | AF30: P06 | AG30: P06 | AI30: =VLOOKUP($B30,'FEB25'!$B:$AL,33,0) -> 2 | AJ30: =COUNTIF(C30:AG30,"UA") -> 0 | AK30: =AI30-AJ30 -> 2 | AM30: ='FEB25'!AL22 -> 22 | AN30: =COUNTIF(C30:AG30,"u") -> 0 | AO30: =AM30-AN30 -> 22
A31: Ricardo Bessa | B31: BESSA, RICARDO | C31: F | D31: F | E31: P06 | F31: P06 | G31: P06 | H31: P06 | I31: F | J31: F | K31: P22 | L31: P22 | M31: P22 | N31: P22 | O31: F | P31: F | Q31: P14 | R31: P14 | S31: P14 | T31: P14 | U31: F | V31: F | W31: P06 | X31: P06 | Y31: P06 | Z31: P06 | AA31: F | AB31: F | AC31: P14 | AD31: P14 | AE31: P14 | AF31: P14 | AG31: F | AI31: =VLOOKUP($B31,'FEB25'!$B:$AL,33,0) -> 0 | AJ31: =COUNTIF(C31:AG31,"UA") -> 0 | AK31: =AI31-AJ31 -> 0 | AM31: ='FEB25'!AL23 -> 22 | AN31: =COUNTIF(C31:AG31,"u") -> 0 | AO31: =AM31-AN31 -> 22
A32: Samuel Neves | B32: NEVES, SAMUEL | C32: P14 | D32: P14 | E32: P14 | F32: P14 | G32: F | H32: F | I32: P06 | J32: P06 | K32: P06 | L32: P06 | M32: F | N32: F | O32: P22 | P32: P22 | Q32: P22 | R32: P22 | S32: F | T32: F | U32: P14 | V32: P14 | W32: P14 | X32: P14 | Y32: F | Z32: F | AA32: P06 | AB32: P06 | AC32: P06 | AD32: UA | AE32: F | AF32: F | AG32: UA | AI32: =VLOOKUP($B32,'FEB25'!$B:$AL,33,0) -> 7 | AJ32: =COUNTIF(C32:AG32,"UA") -> 2 | AK32: =AI32-AJ32 -> 5 | AM32: ='FEB25'!AL24 -> 11 | AN32: =COUNTIF(C32:AG32,"u") -> 0 | AO32: =AM32-AN32 -> 11
A33: Carlos Carvalhais | B33: CARVALHAIS, CARLOS | C33: P06 | D33: P06 | E33: F | F33: F | G33: P14 | H33: P14 | I33: P10 | J33: P14 | K33: F | L33: F | M33: P06 | N33: P06 | O33: P06 | P33: P06 | Q33: F | R33: F | S33: P22 | T33: P22 | U33: P22 | V33: P22 | W33: F | X33: F | Y33: P14 | Z33: P14 | AA33: P14 | AB33: P14 | AC33: F | AD33: F | AE33: U | AF33: U | AG33: U | AI33: =VLOOKUP($B33,'FEB25'!$B:$AL,33,0) -> 0 | AJ33: =COUNTIF(C33:AG33,"UA") -> 0 | AK33: =AI33-AJ33 -> 0 | AM33: ='FEB25'!AL25 -> 12 | AN33: =COUNTIF(C33:AG33,"u") -> 3 | AO33: =AM33-AN33 -> 9
A34: Alefe Sobral | B34: SOBRAL, ALEFE | C34: F | D34: F | E34: UA | F34: H | G34: P06 | H34: P06 | I34: F | J34: F | K34: P14 | L34: P14 | M34: P14 | N34: P14 | O34: F | P34: F | Q34: P06 | R34: P06 | S34: P06 | T34: P06 | U34: F | V34: F | W34: S3 | X34: UA | Y34: UA | Z34: UA | AA34: F | AB34: F | AC34: P22 | AD34: P22 | AE34: P22 | AF34: P22 | AG34: F | AI34: =VLOOKUP($B34,'FEB25'!$B:$AL,33,0) -> 5 | AJ34: =COUNTIF(C34:AG34,"UA") -> 4 | AK34: =AI34-AJ34 -> 1 | AM34: ='FEB25'!AL26 -> 10 | AN34: =COUNTIF(C34:AG34,"u") -> 0 | AO34: =AM34-AN34 -> 10
A35: Jose Alves | B35: ALVES, JOSE | C35: P14 | D35: P14 | E35: P14 | F35: P14 | G35: F | H35: F | I35: P06 | J35: P06 | K35: P06 | L35: P06 | M35: F | N35: F | O35: P14 | P35: P14 | Q35: P14 | R35: P14 | S35: F | T35: F | U35: P06 | V35: P06 | W35: P06 | X35: P06 | Y35: F | Z35: F | AA35: P22 | AB35: P22 | AC35: P22 | AD35: P22 | AE35: F | AF35: F | AG35: P14 | AI35: =VLOOKUP($B35,'FEB25'!$B:$AL,33,0) -> 2 | AJ35: =COUNTIF(C35:AG35,"UA") -> 0 | AK35: =AI35-AJ35 -> 2 | AM35: ='FEB25'!AL27 -> 22 | AN35: =COUNTIF(C35:AG35,"u") -> 0 | AO35: =AM35-AN35 -> 22
A36: Ines Pilre | B36: PILRE, INES | C36: P22 | D36: P22 | E36: F | F36: F | G36: P14 | H36: P14 | I36: P14 | J36: P14 | K36: F | L36: F | M36: P06 | N36: P06 | O36: P06 | P36: P06 | Q36: F | R36: F | S36: P14 | T36: P14 | U36: P14 | V36: P14 | W36: F | X36: F | Y36: P06 | Z36: P06 | AA36: P06 | AB36: P06 | AC36: F | AD36: F | AE36: P22 | AF36: P22 | AG36: P22 | AI36: =VLOOKUP($B36,'FEB25'!$B:$AL,33,0) -> 0 | AJ36: =COUNTIF(C36:AG36,"UA") -> 0 | AK36: =AI36-AJ36 -> 0 | AM36: ='FEB25'!AL28 -> 22 | AN36: =COUNTIF(C36:AG36,"u") -> 0 | AO36: =AM36-AN36 -> 22
A37: Bruna Lima | B37: LIMA, BRUNA | C37: F | D37: F | E37: P22 | F37: P22 | G37: P22 | H37: P22 | I37: F | J37: F | K37: P14 | L37: P14 | M37: P14 | N37: P14 | O37: F | P37: F | Q37: P06 | R37: P06 | S37: UA | T37: UA | U37: F | V37: F | W37: UA | X37: UA | Y37: UA | Z37: UA | AA37: F | AB37: F | AC37: UA | AD37: UA | AE37: UA | AF37: UA | AG37: F | AI37: =VLOOKUP($B37,'FEB25'!$B:$AL,33,0) -> 10 | AJ37: =COUNTIF(C37:AG37,"UA") -> 10 | AK37: =AI37-AJ37 -> 0 | AM37: ='FEB25'!AL29 -> 22 | AN37: =COUNTIF(C37:AG37,"u") -> 0 | AO37: =AM37-AN37 -> 22
A38: Gonçalo Pereira | B38: PEREIRA, GONCALO | C38: P06 | D38: P06 | E38: P06 | F38: P06 | G38: F | H38: F | I38: P22 | J38: P22 | K38: P22 | L38: P22 | M38: F | N38: F | O38: UA | P38: UA | Q38: UA | R38: UA | S38: F | T38: F | U38: S3 | V38: P | W38: P | X38: P | Y38: P | Z38: P | AA38: P | AB38: P | AC38: P | AD38: P | AE38: P | AF38: P | AG38: P | AI38: =VLOOKUP($B38,'FEB25'!$B:$AL,33,0) -> 4 | AJ38: =COUNTIF(C38:AG38,"UA") -> 4 | AK38: =AI38-AJ38 -> 0 | AM38: ='FEB25'!AL30 -> 22 | AN38: =COUNTIF(C38:AG38,"u") -> 0 | AO38: =AM38-AN38 -> 22
A39: Joana Pinheiro | B39: PINHEIRO, JOANA | C39: P14 | D39: P14 | E39: F | F39: F | G39: P22 | H39: P22 | I39: P22 | J39: P22 | K39: F | L39: F | M39: U | N39: U | O39: U | P39: U | Q39: F | R39: F | S39: P06 | T39: P06 | U39: P06 | V39: P06 | W39: F | X39: F | Y39: P22 | Z39: P22 | AA39: P22 | AB39: P22 | AC39: F | AD39: F | AE39: P14 | AF39: P14 | AG39: P14 | AI39: =VLOOKUP($B39,'FEB25'!$B:$AL,33,0) -> 0 | AJ39: =COUNTIF(C39:AG39,"UA") -> 0 | AK39: =AI39-AJ39 -> 0 | AM39: ='FEB25'!AL31 -> 22 | AN39: =COUNTIF(C39:AG39,"u") -> 4 | AO39: =AM39-AN39 -> 18
A40: Inês Coelho | B40: COELHO, INES | C40: F | D40: F | E40: P14 | F40: P14 | G40: P14 | H40: P14 | I40: F | J40: F | K40: P06 | L40: P06 | M40: P06 | N40: P06 | O40: F | P40: F | Q40: P22 | R40: P22 | S40: P22 | T40: P22 | U40: F | V40: F | W40: P14 | X40: P14 | Y40: P14 | Z40: P14 | AA40: F | AB40: F | AC40: P06 | AD40: P06 | AE40: P06 | AF40: P06 | AG40: F | AI40: =VLOOKUP($B40,'FEB25'!$B:$AL,33,0) -> 0 | AJ40: =COUNTIF(C40:AG40,"UA") -> 0 | AK40: =AI40-AJ40 -> 0 | AM40: ='FEB25'!AL32 -> 19 | AN40: =COUNTIF(C40:AG40,"u") -> 0 | AO40: =AM40-AN40 -> 19
... A43: Catia Neves | B43: NEVES, CATIA | C43: F | D43: F | E43: P14 | F43: P14 | G43: P14 | H43: P14 | I43: F | J43: F | K43: P05 | L43: P06 | M43: P06 | N43: P06 | O43: F | P43: F | Q43: P14 | R43: P14 | S43: P14 | T43: P14 | U43: F | V43: F | W43: UA | X43: UA | Y43: UA | Z43: K | AA43: K | AB43: K | AC43: K | AD43: K | AE43: K | AF43: K | AG43: K | AI43: =VLOOKUP($B43,'FEB25'!$B:$AL,33,0) -> 3 | AJ43: =COUNTIF(C43:AG43,"UA") -> 3 | AK43: =AI43-AJ43 -> 0 | AM43: ='FEB25'!AL35 -> 22 | AN43: =COUNTIF(C43:AG43,"u") -> 0 | AO43: =AM43-AN43 -> 22
A45: Hubs Services Team
A46: Carla Ferreira | B46: FERREIRA, CARLA | C46: F | D46: F | E46: P08 | F46: H | G46: P08 | H46: P08 | I46: P08 | J46: F | K46: F | L46: P08 | M46: P08 | N46: P08 | O46: P08 | P46: P08 | Q46: F | R46: F | S46: F | T46: UA | U46: UA | V46: UA | W46: U | X46: F | Y46: F | Z46: P05 | AA46: P05 | AB46: P05 | AC46: P05 | AD46: F | AE46: F | AF46: P13 | AG46: P13 | AI46: =VLOOKUP($B46,'FEB25'!$B:$AL,33,0) -> 3 | AJ46: =COUNTIF(C46:AG46,"UA") -> 3 | AK46: =AI46-AJ46 -> 0 | AM46: ='FEB25'!AL38 -> 22 | AN46: =COUNTIF(C46:AG46,"u") -> 1 | AO46: =AM46-AN46 -> 21
...

Sheet APR25
C1: LGSP - Lufthansa Ground Services Portugal NIF : 509 842 593 Atividade: CAE 52230.R3 Sede e local de trabalho: Avenida da Boavista ED.Burgo, 1837 sala 13.1 Horario de Funcionamento: 24/7 IRT: Não Aplicável
A2: Hubs Services | C2: Abril | AH2: Ferias 2024 | AL2: Ferias 2025
C3: Ter | D3: Qua | E3: Qui | F3: Sex | G3: Sab | H3: Dom | I3: Seg | J3: Ter | K3: Qua | L3: Qui | M3: Sex | N3: Sab | O3: Dom | P3: Seg | Q3: Ter | R3: Qua | S3: Qui | T3: Sex | U3: Sab | V3: Dom | W3: Seg | X3: Ter | Y3: Qua | Z3: Qui | AA3: Sex | AB3: Sab | AC3: Dom | AD3: Seg | AE3: Ter | AF3: Qua | AH3: 2024 | AI3: Used | AJ3: LEFT | AL3: 2025 | AM3: Used | AN3: LEFT
A4: NOME | B4: NOME GENESYS | C4: 1 | D4: 2 | E4: 3 | F4: 4 | G4: 5 | H4: 6 | I4: 7 | J4: 8 | K4: 9 | L4: 10 | M4: 11 | N4: 12 | O4: 13 | P4: 14 | Q4: 15 | R4: 16 | S4: 17 | T4: 18 | U4: 19 | V4: 20 | W4: 21 | X4: 22 | Y4: 23 | Z4: 24 | AA4: 25 | AB4: 26 | AC4: 27 | AD4: 28 | AE4: 29 | AF4: 30
A5: Diana Reisinho | B5: REISINHO, DIANA | C5: K | D5: K | E5: K | F5: K | G5: K | H5: K | I5: K | J5: K | K5: K | L5: K | M5: K | N5: K | O5: K | P5: K | Q5: K | R5: K | S5: K | T5: K | U5: K | V5: K | W5: K | X5: K | Y5: K | Z5: K | AA5: K | AB5: K | AC5: K | AD5: K | AE5: K | AF5: K | AH5: =VLOOKUP($B5,'MAR25'!$B:$AO,36,0) -> 3 | AI5: =COUNTIF(C5:AF5,"UA") -> 0 | AJ5: =AH5-AI5 -> 3 | AL5: =VLOOKUP($B5,'MAR25'!$B:$AO,40,0) -> 22 | AM5: =COUNTIF(C5:AF5,"U") -> 0 | AN5: =AL5-AM5 -> 22
A6: Catarina Ferreira | B6: FERREIRA, CATARINA | C6: P06 | D6: F | E6: F | F6: P22 | G6: P22 | H6: P22 | I6: P22 | J6: F | K6: F | L6: P14 | M6: P14 | N6: P14 | O6: P14 | P6: F | Q6: F | R6: S3 | S6: S3 | T6: H | U6: U | V6: F | W6: F | X6: S3 | Y6: U | Z6: U | AA6: H | AB6: F | AC6: F | AD6: P06 | AE6: P06 | AF6: P06 | AH6: =VLOOKUP($B6,'MAR25'!$B:$AO,36,0) -> 0 | AI6: =COUNTIF(C6:AF6,"UA") -> 0 | AJ6: =AH6-AI6 -> 0 | AL6: =VLOOKUP($B6,'MAR25'!$B:$AO,40,0) -> 19 | AM6: =COUNTIF(C6:AF6,"U") -> 3 | AN6: =AL6-AM6 -> 16
A7: João Santos Silva | B7: SANTOS SILVA, JOAO | C7: P06 | D7: P06 | E7: P06 | F7: F | G7: F | H7: P14 | I7: P14 | J7: P14 | K7: P14 | L7: F | M7: F | N7: P06 | O7: P06 | P7: P06 | Q7: P06 | R7: F | S7: F | T7: H | U7: U | V7: H | W7: U | X7: F | Y7: F | Z7: P06 | AA7: P06 | AB7: P06 | AC7: P06 | AD7: F | AE7: F | AF7: P14 | AH7: =VLOOKUP($B7,'MAR25'!$B:$AO,36,0) -> 0 | AI7: =COUNTIF(C7:AF7,"UA") -> 0 | AJ7: =AH7-AI7 -> 0 | AL7: =VLOOKUP($B7,'MAR25'!$B:$AO,40,0) -> 12 | AM7: =COUNTIF(C7:AF7,"U") -> 2 | AN7: =AL7-AM7 -> 10
A8: Ana Magalhães | B8: MAGALHAES, ANA CATARINA | C8: P14 | D8: F | E8: F | F8: P06 | G8: P06 | H8: P06 | I8: P06 | J8: F | K8: F | L8: P14 | M8: P14 | N8: P14 | O8: P14 | P8: F | Q8: F | R8: P06 | S8: P06 | T8: P06 | U8: P06 | V8: F | W8: F | X8: P14 | Y8: P14 | Z8: P14 | AA8: P14 | AB8: F | AC8: F | AD8: P06 | AE8: P06 | AF8: P06 | AH8: =VLOOKUP($B8,'MAR25'!$B:$AO,36,0) -> 0 | AI8: =COUNTIF(C8:AF8,"UA") -> 0 | AJ8: =AH8-AI8 -> 0 | AL8: =VLOOKUP($B8,'MAR25'!$B:$AO,40,0) -> 23 | AM8: =COUNTIF(C8:AF8,"U") -> 0 | AN8: =AL8-AM8 -> 23
A9: Jorge Gonçalves | B9: GONCALVES, JORGE | C9: F | D9: P14 | E9: P14 | F9: P14 | G9: P14 | H9: F | I9: F | J9: P06 | K9: P06 | L9: P06 | M9: P06 | N9: F | O9: F | P9: P14 | Q9: P14 | R9: P14 | S9: P14 | T9: F | U9: F | V9: P09/ | W9: P09/ | X9: P09/ | Y9: P09/ | Z9: F | AA9: F | AB9: P22 | AC9: P22 | AD9: P22 | AE9: P22 | AF9: F | AH9: =VLOOKUP($B9,'MAR25'!$B:$AO,36,0) -> 0 | AI9: =COUNTIF(C9:AF9,"UA") -> 0 | AJ9: =AH9-AI9 -> 0 | AL9: =VLOOKUP($B9,'MAR25'!$B:$AO,40,0) -> 11 | AM9: =COUNTIF(C9:AF9,"U") -> 0 | AN9: =AL9-AM9 -> 11
A10: Catarina Pereira | B10: PEREIRA, CATARINA | C10: U | D10: U | E10: U | F10: F | G10: F | H10: P14 | I10: P14 | J10: P14 | K10: P14 | L10: F | M10: F | N10: P06 | O10: P06 | P10: P06 | Q10: P06 | R10: F | S10: F | T10: P14 | U10: P14 | V10: P14 | W10: P14 | X10: F | Y10: F | Z10: P06 | AA10: P06 | AB10: P06 | AC10: P06 | AD10: F | AE10: F | AF10: P14 | AH10: =VLOOKUP($B10,'MAR25'!$B:$AO,36,0) -> 0 | AI10: =COUNTIF(C10:AF10,"UA") -> 0 | AJ10: =AH10-AI10 -> 0 | AL10: =VLOOKUP($B10,'MAR25'!$B:$AO,40,0) -> 21 | AM10: =COUNTIF(C10:AF10,"U") -> 3 | AN10: =AL10-AM10 -> 18
A11: Sara Medeiros | B11: MEDEIROS, SARA | C11: P14 | D11: F | E11: F | F11: P06 | G11: P06 | H11: P06 | I11: P06 | J11: F | K11: F | L11: U | M11: U | N11: U | O11: U | P11: F | Q11: F | R11: P06 | S11: P06 | T11: P06 | U11: P06 | V11: F | W11: F | X11: P14 | Y11: P14 | Z11: P14 | AA11: F | AB11: F | AC11: P09/ | AD11: P09/ | AE11: FINJ | AF11: P09/ | AH11: =VLOOKUP($B11,'MAR25'!$B:$AO,36,0) -> 0 | AI11: =COUNTIF(C11:AF11,"UA") -> 0 | AJ11: =AH11-AI11 -> 0 | AL11: =VLOOKUP($B11,'MAR25'!$B:$AO,40,0) -> 22 | AM11: =COUNTIF(C11:AF11,"U") -> 4 | AN11: =AL11-AM11 -> 18
A12: Catia Martins | B12: MARTINS, CATIA | C12: F | D12: P14 | E12: P14 | F12: P14 | G12: P14 | H12: F | I12: F | J12: P06 | K12: P06 | L12: P06 | M12: P06 | N12: F | O12: F | P12: P14 | Q12: P14 | R12: P14 | S12: P14 | T12: F | U12: F | V12: P06 | W12: P06 | X12: P06 | Y12: P06 | Z12: F | AA12: F | AB12: P14 | AC12: P14 | AD12: P14 | AE12: P14 | AF12: F | AH12: =VLOOKUP($B12,'MAR25'!$B:$AO,36,0) -> 0 | AI12: =COUNTIF(C12:AF12,"UA") -> 0 | AJ12: =AH12-AI12 -> 0 | AL12: =VLOOKUP($B12,'MAR25'!$B:$AO,40,0) -> 17 | AM12: =COUNTIF(C12:AF12,"U") -> 0 | AN12: =AL12-AM12 -> 17
A14: Cgsupport
