Workbook

Sheet Sheet1
B2: Not Finalized
B3: Finalized

Sheet JAN
B2: Finalized | C2: HUB Services | E2: LGSP - Lufthansa Ground Services Portugal NIF : 509 842 593 Atividade: CAE 52230.R3 Sede e local de trabalho: Avenida da Boavista ED.Burgo, 1837 sala 13.1 Horario de Funcionamento: 24/7 IRT: Não Aplicável | AL2: Ferias 2025 | AP2: Ferias 2026 | AT2: Dias Trabalhados
C3: Janeiro | E3: Qui | F3: Sex | G3: Sab | H3: Dom | I3: Seg | J3: Ter | K3: Qua | L3: Qui | M3: Sex | N3: Sab | O3: Dom | P3: Seg | Q3: Ter | R3: Qua | S3: Qui | T3: Sex | U3: Sab | V3: Dom | W3: Seg | X3: Ter | Y3: Qua | Z3: Qui | AA3: Sex | AB3: Sab | AC3: Dom | AD3: Seg | AE3: Ter | AF3: Qua | AG3: Qui | AH3: Sex | AI3: Sab
E4: 1 | F4: 2 | G4: 3 | H4: 4 | I4: 5 | J4: 6 | K4: 7 | L4: 8 | M4: 9 | N4: 10 | O4: 11 | P4: 12 | Q4: 13 | R4: 14 | S4: 15 | T4: 16 | U4: 17 | V4: 18 | W4: 19 | X4: 20 | Y4: 21 | Z4: 22 | AA4: 23 | AB4: 24 | AC4: 25 | AD4: 26 | AE4: 27 | AF4: 28 | AG4: 29 | AH4: 30 | AI4: 31 | AL4: 2025 | AM4: Used | AN4: Left | AP4: 2026 | AQ4: Used | AR4: Left
B5: Hub Services Supervision | C5: Catarina Ferreira | D5: FERREIRA, CATARINA | E5: H | F5: P06 | G5: F | H5: F | I5: P06 | J5: P06 | K5: P06 | L5: F | M5: F | N5: P06 | O5: P06 | P5: P06 | Q5: P06 | R5: F | S5: F | T5: P14 | U5: P14 | V5: P14 | W5: P14 | X5: F | Y5: F | Z5: P06 | AA5: P06 | AB5: P06 | AC5: P06 | AD5: F | AE5: F | AF5: P14 | AG5: P14 | AH5: P14 | AI5: P14 | AL5: 1 | AM5: =COUNTIF(E5:AI5, "UA") -> 0 | AN5: =AL5-AM5 -> 1 | AQ5: =COUNTIF(E5:AI5, "U") -> 0 | AR5: =AP5-AQ5 -> 0 | AT5: =COUNTIF(E5:AI5,"P*")+COUNTIF(E5:AI5,"H*")+COUNTIF(E5:AI5,"T*")-COUNTIF(E5:AI5,"H")-COUNTIF(E5:AI5,"P") -> 20
C6: Miguel Pinto | D6: PINTO, MIGUEL | E6: B | F6: P14 | G6: P14 | H6: F | I6: F | J6: P06 | K6: P06 | L6: P06 | M6: P06 | N6: F | O6: F | P6: P14 | Q6: P14 | R6: P14 | S6: P14 | T6: F | U6: F | V6: P06 | W6: P06 | X6: P06 | Y6: P06 | Z6: F | AA6: F | AB6: P14 | AC6: P14 | AD6: P14 | AE6: P14 | AF6: F | AG6: F | AH6: P06 | AI6: P06 | AL6: 0 | AM6: =COUNTIF(E6:AI6, "UA") -> 0 | AN6: =AL6-AM6 -> 0 | AQ6: =COUNTIF(E6:AI6, "U") -> 0 | AR6: =AP6-AQ6 -> 0 | AT6: =COUNTIF(E6:AI6,"P*")+COUNTIF(E6:AI6,"H*")+COUNTIF(E6:AI6,"T*")-COUNTIF(E6:AI6,"H")-COUNTIF(E6:AI6,"P") -> 20
C7: João Santos Silva | D7: SANTOS SILVA, JOAO | E7: P14 | F7: P14 | G7: F | H7: P14 | I7: P14 | J7: P14 | K7: F | L7: F | M7: P06 | N7: P06 | O7: P06 | P7: P06 | Q7: F | R7: F | S7: P14 | T7: P14 | U7: P14 | V7: P14 | W7: F | X7: F | Y7: P06 | Z7: P06 | AA7: P06 | AB7: P06 | AC7: F | AD7: F | AE7: P22 | AF7: P22 | AG7: P22 | AH7: S3 | AI7: F | AL7: 1 | AM7: =COUNTIF(E7:AI7, "UA") -> 0 | AN7: =AL7-AM7 -> 1 | AQ7: =COUNTIF(E7:AI7, "U") -> 0 | AR7: =AP7-AQ7 -> 0 | AT7: =COUNTIF(E7:AI7,"P*")+COUNTIF(E7:AI7,"H*")+COUNTIF(E7:AI7,"T*")-COUNTIF(E7:AI7,"H")-COUNTIF(E7:AI7,"P") -> 20
C8: Ana Magalhães | D8: MAGALHAES, ANA CATARINA | E8: H | F8: UA | G8: F | H8: F | I8: P14 | J8: P14 | K8: P14 | L8: P14 | M8: F | N8: F | O8: P06 | P8: P06 | Q8: P06 | R8: P06 | S8: F | T8: F | U8: P14 | V8: P14 | W8: P14 | X8: P14 | Y8: F | Z8: F | AA8: P06 | AB8: P06 | AC8: P06 | AD8: P06 | AE8: F | AF8: F | AG8: P14 | AH8: P14 | AI8: P14 | AL8: 3 | AM8: =COUNTIF(E8:AI8, "UA") -> 1 | AN8: =AL8-AM8 -> 2 | AQ8: =COUNTIF(E8:AI8, "U") -> 0 | AR8: =AP8-AQ8 -> 0 | AT8: =COUNTIF(E8:AI8,"P*")+COUNTIF(E8:AI8,"H*")+COUNTIF(E8:AI8,"T*")-COUNTIF(E8:AI8,"H")-COUNTIF(E8:AI8,"P") -> 19
C9: Jorge Gonçalves | D9: GONCALVES, JORGE | E9: F | F9: F | G9: U | H9: U | I9: F | J9: F | K9: U | L9: U | M9: U | N9: U | O9: F | P9: F | Q9: U | R9: U | S9: U | T9: U | U9: F | V9: F | W9: P06 | X9: P06 | Y9: P06 | Z9: P06 | AA9: F | AB9: F | AC9: P14 | AD9: P14 | AE9: P14 | AF9: P14 | AG9: F | AH9: F | AI9: P06 | AL9: 0 | AM9: =COUNTIF(E9:AI9, "UA") -> 0 | AN9: =AL9-AM9 -> 0 | AQ9: =COUNTIF(E9:AI9, "U") -> 10 | AR9: =AP9-AQ9 -> -10 | AT9: =COUNTIF(E9:AI9,"P*")+COUNTIF(E9:AI9,"H*")+COUNTIF(E9:AI9,"T*")-COUNTIF(E9:AI9,"H")-COUNTIF(E9:AI9,"P") -> 9
C10: Sara Medeiros | D10: MEDEIROS, SARA | E10: P06 | F10: P06 | G10: F | H10: F | I10: P06 | J10: P06 | K10: P06 | L10: P06 | M10: F | N10: F | O10: P14 | P10: P14 | Q10: P14 | R10: P14 | S10: F | T10: F | U10: P06 | V10: P06 | W10: P06 | X10: P06 | Y10: F | Z10: F | AA10: P14 | AB10: P14 | AC10: P14 | AD10: P14 | AE10: F | AF10: F | AG10: P06 | AH10: P06 | AI10: P06 | AL10: 0 | AM10: =COUNTIF(E10:AI10, "UA") -> 0 | AN10: =AL10-AM10 -> 0 | AQ10: =COUNTIF(E10:AI10, "U") -> 0 | AR10: =AP10-AQ10 -> 0 | AT10: =COUNTIF(E10:AI10,"P*")+COUNTIF(E10:AI10,"H*")+COUNTIF(E10:AI10,"T*")-COUNTIF(E10:AI10,"H")-COUNTIF(E10:AI10,"P") -> 21
C11: Catarina Pereira | D11: PEREIRA, CATARINA | E11: P11 | F11: P07 | G11: P06 | H11: P06 | I11: F | J11: F | K11: P14 | L11: P14 | M11: P14 | N11: P14 | O11: F | P11: F | Q11: P06 | R11: P06 | S11: P06 | T11: P06 | U11: F | V11: F | W11: P14 | X11: P14 | Y11: P14 | Z11: P14 | AA11: F | AB11: F | AC11: P06 | AD11: P06 | AE11: P06 | AF11: P06 | AG11: F | AH11: F | AI11: P11 | AL11: 0 | AM11: =COUNTIF(E11:AI11, "UA") -> 0 | AN11: =AL11-AM11 -> 0 | AQ11: =COUNTIF(E11:AI11, "U") -> 0 | AR11: =AP11-AQ11 -> 0 | AT11: =COUNTIF(E11:AI11,"P*")+COUNTIF(E11:AI11,"H*")+COUNTIF(E11:AI11,"T*")-COUNTIF(E11:AI11,"H")-COUNTIF(E11:AI11,"P") -> 21
C12: Catia Martins | D12: MARTINS, CATIA | E12: F | F12: F | G12: P06 | H12: P06 | I12: P06 | J12: P06 | K12: F | L12: F | M12: P14 | N12: P14 | O12: P14 | P12: P14 | Q12: F | R12: F | S12: P06 | T12: P06 | U12: P06 | V12: P06 | W12: F | X12: F | Y12: P14 | Z12: P14 | AA12: P14 | AB12: P14 | AC12: F | AD12: F | AE12: P06 | AF12: P06 | AG12: P06 | AH12: P06 | AI12: F | AL12: 0 | AM12: =COUNTIF(E12:AI12, "UA") -> 0 | AN12: =AL12-AM12 -> 0 | AQ12: =COUNTIF(E12:AI12, "U") -> 0 | AR12: =AP12-AQ12 -> 0 | AT12: =COUNTIF(E12:AI12,"P*")+COUNTIF(E12:AI12,"H*")+COUNTIF(E12:AI12,"T*")-COUNTIF(E12:AI12,"H")-COUNTIF(E12:AI12,"P") -> 20
B13: Remote Passenger Recovery Team | C13: Ricardo Bessa | D13: BESSA, RICARDO | E13: P14 | F13: F | G13: F | H13: P06 | I13: P06 | J13: F | K13: F | L13: P14 | M13: P14 | N13: P14 | O13: P14 | P13: F | Q13: P06 | R13: P06 | S13: P06 | T13: P06 | U13: F | V13: F | W13: P14 | X13: P14 | Y13: P14 | Z13: P14 | AA13: F | AB13: F | AC13: P22 | AD13: P22 | AE13: P22 | AF13: P22 | AG13: F | AH13: F | AI13: P14 | AL13: 0 | AM13: =COUNTIF(E13:AI13, "UA") -> 0 | AN13: =AL13-AM13 -> 0 | AQ13: =COUNTIF(E13:AI13, "U") -> 0 | AR13: =AP13-AQ13 -> 0 | AT13: =COUNTIF(E13:AI13,"P*")+COUNTIF(E13:AI13,"H*")+COUNTIF(E13:AI13,"T*")-COUNTIF(E13:AI13,"H")-COUNTIF(E13:AI13,"P") -> 20
C14: Samuel Neves | D14: NEVES, SAMUEL | E14: P06 | F14: F | G14: F | H14: P22 | I14: P22 | J14: P22 | K14: P22 | L14: P22 | M14: F | N14: F | O14: F | P14: P14 | Q14: P14 | R14: P14 | S14: F | T14: F | U14: P06 | V14: P06 | W14: P06 | X14: P06 | Y14: F | Z14: F | AA14: P14 | AB14: P14 | AC14: P14 | AD14: P14 | AE14: F | AF14: P06 | AG14: P06 | AH14: P06 | AI14: P06 | AL14: 11 | AM14: =COUNTIF(E14:AI14, "UA") -> 0 | AN14: =AL14-AM14 -> 11 | AQ14: =COUNTIF(E14:AI14, "U") -> 0 | AR14: =AP14-AQ14 -> 0 | AT14: =COUNTIF(E14:AI14,"P*")+COUNTIF(E14:AI14,"H*")+COUNTIF(E14:AI14,"T*")-COUNTIF(E14:AI14,"H")-COUNTIF(E14:AI14,"P") -> 21
C15: Ricardo Medeiros | D15: MEDEIROS, RICARDO | E15: H | F15: F | G15: F | H15: P06 | I15: P06 | J15: P06 | K15: F | L15: F | M15: P22 | N15: P22 | O15: P22 | P15: P22 | Q15: F | R15: F | S15: P14 | T15: P14 | U15: P14 | V15: P14 | W15: F | X15: F | Y15: P06 | Z15: P06 | AA15: P06 | AB15: P06 | AC15: F | AD15: F | AE15: P14 | AF15: P14 | AG15: P14 | AH15: P14 | AI15: F | AL15: 0 | AM15: =COUNTIF(E15:AI15, "UA") -> 0 | AN15: =AL15-AM15 -> 0 | AQ15: =COUNTIF(E15:AI15, "U") -> 0 | AR15: =AP15-AQ15 -> 0 | AT15: =COUNTIF(E15:AI15,"P*")+COUNTIF(E15:AI15,"H*")+COUNTIF(E15:AI15,"T*")-COUNTIF(E15:AI15,"H")-COUNTIF(E15:AI15,"P") -> 19
C16: Joana Pinheiro | D16: PINHEIRO, JOANA | E16: P06 | F16: P06 | G16: F | H16: F | I16: F | J16: P06 | K16: P06 | L16: P06 | M16: P06 | N16: S3 | O16: F | P16: F | Q16: P22 | R16: P22 | S16: P22 | T16: P22 | U16: F | V16: F | W16: P14 | X16: P14 | Y16: P14 | Z16: P14 | AA16: F | AB16: F | AC16: P06 | AD16: P06 | AE16: P06 | AF16: P06 | AG16: F | AH16: F | AI16: P14 | AL16: 0 | AM16: =COUNTIF(E16:AI16, "UA") -> 0 | AN16: =AL16-AM16 -> 0 | AQ16: =COUNTIF(E16:AI16, "U") -> 0 | AR16: =AP16-AQ16 -> 0 | AT16: =COUNTIF(E16:AI16,"P*")+COUNTIF(E16:AI16,"H*")+COUNTIF(E16:AI16,"T*")-COUNTIF(E16:AI16,"H")-COUNTIF(E16:AI16,"P") -> 19
C17: Bruna Lima | D17: LIMA, BRUNA | E17: H | F17: P14 | G17: P14 | H17: F | I17: F | J17: P06 | K17: P06 | L17: P06 | M17: F | N17: F | O17: P06 | P17: P06 | Q17: P06 | R17: P06 | S17: F | T17: F | U17: P22 | V17: P22 | W17: P22 | X17: P22 | Y17: F | Z17: F | AA17: S3 | AB17: UA | AC17: UA | AD17: UA | AE17: F | AF17: F | AG17: P06 | AH17: P06 | AI17: P06 | AL17: 4 | AM17: =COUNTIF(E17:AI17, "UA") -> 3 | AN17: =AL17-AM17 -> 1 | AQ17: =COUNTIF(E17:AI17, "U") -> 0 | AR17: =AP17-AQ17 -> 0 | AT17: =COUNTIF(E17:AI17,"P*")+COUNTIF(E17:AI17,"H*")+COUNTIF(E17:AI17,"T*")-COUNTIF(E17:AI17,"H")-COUNTIF(E17:AI17,"P") -> 16
C18: Ivo Latourrette | D18: LATOURRETTE, IVO | E18: P14 | F18: F | G18: F | H18: P14 | I18: P14 | J18: P14 | K18: F | L18: F | M18: P06 | N18: P06 | O18: P06 | P18: P06 | Q18: F | R18: F | S18: P06 | T18: P06 | U18: P06 | V18: P06 | W18: F | X18: F | Y18: P22 | Z18: P22 | AA18: P22 | AB18: P22 | AC18: F | AD18: F | AE18: P14 | AF18: P14 | AG18: P14 | AH18: P14 | AI18: F | AL18: 18 | AM18: =COUNTIF(E18:AI18, "UA") -> 0 | AN18: =AL18-AM18 -> 18 | AQ18: =COUNTIF(E18:AI18, "U") -> 0 | AR18: =AP18-AQ18 -> 0 | AT18: =COUNTIF(E18:AI18,"P*")+COUNTIF(E18:AI18,"H*")+COUNTIF(E18:AI18,"T*")-COUNTIF(E18:AI18,"H")-COUNTIF(E18:AI18,"P") -> 20
C19: Inês Coelho | D19: COELHO, INES | E19: F | F19: P22 | G19: P22 | H19: P22 | I19: P22 | J19: F | K19: F | L19: P14 | M19: P14 | N19: P14 | O19: P14 | P19: F | Q19: P06 | R19: P06 | S19: P06 | T19: P06 | U19: F | V19: F | W19: P06 | X19: P06 | Y19: P06 | Z19: P06 | AA19: F | AB19: F | AC19: P06 | AD19: P06 | AE19: P06 | AF19: F | AG19: F | AH19: F | AI19: S3 | AL19: 1 | AM19: =COUNTIF(E19:AI19, "UA") -> 0 | AN19: =AL19-AM19 -> 1 | AQ19: =COUNTIF(E19:AI19, "U") -> 0 | AR19: =AP19-AQ19 -> 0 | AT19: =COUNTIF(E19:AI19,"P*")+COUNTIF(E19:AI19,"H*")+COUNTIF(E19:AI19,"T*")-COUNTIF(E19:AI19,"H")-COUNTIF(E19:AI19,"P") -> 19
C20: Jose Alves | D20: ALVES, JOSE | E20: P06 | F20: P06 | G20: F | H20: F | I20: P22 | J20: P22 | K20: P22 | L20: P22 | M20: F | N20: F | O20: P14 | P20: P14 | Q20: P14 | R20: P14 | S20: F | T20: F | U20: P06 | V20: P06 | W20: P06 | X20: P06 | Y20: F | Z20: F | AA20: P06 | AB20: P06 | AC20: U | AD20: U | AE20: F | AF20: F | AG20: U | AH20: P22 | AI20: P22 | AL20: 0 | AM20: =COUNTIF(E20:AI20, "UA") -> 0 | AN20: =AL20-AM20 -> 0 | AQ20: =COUNTIF(E20:AI20, "U") -> 3 | AR20: =AP20-AQ20 -> -3 | AT20: =COUNTIF(E20:AI20,"P*")+COUNTIF(E20:AI20,"H*")+COUNTIF(E20:AI20,"T*")-COUNTIF(E20:AI20,"H")-COUNTIF(E20:AI20,"P") -> 18
C21: Alefe Sobral | D21: SOBRAL, ALEFE | E21: F | F21: F | G21: P14 | H21: P14 | I21: P14 | J21: P14 | K21: F | L21: F | M21: P06 | N21: S3 | O21: P06 | P21: P06 | Q21: F | R21: F | S21: P14 | T21: P14 | U21: P14 | V21: P14 | W21: F | X21: F | Y21: P06 | Z21: P06 | AA21: P06 | AB21: P06 | AC21: F | AD21: F | AE21: P06 | AF21: P06 | AG21: P06 | AH21: P06 | AI21: F | AL21: 0 | AM21: =COUNTIF(E21:AI21, "UA") -> 0 | AN21: =AL21-AM21 -> 0 | AQ21: =COUNTIF(E21:AI21, "U") -> 0 | AR21: =AP21-AQ21 -> 0 | AT21: =COUNTIF(E21:AI21,"P*")+COUNTIF(E21:AI21,"H*")+COUNTIF(E21:AI21,"T*")-COUNTIF(E21:AI21,"H")-COUNTIF(E21:AI21,"P") -> 19
C22: Gonçalo Pereira | D22: PEREIRA, GONCALO | E22: F | F22: F | G22: P06 | H22: P06 | I22: F | J22: F | K22: P14 | L22: P14 | M22: P14 | N22: P13 | O22: F | P22: F | Q22: P06 | R22: E | S22: P06 | T22: P06 | U22: F | V22: F | W22: P14 | X22: P14 | Y22: P14 | Z22: P14 | AA22: F | AB22: F | AC22: P06 | AD22: P06 | AE22: P06 | AF22: P06 | AG22: F | AH22: F | AI22: P06 | AL22: 1 | AM22: =COUNTIF(E22:AI22, "UA") -> 0 | AN22: =AL22-AM22 -> 1 | AQ22: =COUNTIF(E22:AI22, "U") -> 0 | AR22: =AP22-AQ22 -> 0 | AT22: =COUNTIF(E22:AI22,"P*")+COUNTIF(E22:AI22,"H*")+COUNTIF(E22:AI22,"T*")-COUNTIF(E22:AI22,"H")-COUNTIF(E22:AI22,"P") -> 18
C23: Carlos Carvalhais | D23: CARVALHAIS, CARLOS | E23: P14 | F23: P14 | G23: F | H23: F | I23: P06 | J23: P06 | K23: P06 | L23: P06 | M23: F | N23: F | O23: P14 | P23: P14 | Q23: P14 | R23: P14 | S23: F | T23: F | U23: P06 | V23: P06 | W23: P06 | X23: P06 | Y23: F | Z23: F | AA23: P14 | AB23: P14 | AC23: P14 | AD23: P14 | AE23: F | AF23: F | AG23: P06 | AH23: P06 | AI23: P06 | AL23: 3 | AM23: =COUNTIF(E23:AI23, "UA") -> 0 | AN23: =AL23-AM23 -> 3 | AQ23: =COUNTIF(E23:AI23, "U") -> 0 | AR23: =AP23-AQ23 -> 0 | AT23: =COUNTIF(E23:AI23,"P*")+COUNTIF(E23:AI23,"H*")+COUNTIF(E23:AI23,"T*")-COUNTIF(E23:AI23,"H")-COUNTIF(E23:AI23,"P") -> 21
C24: Ines Pilre | D24: PILRE, INES | E24: P22 | F24: P22 | G24: P22 | H24: F | I24: F | J24: P14 | K24: P14 | L24: F | M24: F | N24: P06 | O24: P06 | P24: P06 | Q24: F | R24: F | S24: P14 | T24: P14 | U24: P14 | V24: P14 | W24: F | X24: F | Y24: P06 | Z24: P06 | AA24: P06 | AB24: S3 | AC24: F | AD24: F | AE24: P14 | AF24: P14 | AG24: P14 | AH24: P14 | AI24: F | AL24: 0 | AM24: =COUNTIF(E24:AI24, "UA") -> 0 | AN24: =AL24-AM24 -> 0 | AQ24: =COUNTIF(E24:AI24, "U") -> 0 | AR24: =AP24-AQ24 -> 0 | AT24: =COUNTIF(E24:AI24,"P*")+COUNTIF(E24:AI24,"H*")+COUNTIF(E24:AI24,"T*")-COUNTIF(E24:AI24,"H")-COUNTIF(E24:AI24,"P") -> 19
B25: Hubs Services Team | C25: Raquel Oliveira | D25: OLIVEIRA, RAQUEL ALEXANDRA | E25: H | F25: F | G25: P06 | H25: P06 | I25: F | J25: F | K25: P14 | L25: P14 | M25: P14 | N25: S3 | O25: F | P25: F | Q25: P22 | R25: P22 | S25: P22 | T25: P22 | U25: F | V25: F | W25: P14 | X25: P14 | Y25: P14 | Z25: P14 | AA25: F | AB25: F | AC25: P06 | AD25: P06 | AE25: P06 | AF25: P06 | AG25: F | AH25: F | AI25: P14 | AL25: 4 | AM25: =COUNTIF(E25:AI25, "UA") -> 0 | AN25: =AL25-AM25 -> 4 | AQ25: =COUNTIF(E25:AI25, "U") -> 0 | AR25: =AP25-AQ25 -> 0 | AT25: =COUNTIF(E25:AI25,"P*")+COUNTIF(E25:AI25,"H*")+COUNTIF(E25:AI25,"T*")-COUNTIF(E25:AI25,"H")-COUNTIF(E25:AI25,"P") -> 18
C26: Rafael Silva | D26: SILVA, RAFAEL | E26: H | F26: P14 | G26: F | H26: F | I26: P06 | J26: P06 | K26: P06 | L26: P06 | M26: F | N26: F | O26: P14 | P26: P14 | Q26: P14 | R26: P14 | S26: F | T26: F | U26: S3 | V26: U | W26: P22 | X26: P22 | Y26: F | Z26: F | AA26: P14 | AB26: P14 | AC26: P14 | AD26: P14 | AE26: F | AF26: F | AG26: P06 | AH26: P06 | AI26: P06 | AL26: 0 | AM26: =COUNTIF(E26:AI26, "UA") -> 0 | AN26: =AL26-AM26 -> 0 | AQ26: =COUNTIF(E26:AI26, "U") -> 1 | AR26: =AP26-AQ26 -> -1 | AT26: =COUNTIF(E26:AI26,"P*")+COUNTIF(E26:AI26,"H*")+COUNTIF(E26:AI26,"T*")-COUNTIF(E26:AI26,"H")-COUNTIF(E26:AI26,"P") -> 18
C27: Jose Borges | D27: BORGES, JOSE | E27: F | F27: P06 | G27: P06 | H27: P06 | I27: F | J27: F | K27: P14 | L27: P14 | M27: P14 | N27: P14 | O27: F | P27: F | Q27: P06 | R27: P06 | S27: P06 | T27: P06 | U27: F | V27: F | W27: P06 | X27: P06 | Y27: P06 | Z27: P06 | AA27: F | AB27: F | AC27: P22 | AD27: P22 | AE27: P22 | AF27: P22 | AG27: F | AH27: F | AI27: P14 | AL27: 11 | AM27: =COUNTIF(E27:AI27, "UA") -> 0 | AN27: =AL27-AM27 -> 11 | AQ27: =COUNTIF(E27:AI27, "U") -> 0 | AR27: =AP27-AQ27 -> 0 | AT27: =COUNTIF(E27:AI27,"P*")+COUNTIF(E27:AI27,"H*")+COUNTIF(E27:AI27,"T*")-COUNTIF(E27:AI27,"H")-COUNTIF(E27:AI27,"P") -> 20
C28: Josue Fula | D28: FULA, JOSUE | E28: H | F28: UA | G28: F | H28: F | I28: K | J28: K | K28: K | L28: K | M28: K | N28: F | O28: P14 | P28: P14 | Q28: P14 | R28: P14 | S28: F | T28: F | U28: P06 | V28: P06 | W28: P06 | X28: P06 | Y28: F | Z28: F | AA28: P06 | AB28: P06 | AC28: P06 | AD28: P06 | AE28: F | AF28: F | AG28: P22 | AH28: P22 | AI28: P22 | AL28: 1 | AM28: =COUNTIF(E28:AI28, "UA") -> 1 | AN28: =AL28-AM28 -> 0 | AQ28: =COUNTIF(E28:AI28, "U") -> 0 | AR28: =AP28-AQ28 -> 0 | AT28: =COUNTIF(E28:AI28,"P*")+COUNTIF(E28:AI28,"H*")+COUNTIF(E28:AI28,"T*")-COUNTIF(E28:AI28,"H")-COUNTIF(E28:AI28,"P") -> 15
C29: Barbara Pereira | D29: PEREIRA, BARBARA | E29: H | F29: F | G29: F | H29: P14 | I29: P14 | J29: P14 | K29: F | L29: F | M29: P06 | N29: P06 | O29: P06 | P29: P06 | Q29: F | R29: F | S29: P10 | T29: P10 | U29: P10 | V29: P10 | W29: F | X29: F | Y29: P22 | Z29: P22 | AA29: P22 | AB29: P22 | AC29: F | AD29: F | AE29: P14 | AF29: P14 | AG29: P14 | AH29: P14 | AI29: F | AL29: 1 | AM29: =COUNTIF(E29:AI29, "UA") -> 0 | AN29: =AL29-AM29 -> 1 | AQ29: =COUNTIF(E29:AI29, "U") -> 0 | AR29: =AP29-AQ29 -> 0 | AT29: =COUNTIF(E29:AI29,"P*")+COUNTIF(E29:AI29,"H*")+COUNTIF(E29:AI29,"T*")-COUNTIF(E29:AI29,"H")-COUNTIF(E29:AI29,"P") -> 19
C30: Dulani Monteiro | D30: MONTEIRO, DULANI | E30: P06 | F30: F | G30: F | H30: P14 | I30: P14 | J30: F | K30: P14 | L30: P14 | M30: P14 | N30: P14 | O30: F | P30: F | Q30: P06 | R30: P06 | S30: P06 | T30: P06 | U30: F | V30: F | W30: P14 | X30: P14 | Y30: P14 | Z30: P14 | AA30: F | AB30: F | AC30: P06 | AD30: P06 | AE30: P06 | AF30: P06 | AG30: F | AH30: F | AI30: P06 | AL30: 0 | AM30: =COUNTIF(E30:AI30, "UA") -> 0 | AN30: =AL30-AM30 -> 0 | AQ30: =COUNTIF(E30:AI30, "U") -> 0 | AR30: =AP30-AQ30 -> 0 | AT30: =COUNTIF(E30:AI30,"P*")+COUNTIF(E30:AI30,"H*")+COUNTIF(E30:AI30,"T*")-COUNTIF(E30:AI30,"H")-COUNTIF(E30:AI30,"P") -> 20
C31: Diogo Arantes | D31: ARANTES, DIOGO | E31: H | F31: UA | G31: F | H31: F | I31: UA | J31: UA | K31: UA | L31: UA | M31: F | N31: F | O31: P14 | P31: P14 | Q31: P14 | R31: P14 | S31: F | T31: F | U31: S3 | V31: P06 | W31: P06 | X31: P06 | Y31: F | Z31: F | AA31: P14 | AB31: P14 | AC31: P14 | AD31: P14 | AE31: F | AF31: F | AG31: P06 | AH31: P06 | AI31: UA | AL31: 12 | AM31: =COUNTIF(E31:AI31, "UA") -> 6 | AN31: =AL31-AM31 -> 6 | AQ31: =COUNTIF(E31:AI31, "U") -> 0 | AR31: =AP31-AQ31 -> 0 | AT31: =COUNTIF(E31:AI31,"P*")+COUNTIF(E31:AI31,"H*")+COUNTIF(E31:AI31,"T*")-COUNTIF(E31:AI31,"H")-COUNTIF(E31:AI31,"P") -> 13
C32: Jessica Martins | D32: MARTINS, JESSICA | E32: K | F32: K | G32: K | H32: K | I32: K | J32: K | K32: K | L32: K | M32: K | N32: K | O32: K | P32: K | Q32: F | R32: F | S32: P14 | T32: P14 | U32: P14 | V32: P14 | W32: F | X32: F | Y32: P06 | Z32: P06 | AA32: P06 | AB32: P06 | AC32: F | AD32: F | AE32: P14 | AF32: P14 | AG32: P14 | AH32: P14 | AI32: F | AL32: 8 | AM32: =COUNTIF(E32:AI32, "UA") -> 0 | AN32: =AL32-AM32 -> 8 | AQ32: =COUNTIF(E32:AI32, "U") -> 0 | AR32: =AP32-AQ32 -> 0 | AT32: =COUNTIF(E32:AI32,"P*")+COUNTIF(E32:AI32,"H*")+COUNTIF(E32:AI32,"T*")-COUNTIF(E32:AI32,"H")-COUNTIF(E32:AI32,"P") -> 12
C33: Carla Ferreira | D33: FERREIRA, CARLA | E33: P06 | F33: P06 | G33: P06 | H33: F | I33: F | J33: P14 | K33: P14 | L33: P14 | M33: P14 | N33: F | O33: F | P33: P06 | Q33: P06 | R33: P06 | S33: P06 | T33: F | U33: F | V33: P14 | W33: P14 | X33: P14 | Y33: P14 | Z33: F | AA33: F | AB33: P06 | AC33: P06 | AD33: P06 | AE33: P06 | AF33: F | AG33: F | AH33: P14 | AI33: P14 | AL33: 7 | AM33: =COUNTIF(E33:AI33, "UA") -> 0 | AN33: =AL33-AM33 -> 7 | AQ33: =COUNTIF(E33:AI33, "U") -> 0 | AR33: =AP33-AQ33 -> 0 | AT33: =COUNTIF(E33:AI33,"P*")+COUNTIF(E33:AI33,"H*")+COUNTIF(E33:AI33,"T*")-COUNTIF(E33:AI33,"H")-COUNTIF(E33:AI33,"P") -> 21
C34: Rafael Medina | D34: MEDINA, RAFAEL | E34: P14 | F34: F | G34: F | H34: P06 | I34: P06 | J34: P06 | K34: P06 | L34: F | M34: F | N34: P14 | O34: P14 | P34: P14 | Q34: P14 | R34: F | S34: F | T34: P06 | U34: P06 | V34: P06 | W34: P06 | X34: F | Y34: F | Z34: P14 | AA34: P14 | AB34: P14 | AC34: P14 | AD34: F | AE34: F | AF34: UA | AG34: P06 | AH34: P06 | AI34: P06 | AL34: 1 | AM34: =COUNTIF(E34:AI34, "UA") -> 1 | AN34: =AL34-AM34 -> 0 | AQ34: =COUNTIF(E34:AI34, "U") -> 0 | AR34: =AP34-AQ34 -> 0 | AT34: =COUNTIF(E34:AI34,"P*")+COUNTIF(E34:AI34,"H*")+COUNTIF(E34:AI34,"T*")-COUNTIF(E34:AI34,"H")-COUNTIF(E34:AI34,"P") -> 20
C35: Catia Neves | D35: NEVES, CATIA | E35: F | F35: P14 | G35: P14 | H35: P14 | I35: S3 | J35: F | K35: F | L35: P06 | M35: P06 | N35: P06 | O35: P06 | P35: F | Q35: F | R35: P14 | S35: P14 | T35: P14 | U35: P14 | V35: F | W35: F | X35: P06 | Y35: P06 | Z35: P06 | AA35: P06 | AB35: F | AC35: F | AD35: P14 | AE35: P14 | AF35: P14 | AG35: P14 | AH35: F | AI35: F | AL35: 5 | AM35: =COUNTIF(E35:AI35, "UA") -> 0 | AN35: =AL35-AM35 -> 5 | AQ35: =COUNTIF(E35:AI35, "U") -> 0 | AR35: =AP35-AQ35 -> 0 | AT35: =COUNTIF(E35:AI35,"P*")+COUNTIF(E35:AI35,"H*")+COUNTIF(E35:AI35,"T*")-COUNTIF(E35:AI35,"H")-COUNTIF(E35:AI35,"P") -> 19
B36: LHX & Catering | C36: Ana Telma Carvalho | D36: CARVALHO, ANA | E36: F | F36: H05 | G36: H05 | H36: H05 | I36: H05 | J36: F | K36: F | L36: P13 | M36: P13 | N36: P13 | O36: P13 | P36: F | Q36: F | R36: H05 | S36: H05 | T36: H05 | U36: H05 | V36: F | W36: F | X36: P13 | Y36: P13 | Z36: P13 | AA36: P13 | AB36: F | AC36: F | AD36: H05 | AE36: H05 | AF36: H05 | AG36: H05 | AH36: F | AI36: F | AL36: 0 | AM36: =COUNTIF(E36:AI36, "UA") -> 0 | AN36: =AL36-AM36 -> 0 | AQ36: =COUNTIF(E36:AI36, "U") -> 0 | AR36: =AP36-AQ36 -> 0 | AT36: =COUNTIF(E36:AI36,"P*")+COUNTIF(E36:AI36,"H*")+COUNTIF(E36:AI36,"T*")-COUNTIF(E36:AI36,"H")-COUNTIF(E36:AI36,"P") -> 20
C37: Catia Craveiro | D37: CRAVEIRO, CATIA | E37: H | F37: F | G37: F | H37: S3 | I37: P13 | J37: P13 | K37: P13 | L37: F | M37: F | N37: H05 | O37: H05 | P37: H05 | Q37: H05 | R37: F | S37: F | T37: P13 | U37: P13 | V37: P13 | W37: P13 | X37: F | Y37: F | Z37: H05 | AA37: H05 | AB37: H05 | AC37: H05 | AD37: F | AE37: F | AF37: P13 | AG37: P13 | AH37: P13 | AI37: P13 | AL37: 0 | AM37: =COUNTIF(E37:AI37, "UA") -> 0 | AN37: =AL37-AM37 -> 0 | AQ37: =COUNTIF(E37:AI37, "U") -> 0 | AR37: =AP37-AQ37 -> 0 | AT37: =COUNTIF(E37:AI37,"P*")+COUNTIF(E37:AI37,"H*")+COUNTIF(E37:AI37,"T*")-COUNTIF(E37:AI37,"H")-COUNTIF(E37:AI37,"P") -> 19
C38: Maria Vitoria Almeida | D38: ALMEIDA, MARIA VITORIA | E38: H | F38: P13 | G38: P13 | H38: F | I38: F | J38: H05 | K38: H05 | L38: H05 | M38: H05 | N38: F | O38: F | P38: P13 | Q38: P13 | R38: P13 | S38: P13 | T38: F | U38: F | V38: H05 | W38: H05 | X38: H05 | Y38: H05 | Z38: F | AA38: F | AB38: P13 | AC38: P13 | AD38: P13 | AE38: P13 | AF38: F | AG38: F | AH38: H05 | AI38: H05 | AL38: 0 | AM38: =COUNTIF(E38:AI38, "UA") -> 0 | AN38: =AL38-AM38 -> 0 | AQ38: =COUNTIF(E38:AI38, "U") -> 0 | AR38: =AP38-AQ38 -> 0 | AT38: =COUNTIF(E38:AI38,"P*")+COUNTIF(E38:AI38,"H*")+COUNTIF(E38:AI38,"T*")-COUNTIF(E38:AI38,"H")-COUNTIF(E38:AI38,"P") -> 20
C39: Jessica Santos | D39: SANTOS, JESSICA | E39: M | F39: M | G39: M | H39: M | I39: M | J39: M | K39: M | L39: M | M39: M | N39: M | O39: M | P39: M | Q39: M | R39: M | S39: M | T39: M | U39: M | V39: M | W39: M | X39: M | Y39: M | Z39: M | AA39: M | AB39: M | AC39: M | AD39: M | AE39: M | AF39: M | AG39: M | AH39: M | AI39: M | AL39: 19 | AM39: =COUNTIF(E39:AI39, "UA") -> 0 | AN39: =AL39-AM39 -> 19 | AQ39: =COUNTIF(E39:AI39, "U") -> 0 | AR39: =AP39-AQ39 -> 0 | AT39: =COUNTIF(E39:AI39,"P*")+COUNTIF(E39:AI39,"H*")+COUNTIF(E39:AI39,"T*")-COUNTIF(E39:AI39,"H")-COUNTIF(E39:AI39,"P") -> 0
B40: INAD HUB/CG/DEPO | C40: Cristiana Ferreira | D40: FERREIRA, CRISTIANA MARGARIDA | E40: K | F40: M | G40: M | H40: M | I40: M | J40: M | K40: M | L40: M | M40: M | N40: M | O40: M | P40: M | Q40: M | R40: M | S40: M | T40: M | U40: M | V40: M | W40: M | X40: M | Y40: M | Z40: M | AA40: M | AB40: M | AC40: M | AD40: M | AE40: M | AF40: M | AG40: M | AH40: M | AI40: M | AL40: 14 | AM40: =COUNTIF(E40:AI40, "UA") -> 0 | AN40: =AL40-AM40 -> 14 | AQ40: =COUNTIF(E40:AI40, "U") -> 0 | AR40: =AP40-AQ40 -> 0 | AT40: =COUNTIF(E40:AI40,"P*")+COUNTIF(E40:AI40,"H*")+COUNTIF(E40:AI40,"T*")-COUNTIF(E40:AI40,"H")-COUNTIF(E40:AI40,"P") -> 0
C41: Mauro Silva | D41: SILVA, MAURO | E41: H | F41: P08/ | G41: F | H41: F | I41: P08/ | J41: P08/ | K41: P08/ | L41: P08/ | M41: P08/ | N41: F | O41: F | P41: P08/ | Q41: P08/ | R41: P08/ | S41: P08/ | T41: P08/ | U41: F | V41: F | W41: P08/ | X41: P08/ | Y41: P08/ | Z41: P08/ | AA41: P08/ | AB41: F | AC41: F | AD41: P08/ | AE41: P08/ | AF41: P08/ | AG41: P08/ | AH41: P08/ | AI41: F | AL41: 0 | AM41: =COUNTIF(E41:AI41, "UA") -> 0 | AN41: =AL41-AM41 -> 0 | AQ41: =COUNTIF(E41:AI41, "U") -> 0 | AR41: =AP41-AQ41 -> 0 | AT41: =COUNTIF(E41:AI41,"P*")+COUNTIF(E41:AI41,"H*")+COUNTIF(E41:AI41,"T*")-COUNTIF(E41:AI41,"H")-COUNTIF(E41:AI41,"P") -> 21
...

Sheet FEB
B2: Not Finalized | C2: HUB Services | E2: LGSP - Lufthansa Ground Services Portugal NIF : 509 842 593 Atividade: CAE 52230.R3 Sede e local de trabalho: Avenida da Boavista ED.Burgo, 1837 sala 13.1 Horario de Funcionamento: 24/7 IRT : Nao Aplicavel | AH2: Ferias 2025 | AL2: Ferias 2026 | AP2: Dias Trabalhados
C3: Fevereiro | E3: Dom | F3: Seg | G3: Ter | H3: Qua | I3: Qui | J3: Sex | K3: Sab | L3: Dom | M3: Seg | N3: Ter | O3: Qua | P3: Qui | Q3: Sex | R3: Sab | S3: Dom | T3: Seg | U3: Ter | V3: Qua | W3: Qui | X3: Sex | Y3: Sab | Z3: Dom | AA3: Seg | AB3: Ter | AC3: Qua | AD3: Qui | AE3: Sex | AF3: Sab
E4: 1 | F4: 2 | G4: 3 | H4: 4 | I4: 5 | J4: 6 | K4: 7 | L4: 8 | M4: 9 | N4: 10 | O4: 11 | P4: 12 | Q4: 13 | R4: 14 | S4: 15 | T4: 16 | U4: 17 | V4: 18 | W4: 19 | X4: 20 | Y4: 21 | Z4: 22 | AA4: 23 | AB4: 24 | AC4: 25 | AD4: 26 | AE4: 27 | AF4: 28 | AH4: 2025 | AI4: Used | AJ4: Left | AL4: 2026 | AM4: Used | AN4: Left
B5: Hub Services Supervision | C5: Catarina Ferreira | D5: FERREIRA, CATARINA | E5: F | F5: F | G5: P06 | H5: P06 | I5: P06 | J5: P06 | K5: F | L5: F | M5: P14 | N5: P14 | O5: P14 | P5: P14 | Q5: F | R5: F | S5: P06 | T5: P06 | U5: P06 | V5: P06 | W5: F | X5: F | Y5: P14 | Z5: P14 | AA5: P14 | AB5: P14 | AC5: F | AD5: F | AE5: P06 | AF5: P06 | AH5: =JAN!AN5 -> 1 | AI5: =COUNTIF(E5:AF5, "UA") -> 0 | AJ5: =AH5-AI5 -> 1 | AM5: =COUNTIF(E5:AF5, "U") -> 0 | AN5: =AL5-AM5 -> 0 | AP5: =COUNTIF(E5:AF5,"P*")+COUNTIF(E5:AF5,"H*")+COUNTIF(E5:AF5,"T*")-COUNTIF(E5:AF5,"H")-COUNTIF(E5:AF5,"P") -> 18
C6: Miguel Pinto | D6: PINTO, MIGUEL | E6: P06 | F6: P06 | G6: F | H6: F | I6: P14 | J6: P14 | K6: P10 | L6: P06 | M6: F | N6: F | O6: S3 | P6: U | Q6: U | R6: U | S6: F | T6: F | U6: H | V6: U | W6: U | X6: U | Y6: F | Z6: F | AA6: P06 | AB6: P06 | AC6: P06 | AD6: P06 | AE6: F | AF6: F | AH6: =JAN!AN6 -> 0 | AI6: =COUNTIF(E6:AF6, "UA") -> 0 | AJ6: =AH6-AI6 -> 0 | AM6: =COUNTIF(E6:AF6, "U") -> 6 | AN6: =AL6-AM6 -> -6 | AP6: =COUNTIF(E6:AF6,"P*")+COUNTIF(E6:AF6,"H*")+COUNTIF(E6:AF6,"T*")-COUNTIF(E6:AF6,"H")-COUNTIF(E6:AF6,"P") -> 10
C7: João Santos Silva | D7: SANTOS SILVA, JOAO | E7: F | F7: P06 | G7: P06 | H7: P06 | I7: P06 | J7: F | K7: F | L7: P14 | M7: P14 | N7: P14 | O7: P14 | P7: F | Q7: F | R7: P06 | S7: P06 | T7: P06 | U7: P06 | V7: F | W7: F | X7: P06 | Y7: P06 | Z7: P06 | AA7: P06 | AB7: F | AC7: F | AD7: P22 | AE7: P22 | AF7: P22 | AH7: =JAN!AN7 -> 1 | AI7: =COUNTIF(E7:AF7, "UA") -> 0 | AJ7: =AH7-AI7 -> 1 | AM7: =COUNTIF(E7:AF7, "U") -> 0 | AN7: =AL7-AM7 -> 0 | AP7: =COUNTIF(E7:AF7,"P*")+COUNTIF(E7:AF7,"H*")+COUNTIF(E7:AF7,"T*")-COUNTIF(E7:AF7,"H")-COUNTIF(E7:AF7,"P") -> 19
C8: Ana Magalhães | D8: MAGALHAES, ANA CATARINA | E8: P14 | F8: F | G8: F | H8: P06 | I8: P06 | J8: P06 | K8: P06 | L8: F | M8: F | N8: P14 | O8: P14 | P8: P14 | Q8: P14 | R8: F | S8: F | T8: P06 | U8: P06 | V8: P06 | W8: P06 | X8: F | Y8: F | Z8: P14 | AA8: P14 | AB8: P14 | AC8: P14 | AD8: F | AE8: F | AF8: P06 | AH8: =JAN!AN8 -> 2 | AI8: =COUNTIF(E8:AF8, "UA") -> 0 | AJ8: =AH8-AI8 -> 2 | AM8: =COUNTIF(E8:AF8, "U") -> 0 | AN8: =AL8-AM8 -> 0 | AP8: =COUNTIF(E8:AF8,"P*")+COUNTIF(E8:AF8,"H*")+COUNTIF(E8:AF8,"T*")-COUNTIF(E8:AF8,"H")-COUNTIF(E8:AF8,"P") -> 18
C9: Jorge Gonçalves | D9: GONCALVES, JORGE | E9: P06 | F9: P06 | G9: P06 | H9: F | I9: F | J9: P14 | K9: P14 | L9: P14 | M9: P14 | N9: F | O9: F | P9: P06 | Q9: P06 | R9: P06 | S9: P06 | T9: F | U9: F | V9: P14 | W9: P14 | X9: P14 | Y9: P14 | Z9: F | AA9: F | AB9: P06 | AC9: P06 | AD9: P06 | AE9: P06 | AF9: F | AH9: =JAN!AN9 -> 0 | AI9: =COUNTIF(E9:AF9, "UA") -> 0 | AJ9: =AH9-AI9 -> 0 | AM9: =COUNTIF(E9:AF9, "U") -> 0 | AN9: =AL9-AM9 -> 0 | AP9: =COUNTIF(E9:AF9,"P*")+COUNTIF(E9:AF9,"H*")+COUNTIF(E9:AF9,"T*")-COUNTIF(E9:AF9,"H")-COUNTIF(E9:AF9,"P") -> 19
C10: Sara Medeiros | D10: MEDEIROS, SARA | E10: P06 | F10: F | G10: F | H10: P14 | I10: P14 | J10: P14 | K10: P14 | L10: F | M10: F | N10: P06 | O10: P06 | P10: P06 | Q10: P06 | R10: F | S10: F | T10: P14 | U10: P14 | V10: P14 | W10: P14 | X10: F | Y10: F | Z10: P06 | AA10: P06 | AB10: P06 | AC10: P06 | AD10: F | AE10: F | AF10: S3 | AH10: =JAN!AN10 -> 0 | AI10: =COUNTIF(E10:AF10, "UA") -> 0 | AJ10: =AH10-AI10 -> 0 | AM10: =COUNTIF(E10:AF10, "U") -> 0 | AN10: =AL10-AM10 -> 0 | AP10: =COUNTIF(E10:AF10,"P*")+COUNTIF(E10:AF10,"H*")+COUNTIF(E10:AF10,"T*")-COUNTIF(E10:AF10,"H")-COUNTIF(E10:AF10,"P") -> 17
C11: Catarina Pereira | D11: PEREIRA, CATARINA | E11: P14 | F11: P14 | G11: P14 | H11: F | I11: F | J11: P06 | K11: P06 | L11: P06 | M11: P06 | N11: F | O11: F | P11: P14 | Q11: P14 | R11: P14 | S11: P14 | T11: F | U11: F | V11: P06 | W11: P06 | X11: P06 | Y11: P06 | Z11: F | AA11: F | AB11: P14 | AC11: P14 | AD11: P14 | AE11: P14 | AF11: F | AH11: =JAN!AN11 -> 0 | AI11: =COUNTIF(E11:AF11, "UA") -> 0 | AJ11: =AH11-AI11 -> 0 | AM11: =COUNTIF(E11:AF11, "U") -> 0 | AN11: =AL11-AM11 -> 0 | AP11: =COUNTIF(E11:AF11,"P*")+COUNTIF(E11:AF11,"H*")+COUNTIF(E11:AF11,"T*")-COUNTIF(E11:AF11,"H")-COUNTIF(E11:AF11,"P") -> 19
C12: Catia Martins | D12: MARTINS, CATIA | E12: F | F12: P14 | G12: P14 | H12: P14 | I12: P14 | J12: F | K12: F | L12: P06 | M12: P06 | N12: P06 | O12: B | P12: F | Q12: F | R12: U | S12: U | T12: U | U12: H | V12: F | W12: F | X12: P06 | Y12: P06 | Z12: P06 | AA12: P06 | AB12: F | AC12: F | AD12: P14 | AE12: P14 | AF12: P14 | AH12: =JAN!AN12 -> 0 | AI12: =COUNTIF(E12:AF12, "UA") -> 0 | AJ12: =AH12-AI12 -> 0 | AM12: =COUNTIF(E12:AF12, "U") -> 3 | AN12: =AL12-AM12 -> -3 | AP12: =COUNTIF(E12:AF12,"P*")+COUNTIF(E12:AF12,"H*")+COUNTIF(E12:AF12,"T*")-COUNTIF(E12:AF12,"H")-COUNTIF(E12:AF12,"P") -> 14
B13: Remote Passenger Recovery Team | C13: Ricardo Bessa | D13: BESSA, RICARDO | E13: P14 | F13: P14 | G13: P14 | H13: F | I13: F | J13: P06 | K13: P06 | L13: P06 | M13: P06 | N13: F | O13: F | P13: P06 | Q13: P06 | R13: P06 | S13: P06 | T13: F | U13: F | V13: P22 | W13: P22 | X13: P22 | Y13: P22 | Z13: F | AA13: F | AB13: P14 | AC13: P14 | AD13: P14 | AE13: P14 | AF13: F | AH13: =JAN!AN13 -> 0 | AI13: =COUNTIF(E13:AF13, "UA") -> 0 | AJ13: =AH13-AI13 -> 0 | AM13: =COUNTIF(E13:AF13, "U") -> 0 | AN13: =AL13-AM13 -> 0 | AP13: =COUNTIF(E13:AF13,"P*")+COUNTIF(E13:AF13,"H*")+COUNTIF(E13:AF13,"T*")-COUNTIF(E13:AF13,"H")-COUNTIF(E13:AF13,"P") -> 19
C14: Samuel Neves | D14: NEVES, SAMUEL | E14: P06 | F14: F | G14: F | H14: P14 | I14: P14 | J14: P14 | K14: P14 | L14: F | M14: F | N14: P06 | O14: P06 | P14: P06 | Q14: P06 | R14: F | S14: F | T14: P06 | U14: P06 | V14: P06 | W14: P06 | X14: F | Y14: F | Z14: P22 | AA14: P22 | AB14: P22 | AC14: P22 | AD14: F | AE14: F | AF14: P14 | AH14: =JAN!AN14 -> 11 | AI14: =COUNTIF(E14:AF14, "UA") -> 0 | AJ14: =AH14-AI14 -> 11 | AM14: =COUNTIF(E14:AF14, "U") -> 0 | AN14: =AL14-AM14 -> 0 | AP14: =COUNTIF(E14:AF14,"P*")+COUNTIF(E14:AF14,"H*")+COUNTIF(E14:AF14,"T*")-COUNTIF(E14:AF14,"H")-COUNTIF(E14:AF14,"P") -> 18
C15: Ricardo Medeiros | D15: MEDEIROS, RICARDO | E15: F | F15: P06 | G15: P06 | H15: P06 | I15: P06 | J15: F | K15: F | L15: P14 | M15: P14 | N15: P14 | O15: P14 | P15: F | Q15: F | R15: P06 | S15: P06 | T15: P06 | U15: P06 | V15: F | W15: F | X15: P06 | Y15: P06 | Z15: P06 | AA15: P06 | AB15: F | AC15: F | AD15: P22 | AE15: P22 | AF15: P22 | AH15: =JAN!AN15 -> 0 | AI15: =COUNTIF(E15:AF15, "UA") -> 0 | AJ15: =AH15-AI15 -> 0 | AM15: =COUNTIF(E15:AF15, "U") -> 0 | AN15: =AL15-AM15 -> 0 | AP15: =COUNTIF(E15:AF15,"P*")+COUNTIF(E15:AF15,"H*")+COUNTIF(E15:AF15,"T*")-COUNTIF(E15:AF15,"H")-COUNTIF(E15:AF15,"P") -> 19
C16: Joana Pinheiro | D16: PINHEIRO, JOANA | E16: P14 | F16: P14 | G16: P14 | H16: F | I16: F | J16: P06 | K16: P06 | L16: P06 | M16: P06 | N16: F | O16: F | P16: P14 | Q16: P14 | R16: P14 | S16: P14 | T16: F | U16: F | V16: P06 | W16: P06 | X16: P06 | Y16: P06 | Z16: F | AA16: F | AB16: P14 | AC16: P14 | AD16: P14 | AE16: P14 | AF16: F | AH16: =JAN!AN16 -> 0 | AI16: =COUNTIF(E16:AF16, "UA") -> 0 | AJ16: =AH16-AI16 -> 0 | AM16: =COUNTIF(E16:AF16, "U") -> 0 | AN16: =AL16-AM16 -> 0 | AP16: =COUNTIF(E16:AF16,"P*")+COUNTIF(E16:AF16,"H*")+COUNTIF(E16:AF16,"T*")-COUNTIF(E16:AF16,"H")-COUNTIF(E16:AF16,"P") -> 19
C17: Bruna Lima | D17: LIMA, BRUNA | E17: P06 | F17: F | G17: F | H17: P14 | I17: P14 | J17: P14 | K17: P14 | L17: F | M17: F | N17: P06 | O17: P06 | P17: P06 | Q17: P06 | R17: F | S17: F | T17: P14 | U17: P14 | V17: P14 | W17: P14 | X17: F | Y17: F | Z17: UA | AA17: P06 | AB17: P06 | AC17: P06 | AD17: F | AE17: F | AF17: P06 | AH17: =JAN!AN17 -> 1 | AI17: =COUNTIF(E17:AF17, "UA") -> 1 | AJ17: =AH17-AI17 -> 0 | AM17: =COUNTIF(E17:AF17, "U") -> 0 | AN17: =AL17-AM17 -> 0 | AP17: =COUNTIF(E17:AF17,"P*")+COUNTIF(E17:AF17,"H*")+COUNTIF(E17:AF17,"T*")-COUNTIF(E17:AF17,"H")-COUNTIF(E17:AF17,"P") -> 17
C18: Ivo Latourrette | D18: LATOURRETTE, IVO | E18: F | F18: P06 | G18: P06 | H18: P06 | I18: UA | J18: F | K18: F | L18: UA | M18: UA | N18: UA | O18: UA | P18: F | Q18: F | R18: P22 | S18: P22 | T18: P22 | U18: P22 | V18: F | W18: F | X18: P14 | Y18: P14 | Z18: P14 | AA18: P14 | AB18: F | AC18: F | AD18: P06 | AE18: P06 | AF18: P06 | AH18: =JAN!AN18 -> 18 | AI18: =COUNTIF(E18:AF18, "UA") -> 5 | AJ18: =AH18-AI18 -> 13 | AM18: =COUNTIF(E18:AF18, "U") -> 0 | AN18: =AL18-AM18 -> 0 | AP18: =COUNTIF(E18:AF18,"P*")+COUNTIF(E18:AF18,"H*")+COUNTIF(E18:AF18,"T*")-COUNTIF(E18:AF18,"H")-COUNTIF(E18:AF18,"P") -> 14
C19: Inês Coelho | D19: COELHO, INES | E19: UA | F19: P14 | G19: P14 | H19: F | I19: F | J19: P06 | K19: P06 | L19: P06 | M19: P06 | N19: F | O19: F | P19: P14 | Q19: P14 | R19: P14 | S19: P14 | T19: F | U19: F | V19: P06 | W19: P06 | X19: P06 | Y19: P06 | Z19: F | AA19: F | AB19: P14 | AC19: P14 | AD19: P14 | AE19: P14 | AF19: F | AH19: =JAN!AN19 -> 1 | AI19: =COUNTIF(E19:AF19, "UA") -> 1 | AJ19: =AH19-AI19 -> 0 | AM19: =COUNTIF(E19:AF19, "U") -> 0 | AN19: =AL19-AM19 -> 0 | AP19: =COUNTIF(E19:AF19,"P*")+COUNTIF(E19:AF19,"H*")+COUNTIF(E19:AF19,"T*")-COUNTIF(E19:AF19,"H")-COUNTIF(E19:AF19,"P") -> 18
C20: Jose Alves | D20: ALVES, JOSE | E20: P22 | F20: F | G20: F | H20: P14 | I20: P14 | J20: P14 | K20: P14 | L20: F | M20: F | N20: P06 | O20: P06 | P20: P06 | Q20: P06 | R20: F | S20: F | T20: P14 | U20: P14 | V20: P14 | W20: P14 | X20: F | Y20: F | Z20: P06 | AA20: P06 | AB20: P06 | AC20: P06 | AD20: F | AE20: F | AF20: P14 | AH20: =JAN!AN20 -> 0 | AI20: =COUNTIF(E20:AF20, "UA") -> 0 | AJ20: =AH20-AI20 -> 0 | AM20: =COUNTIF(E20:AF20, "U") -> 0 | AN20: =AL20-AM20 -> 0 | AP20: =COUNTIF(E20:AF20,"P*")+COUNTIF(E20:AF20,"H*")+COUNTIF(E20:AF20,"T*")-COUNTIF(E20:AF20,"H")-COUNTIF(E20:AF20,"P") -> 18
C21: Alefe Sobral | D21: SOBRAL, ALEFE | E21: F | F21: P22 | G21: P22 | H21: P22 | I21: P22 | J21: F | K21: F | L21: P14 | M21: P14 | N21: P14 | O21: P14 | P21: F | Q21: F | R21: P06 | S21: P06 | T21: P06 | U21: P06 | V21: F | W21: F | X21: P14 | Y21: P14 | Z21: P14 | AA21: P14 | AB21: F | AC21: F | AD21: P06 | AE21: P06 | AF21: P06 | AH21: =JAN!AN21 -> 0 | AI21: =COUNTIF(E21:AF21, "UA") -> 0 | AJ21: =AH21-AI21 -> 0 | AM21: =COUNTIF(E21:AF21, "U") -> 0 | AN21: =AL21-AM21 -> 0 | AP21: =COUNTIF(E21:AF21,"P*")+COUNTIF(E21:AF21,"H*")+COUNTIF(E21:AF21,"T*")-COUNTIF(E21:AF21,"H")-COUNTIF(E21:AF21,"P") -> 19
C22: Gonçalo Pereira | D22: PEREIRA, GONCALO | E22: P06 | F22: P06 | G22: P06 | H22: F | I22: F | J22: P22 | K22: P22 | L22: P22 | M22: P22 | N22: F | O22: F | P22: P14 | Q22: P14 | R22: P14 | S22: P14 | T22: F | U22: F | V22: P06 | W22: P06 | X22: P06 | Y22: P06 | Z22: F | AA22: F | AB22: P14 | AC22: P14 | AD22: P14 | AE22: P14 | AF22: F | AH22: =JAN!AN22 -> 1 | AI22: =COUNTIF(E22:AF22, "UA") -> 0 | AJ22: =AH22-AI22 -> 1 | AM22: =COUNTIF(E22:AF22, "U") -> 0 | AN22: =AL22-AM22 -> 0 | AP22: =COUNTIF(E22:AF22,"P*")+COUNTIF(E22:AF22,"H*")+COUNTIF(E22:AF22,"T*")-COUNTIF(E22:AF22,"H")-COUNTIF(E22:AF22,"P") -> 19
C23: Carlos Carvalhais | D23: CARVALHAIS, CARLOS | E23: P06 | F23: F | G23: F | H23: P06 | I23: P06 | J23: P06 | K23: P06 | L23: F | M23: F | N23: P22 | O23: P22 | P23: P22 | Q23: P22 | R23: F | S23: F | T23: P14 | U23: P14 | V23: P14 | W23: P14 | X23: F | Y23: F | Z23: P06 | AA23: P06 | AB23: P06 | AC23: P06 | AD23: F | AE23: F | AF23: P14 | AH23: =JAN!AN23 -> 3 | AI23: =COUNTIF(E23:AF23, "UA") -> 0 | AJ23: =AH23-AI23 -> 3 | AM23: =COUNTIF(E23:AF23, "U") -> 0 | AN23: =AL23-AM23 -> 0 | AP23: =COUNTIF(E23:AF23,"P*")+COUNTIF(E23:AF23,"H*")+COUNTIF(E23:AF23,"T*")-COUNTIF(E23:AF23,"H")-COUNTIF(E23:AF23,"P") -> 18
C24: Ines Pilre | D24: PILRE, INES | E24: F | F24: P06 | G24: P06 | H24: P06 | I24: P06 | J24: F | K24: F | L24: U | M24: U | N24: P06 | O24: P06 | P24: F | Q24: F | R24: P22 | S24: P22 | T24: P22 | U24: P22 | V24: F | W24: F | X24: P14 | Y24: P14 | Z24: P14 | AA24: P14 | AB24: F | AC24: F | AD24: P06 | AE24: P06 | AF24: P06 | AH24: =JAN!AN24 -> 0 | AI24: =COUNTIF(E24:AF24, "UA") -> 0 | AJ24: =AH24-AI24 -> 0 | AM24: =COUNTIF(E24:AF24, "U") -> 2 | AN24: =AL24-AM24 -> -2 | AP24: =COUNTIF(E24:AF24,"P*")+COUNTIF(E24:AF24,"H*")+COUNTIF(E24:AF24,"T*")-COUNTIF(E24:AF24,"H")-COUNTIF(E24:AF24,"P") -> 17
B25: Hubs Services Team | C25: Raquel Oliveira | D25: OLIVEIRA, RAQUEL ALEXANDRA | E25: P14 | F25: P14 | G25: P14 | H25: F | I25: F | J25: P06 | K25: P06 | L25: P06 | M25: P06 | N25: F | O25: F | P25: P06 | Q25: P06 | R25: P06 | S25: P06 | T25: F | U25: F | V25: P22 | W25: P22 | X25: P22 | Y25: P22 | Z25: F | AA25: F | AB25: UA | AC25: UA | AD25: UA | AE25: UA | AF25: F | AH25: =JAN!AN25 -> 4 | AI25: =COUNTIF(E25:AF25, "UA") -> 4 | AJ25: =AH25-AI25 -> 0 | AM25: =COUNTIF(E25:AF25, "U") -> 0 | AN25: =AL25-AM25 -> 0 | AP25: =COUNTIF(E25:AF25,"P*")+COUNTIF(E25:AF25,"H*")+COUNTIF(E25:AF25,"T*")-COUNTIF(E25:AF25,"H")-COUNTIF(E25:AF25,"P") -> 15
C26: Rafael Silva | D26: SILVA, RAFAEL | E26: P06 | F26: F | G26: F | H26: P14 | I26: P14 | J26: P14 | K26: P14 | L26: F | M26: F | N26: P06 | O26: P06 | P26: P06 | Q26: P06 | R26: F | S26: F | T26: P06 | U26: P06 | V26: P06 | W26: P06 | X26: F | Y26: F | Z26: P22 | AA26: P22 | AB26: P22 | AC26: P22 | AD26: F | AE26: F | AF26: P14 | AH26: =JAN!AN26 -> 0 | AI26: =COUNTIF(E26:AF26, "UA") -> 0 | AJ26: =AH26-AI26 -> 0 | AM26: =COUNTIF(E26:AF26, "U") -> 0 | AN26: =AL26-AM26 -> 0 | AP26: =COUNTIF(E26:AF26,"P*")+COUNTIF(E26:AF26,"H*")+COUNTIF(E26:AF26,"T*")-COUNTIF(E26:AF26,"H")-COUNTIF(E26:AF26,"P") -> 18
C27: Jose Borges | D27: BORGES, JOSE | E27: P14 | F27: P14 | G27: P14 | H27: F | I27: F | J27: P06 | K27: P06 | L27: P06 | M27: P06 | N27: F | O27: F | P27: P14 | Q27: P14 | R27: P14 | S27: P14 | T27: F | U27: F | V27: P06 | W27: P06 | X27: P06 | Y27: P06 | Z27: F | AA27: F | AB27: P06 | AC27: P06 | AD27: P06 | AE27: P06 | AF27: F | AH27: =JAN!AN27 -> 11 | AI27: =COUNTIF(E27:AF27, "UA") -> 0 | AJ27: =AH27-AI27 -> 11 | AM27: =COUNTIF(E27:AF27, "U") -> 0 | AN27: =AL27-AM27 -> 0 | AP27: =COUNTIF(E27:AF27,"P*")+COUNTIF(E27:AF27,"H*")+COUNTIF(E27:AF27,"T*")-COUNTIF(E27:AF27,"H")-COUNTIF(E27:AF27,"P") -> 19
C28: Josue Fula | D28: FULA, JOSUE | E28: P22 | F28: F | G28: F | H28: P14 | I28: P14 | J28: P14 | K28: P14 | L28: F | M28: F | N28: P06 | O28: P06 | P28: P06 | Q28: P06 | R28: F | S28: F | T28: P14 | U28: P14 | V28: P14 | W28: P14 | X28: F | Y28: F | Z28: P06 | AA28: P06 | AB28: P06 | AC28: P06 | AD28: F | AE28: F | AF28: P06 | AH28: =JAN!AN28 -> 0 | AI28: =COUNTIF(E28:AF28, "UA") -> 0 | AJ28: =AH28-AI28 -> 0 | AM28: =COUNTIF(E28:AF28, "U") -> 0 | AN28: =AL28-AM28 -> 0 | AP28: =COUNTIF(E28:AF28,"P*")+COUNTIF(E28:AF28,"H*")+COUNTIF(E28:AF28,"T*")-COUNTIF(E28:AF28,"H")-COUNTIF(E28:AF28,"P") -> 18
C29: Barbara Pereira | D29: PEREIRA, BARBARA | E29: F | F29: P22 | G29: P22 | H29: P22 | I29: P22 | J29: F | K29: F | L29: P14 | M29: P14 | N29: P14 | O29: P14 | P29: F | Q29: F | R29: P06 | S29: S3 | T29: UA | U29: P06 | V29: F | W29: F | X29: P14 | Y29: P14 | Z29: P14 | AA29: P14 | AB29: F | AC29: F | AD29: P06 | AE29: P06 | AF29: P06 | AH29: =JAN!AN29 -> 1 | AI29: =COUNTIF(E29:AF29, "UA") -> 1 | AJ29: =AH29-AI29 -> 0 | AM29: =COUNTIF(E29:AF29, "U") -> 0 | AN29: =AL29-AM29 -> 0 | AP29: =COUNTIF(E29:AF29,"P*")+COUNTIF(E29:AF29,"H*")+COUNTIF(E29:AF29,"T*")-COUNTIF(E29:AF29,"H")-COUNTIF(E29:AF29,"P") -> 17
C30: Dulani Monteiro | D30: MONTEIRO, DULANI | E30: P06 | F30: P06 | G30: P06 | H30: F | I30: F | J30: P22 | K30: P22 | L30: P22 | M30: P22 | N30: F | O30: F | P30: P14 | Q30: P14 | R30: P14 | S30: P14 | T30: F | U30: F | V30: P06 | W30: P06 | X30: P06 | Y30: P06 | Z30: F | AA30: F | AB30: P14 | AC30: P14 | AD30: P14 | AE30: P14 | AF30: F | AH30: =JAN!AN30 -> 0 | AI30: =COUNTIF(E30:AF30, "UA") -> 0 | AJ30: =AH30-AI30 -> 0 | AM30: =COUNTIF(E30:AF30, "U") -> 0 | AN30: =AL30-AM30 -> 0 | AP30: =COUNTIF(E30:AF30,"P*")+COUNTIF(E30:AF30,"H*")+COUNTIF(E30:AF30,"T*")-COUNTIF(E30:AF30,"H")-COUNTIF(E30:AF30,"P") -> 19
C31: Diogo Arantes | D31: ARANTES, DIOGO | E31: P06 | F31: F | G31: F | H31: P06 | I31: P06 | J31: P06 | K31: P06 | L31: F | M31: F | N31: P22 | O31: P22 | P31: P22 | Q31: P22 | R31: F | S31: F | T31: P14 | U31: P14 | V31: P14 | W31: P14 | X31: F | Y31: F | Z31: P06 | AA31: P06 | AB31: P06 | AC31: P06 | AD31: F | AE31: F | AF31: P14 | AH31: =JAN!AN31 -> 6 | AI31: =COUNTIF(E31:AF31, "UA") -> 0 | AJ31: =AH31-AI31 -> 6 | AM31: =COUNTIF(E31:AF31, "U") -> 0 | AN31: =AL31-AM31 -> 0 | AP31: =COUNTIF(E31:AF31,"P*")+COUNTIF(E31:AF31,"H*")+COUNTIF(E31:AF31,"T*")-COUNTIF(E31:AF31,"H")-COUNTIF(E31:AF31,"P") -> 18
C32: Jessica Martins | D32: MARTINS, JESSICA | E32: P14 | F32: P14 | G32: P14 | H32: P14 | I32: F | J32: F | K32: P14 | L32: P14 | M32: P14 | N32: UA | O32: F | P32: B | Q32: B* | R32: UA | S32: UA | T32: UA | U32: F | V32: F | W32: UA | X32: UA | Y32: UA | Z32: UA | AA32: F | AB32: F | AC32: P06 | AD32: P06 | AE32: P06 | AF32: P06 | AH32: =JAN!AN32 -> 8 | AI32: =COUNTIF(E32:AF32, "UA") -> 8 | AJ32: =AH32-AI32 -> 0 | AM32: =COUNTIF(E32:AF32, "U") -> 0 | AN32: =AL32-AM32 -> 0 | AP32: =COUNTIF(E32:AF32,"P*")+COUNTIF(E32:AF32,"H*")+COUNTIF(E32:AF32,"T*")-COUNTIF(E32:AF32,"H")-COUNTIF(E32:AF32,"P") -> 11
C33: Carla Ferreira | D33: FERREIRA, CARLA | E33: P14 | F33: P14 | G33: F | H33: F | I33: P06 | J33: P06 | K33: P06 | L33: P06 | M33: F | N33: F | O33: P14 | P33: P14 | Q33: P14 | R33: P14 | S33: F | T33: F | U33: P06 | V33: P06 | W33: P06 | X33: P06 | Y33: F | Z33: F | AA33: P14 | AB33: P14 | AC33: P14 | AD33: P14 | AE33: F | AF33: F | AH33: =JAN!AN33 -> 7 | AI33: =COUNTIF(E33:AF33, "UA") -> 0 | AJ33: =AH33-AI33 -> 7 | AM33: =COUNTIF(E33:AF33, "U") -> 0 | AN33: =AL33-AM33 -> 0 | AP33: =COUNTIF(E33:AF33,"P*")+COUNTIF(E33:AF33,"H*")+COUNTIF(E33:AF33,"T*")-COUNTIF(E33:AF33,"H")-COUNTIF(E33:AF33,"P") -> 18
C34: Rafael Medina | D34: MEDINA, RAFAEL | E34: F | F34: F | G34: P14 | H34: P14 | I34: P14 | J34: P14 | K34: F | L34: F | M34: P06 | N34: P06 | O34: P06 | P34: P06 | Q34: F | R34: F | S34: P14 | T34: P14 | U34: P14 | V34: P14 | W34: F | X34: F | Y34: P06 | Z34: P06 | AA34: P06 | AB34: P06 | AC34: F | AD34: F | AE34: P14 | AF34: P14 | AH34: =JAN!AN34 -> 0 | AI34: =COUNTIF(E34:AF34, "UA") -> 0 | AJ34: =AH34-AI34 -> 0 | AM34: =COUNTIF(E34:AF34, "U") -> 0 | AN34: =AL34-AM34 -> 0 | AP34: =COUNTIF(E34:AF34,"P*")+COUNTIF(E34:AF34,"H*")+COUNTIF(E34:AF34,"T*")-COUNTIF(E34:AF34,"H")-COUNTIF(E34:AF34,"P") -> 18
C35: Catia Neves | D35: NEVES, CATIA | E35: P06 | F35: P06 | G35: P06 | H35: P06 | I35: F | J35: F | K35: P14 | L35: P14 | M35: P14 | N35: P14 | O35: F | P35: F | Q35: P06 | R35: P06 | S35: P06 | T35: P06 | U35: F | V35: F | W35: P14 | X35: UA | Y35: P14 | Z35: P14 | AA35: F | AB35: F | AC35: P06 | AD35: P06 | AE35: P06 | AF35: P06 | AH35: =JAN!AN35 -> 5 | AI35: =COUNTIF(E35:AF35, "UA") -> 1 | AJ35: =AH35-AI35 -> 4 | AM35: =COUNTIF(E35:AF35, "U") -> 0 | AN35: =AL35-AM35 -> 0 | AP35: =COUNTIF(E35:AF35,"P*")+COUNTIF(E35:AF35,"H*")+COUNTIF(E35:AF35,"T*")-COUNTIF(E35:AF35,"H")-COUNTIF(E35:AF35,"P") -> 19
B36: LHX & Catering | C36: Ana Telma Carvalho | D36: CARVALHO, ANA | E36: P13 | F36: P13 | G36: P13 | H36: P13 | I36: F | J36: F | K36: H05 | L36: H05 | M36: H05 | N36: H05 | O36: F | P36: F | Q36: P13 | R36: P13 | S36: P13 | T36: P13 | U36: F | V36: F | W36: H05 | X36: H05 | Y36: H05 | Z36: H05 | AA36: F | AB36: F | AC36: P13 | AD36: P13 | AE36: P13 | AF36: P13 | AH36: =JAN!AN36 -> 0 | AI36: =COUNTIF(E36:AF36, "UA") -> 0 | AJ36: =AH36-AI36 -> 0 | AM36: =COUNTIF(E36:AF36, "U") -> 0 | AN36: =AL36-AM36 -> 0 | AP36: =COUNTIF(E36:AF36,"P*")+COUNTIF(E36:AF36,"H*")+COUNTIF(E36:AF36,"T*")-COUNTIF(E36:AF36,"H")-COUNTIF(E36:AF36,"P") -> 20
C37: Catia Craveiro | D37: CRAVEIRO, CATIA | E37: F | F37: F | G37: H05 | H37: H05 | I37: H05 | J37: H05 | K37: F | L37: F | M37: P13 | N37: P13 | O37: P13 | P37: P13 | Q37: F | R37: F | S37: H05 | T37: H05 | U37: H05 | V37: H05 | W37: F | X37: F | Y37: P13 | Z37: P13 | AA37: P13 | AB37: P13 | AC37: F | AD37: F | AE37: H05 | AF37: H05 | AH37: =JAN!AN37 -> 0 | AI37: =COUNTIF(E37:AF37, "UA") -> 0 | AJ37: =AH37-AI37 -> 0 | AM37: =COUNTIF(E37:AF37, "U") -> 0 | AN37: =AL37-AM37 -> 0 | AP37: =COUNTIF(E37:AF37,"P*")+COUNTIF(E37:AF37,"H*")+COUNTIF(E37:AF37,"T*")-COUNTIF(E37:AF37,"H")-COUNTIF(E37:AF37,"P") -> 18
C38: Maria Vitoria Almeida | D38: ALMEIDA, MARIA VITORIA | E38: H05 | F38: H05 | G38: F | H38: F | I38: P13 | J38: P13 | K38: P13 | L38: P13 | M38: F | N38: F | O38: H05 | P38: H05 | Q38: H05 | R38: H05 | S38: F | T38: F | U38: P13 | V38: P13 | W38: P13 | X38: P13 | Y38: F | Z38: F | AA38: H05 | AB38: H05 | AC38: H05 | AD38: H05 | AE38: F | AF38: F | AH38: =JAN!AN38 -> 0 | AI38: =COUNTIF(E38:AF38, "UA") -> 0 | AJ38: =AH38-AI38 -> 0 | AM38: =COUNTIF(E38:AF38, "U") -> 0 | AN38: =AL38-AM38 -> 0 | AP38: =COUNTIF(E38:AF38,"P*")+COUNTIF(E38:AF38,"H*")+COUNTIF(E38:AF38,"T*")-COUNTIF(E38:AF38,"H")-COUNTIF(E38:AF38,"P") -> 18
C39: Jessica Santos | D39: SANTOS, JESSICA | E39: M | F39: M | G39: M | H39: M | I39: M | J39: M | K39: M | L39: M | M39: M | N39: M | O39: M | P39: M | Q39: M | R39: M | S39: M | T39: M | U39: M | V39: M | W39: M | X39: M | Y39: M | Z39: M | AA39: M | AB39: M | AC39: M | AD39: M | AE39: M | AF39: M | AH39: =JAN!AN39 -> 19 | AI39: =COUNTIF(E39:AF39, "UA") -> 0 | AJ39: =AH39-AI39 -> 19 | AM39: =COUNTIF(E39:AF39, "U") -> 0 | AN39: =AL39-AM39 -> 0 | AP39: =COUNTIF(E39:AF39,"P*")+COUNTIF(E39:AF39,"H*")+COUNTIF(E39:AF39,"T*")-COUNTIF(E39:AF39,"H")-COUNTIF(E39:AF39,"P") -> 0
B40: INAD HUB/CG/DEPO | C40: Cristiana Ferreira | D40: FERREIRA, CRISTIANA MARGARIDA | E40: M | F40: M | G40: M | H40: M | I40: M | J40: M | K40: M | L40: M | M40: M | N40: M | O40: M | P40: M | Q40: M | R40: M | S40: M | T40: M | U40: M | V40: M | W40: M | X40: M | Y40: M | Z40: M | AA40: M | AB40: M | AC40: M | AD40: M | AE40: M | AF40: M | AH40: =JAN!AN40 -> 14 | AI40: =COUNTIF(E40:AF40, "UA") -> 0 | AJ40: =AH40-AI40 -> 14 | AM40: =COUNTIF(E40:AF40, "U") -> 0 | AN40: =AL40-AM40 -> 0 | AP40: =COUNTIF(E40:AF40,"P*")+COUNTIF(E40:AF40,"H*")+COUNTIF(E40:AF40,"T*")-COUNTIF(E40:AF40,"H")-COUNTIF(E40:AF40,"P") -> 0
C41: Mauro Silva | D41: SILVA, MAURO | E41: F | F41: P08/ | G41: P08/ | H41: P08/ | I41: P08/ | J41: P08/ | K41: F | L41: F | M41: P08/ | N41: P08/ | O41: P08/ | P41: P08/ | Q41: P08/ | R41: F | S41: F | T41: P08/ | U41: P08/ | V41: P08/ | W41: P08/ | X41: P08/ | Y41: F | Z41: F | AA41: P08/ | AB41: P08/ | AC41: P08/ | AD41: P08/ | AE41: P08/ | AF41: F | AH41: =JAN!AN41 -> 0 | AI41: =COUNTIF(E41:AF41, "UA") -> 0 | AJ41: =AH41-AI41 -> 0 | AM41: =COUNTIF(E41:AF41, "U") -> 0 | AN41: =AL41-AM41 -> 0 | AP41: =COUNTIF(E41:AF41,"P*")+COUNTIF(E41:AF41,"H*")+COUNTIF(E41:AF41,"T*")-COUNTIF(E41:AF41,"H")-COUNTIF(E41:AF41,"P") -> 20
...

Sheet MAR
B2: Not Finalized | C2: HUB Services | E2: LGSP - Lufthansa Ground Services Portugal NIF : 509 842 593 Atividade: CAE 52230.R3 Sede e local de trabalho: Avenida da Boavista ED.Burgo, 1837 sala 13.1 Horario de Funcionamento: 24/7 IRT: Não Aplicável | AK2: Ferias 2025 | AO2: Ferias 2026 | AS2: Dias Trabalhados
C3: Marco | E3: Dom | F3: Seg | G3: Ter | H3: Qua | I3: Qui | J3: Sex | K3: Sab | L3: Dom | M3: Seg | N3: Ter | O3: Qua | P3: Qui | Q3: Sex | R3: Sab | S3: Dom | T3: Seg | U3: Ter | V3: Qua | W3: Qui | X3: Sex | Y3: Sab | Z3: Dom | AA3: Seg | AB3: Ter | AC3: Qua | AD3: Qui | AE3: Sex | AF3: Sab | AG3: Dom | AH3: Seg | AI3: Ter
E4: 1 | F4: 2 | G4: 3 | H4: 4 | I4: 5 | J4: 6 | K4: 7 | L4: 8 | M4: 9 | N4: 10 | O4: 11 | P4: 12 | Q4: 13 | R4: 14 | S4: 15 | T4: 16 | U4: 17 | V4: 18 | W4: 19 | X4: 20 | Y4: 21 | Z4: 22 | AA4: 23 | AB4: 24 | AC4: 25 | AD4: 26 | AE4: 27 | AF4: 28 | AG4: 29 | AH4: 30 | AI4: 31 | AK4: 2025 | AL4: Used | AM4: Left | AO4: 2026 | AP4: Used | AQ4: Left
B5: Hub Services Supervision | C5: Catarina Ferreira | D5: FERREIRA, CATARINA | E5: P06 | F5: P06 | G5: F | H5: F | I5: P14 | J5: P14 | K5: P14 | L5: P14 | M5: F | N5: F | O5: P06 | P5: P06 | Q5: P06 | R5: P06 | S5: F | T5: F | U5: P14 | V5: P14 | W5: P14 | X5: P14 | Y5: F | Z5: F | AA5: P06 | AB5: P06 | AC5: P06 | AD5: P06 | AE5: F | AF5: F | AG5: P14 | AH5: P14 | AI5: P14 | AK5: =FEB!AJ5 -> 1 | AL5: =COUNTIF(E5:AI5, "UA") -> 0 | AM5: =AK5-AL5 -> 1 | AP5: =COUNTIF(E5:AI5, "U") -> 0 | AQ5: =AO5-AP5 -> 0 | AS5: =COUNTIF(E5:AI5,"P*")+COUNTIF(E5:AI5,"H*")+COUNTIF(E5:AI5,"T*")-COUNTIF(E5:AI5,"H")-COUNTIF(E5:AI5,"P") -> 21
C6: Miguel Pinto | D6: PINTO, MIGUEL | E6: P14 | F6: P14 | G6: P14 | H6: P14 | I6: F | J6: F | K6: P06 | L6: P06 | M6: P06 | N6: P06 | O6: F | P6: F | Q6: P14 | R6: P14 | S6: P14 | T6: P14 | U6: F | V6: F | W6: P06 | X6: P06 | Y6: P06 | Z6: P06 | AA6: F | AB6: F | AC6: P14 | AD6: P14 | AE6: P14 | AF6: P14 | AG6: F | AH6: F | AI6: P06 | AK6: =FEB!AJ6 -> 0 | AL6: =COUNTIF(E6:AI6, "UA") -> 0 | AM6: =AK6-AL6 -> 0 | AP6: =COUNTIF(E6:AI6, "U") -> 0 | AQ6: =AO6-AP6 -> 0 | AS6: =COUNTIF(E6:AI6,"P*")+COUNTIF(E6:AI6,"H*")+COUNTIF(E6:AI6,"T*")-COUNTIF(E6:AI6,"H")-COUNTIF(E6:AI6,"P") -> 21
C7: João Santos Silva | D7: SANTOS SILVA, JOAO | E7: P22 | F7: F | G7: F | H7: P14 | I7: P14 | J7: P14 | K7: P14 | L7: P14 | M7: F | N7: P06 | O7: P06 | P7: P06 | Q7: F | R7: F | S7: F | T7: UA | U7: P14 | V7: P14 | W7: P14 | X7: F | Y7: F | Z7: P06 | AA7: P06 | AB7: P06 | AC7: P06 | AD7: F | AE7: F | AF7: P14 | AG7: P14 | AH7: P14 | AI7: P14 | AK7: =FEB!AJ7 -> 1 | AL7: =COUNTIF(E7:AI7, "UA") -> 1 | AM7: =AK7-AL7 -> 0 | AP7: =COUNTIF(E7:AI7, "U") -> 0 | AQ7: =AO7-AP7 -> 0 | AS7: =COUNTIF(E7:AI7,"P*")+COUNTIF(E7:AI7,"H*")+COUNTIF(E7:AI7,"T*")-COUNTIF(E7:AI7,"H")-COUNTIF(E7:AI7,"P") -> 20
C8: Ana Magalhães | D8: MAGALHAES, ANA CATARINA | E8: P06 | F8: P06 | G8: P06 | H8: F | I8: F | J8: P14 | K8: P14 | L8: P14 | M8: P14 | N8: F | O8: F | P8: P06 | Q8: P06 | R8: P06 | S8: P06 | T8: F | U8: F | V8: P14 | W8: P14 | X8: P14 | Y8: P14 | Z8: F | AA8: F | AB8: P06 | AC8: P06 | AD8: P06 | AE8: P06 | AF8: F | AG8: F | AH8: P14 | AI8: P14 | AK8: =FEB!AJ8 -> 2 | AL8: =COUNTIF(E8:AI8, "UA") -> 0 | AM8: =AK8-AL8 -> 2 | AP8: =COUNTIF(E8:AI8, "U") -> 0 | AQ8: =AO8-AP8 -> 0 | AS8: =COUNTIF(E8:AI8,"P*")+COUNTIF(E8:AI8,"H*")+COUNTIF(E8:AI8,"T*")-COUNTIF(E8:AI8,"H")-COUNTIF(E8:AI8,"P") -> 21
C9: Jorge Gonçalves | D9: GONCALVES, JORGE | E9: F | F9: P14 | G9: P14 | H9: P14 | I9: P14 | J9: F | K9: F | L9: P06 | M9: P06 | N9: P06 | O9: P06 | P9: F | Q9: F | R9: P14 | S9: P14 | T9: P14 | U9: P14 | V9: F | W9: F | X9: P06 | Y9: P06 | Z9: P06 | AA9: P06 | AB9: F | AC9: F | AD9: P14 | AE9: P14 | AF9: P14 | AG9: P14 | AH9: F | AI9: F | AK9: =FEB!AJ9 -> 0 | AL9: =COUNTIF(E9:AI9, "UA") -> 0 | AM9: =AK9-AL9 -> 0 | AP9: =COUNTIF(E9:AI9, "U") -> 0 | AQ9: =AO9-AP9 -> 0 | AS9: =COUNTIF(E9:AI9,"P*")+COUNTIF(E9:AI9,"H*")+COUNTIF(E9:AI9,"T*")-COUNTIF(E9:AI9,"H")-COUNTIF(E9:AI9,"P") -> 20
C10: Sara Medeiros | D10: MEDEIROS, SARA | E10: P14 | F10: P14 | G10: P14 | H10: F | I10: F | J10: P06 | K10: P06 | L10: P06 | M10: P06 | N10: F | O10: F | P10: P14 | Q10: P14 | R10: P14 | S10: P14 | T10: F | U10: F | V10: P06 | W10: P06 | X10: P06 | Y10: P06 | Z10: F | AA10: F | AB10: P14 | AC10: P14 | AD10: P14 | AE10: P14 | AF10: F | AG10: F | AH10: P06 | AI10: P06 | AK10: =FEB!AJ10 -> 0 | AL10: =COUNTIF(E10:AI10, "UA") -> 0 | AM10: =AK10-AL10 -> 0 | AP10: =COUNTIF(E10:AI10, "U") -> 0 | AQ10: =AO10-AP10 -> 0 | AS10: =COUNTIF(E10:AI10,"P*")+COUNTIF(E10:AI10,"H*")+COUNTIF(E10:AI10,"T*")-COUNTIF(E10:AI10,"H")-COUNTIF(E10:AI10,"P") -> 21
C11: Catarina Pereira | D11: PEREIRA, CATARINA | E11: F | F11: P06 | G11: P06 | H11: P06 | I11: P06 | J11: F | K11: F | L11: F | M11: P14 | N11: P14 | O11: P14 | P11: F | Q11: P06 | R11: P06 | S11: P06 | T11: P06 | U11: P06 | V11: F | W11: F | X11: P14 | Y11: P14 | Z11: P14 | AA11: P14 | AB11: F | AC11: F | AD11: P06 | AE11: P06 | AF11: P06 | AG11: P06 | AH11: F | AI11: F | AK11: =FEB!AJ11 -> 0 | AL11: =COUNTIF(E11:AI11, "UA") -> 0 | AM11: =AK11-AL11 -> 0 | AP11: =COUNTIF(E11:AI11, "U") -> 0 | AQ11: =AO11-AP11 -> 0 | AS11: =COUNTIF(E11:AI11,"P*")+COUNTIF(E11:AI11,"H*")+COUNTIF(E11:AI11,"T*")-COUNTIF(E11:AI11,"H")-COUNTIF(E11:AI11,"P") -> 20
C12: Catia Martins | D12: MARTINS, CATIA | E12: P14 | F12: F | G12: F | H12: P06 | I12: P06 | J12: P06 | K12: P06 | L12: F | M12: F | N12: P14 | O12: P14 | P12: P14 | Q12: P14 | R12: F | S12: F | T12: P06 | U12: P06 | V12: P06 | W12: P06 | X12: F | Y12: F | Z12: P14 | AA12: P14 | AB12: P14 | AC12: P14 | AD12: F | AE12: F | AF12: P06 | AG12: P06 | AH12: P06 | AI12: P06 | AK12: =FEB!AJ12 -> 0 | AL12: =COUNTIF(E12:AI12, "UA") -> 0 | AM12: =AK12-AL12 -> 0 | AP12: =COUNTIF(E12:AI12, "U") -> 0 | AQ12: =AO12-AP12 -> 0 | AS12: =COUNTIF(E12:AI12,"P*")+COUNTIF(E12:AI12,"H*")+COUNTIF(E12:AI12,"T*")-COUNTIF(E12:AI12,"H")-COUNTIF(E12:AI12,"P") -> 21
B13: Remote Passenger Recovery Team | C13: Ricardo Bessa | D13: BESSA, RICARDO | E13: F | F13: P06 | G13: P06 | H13: P06 | I13: P06 | J13: F | K13: F | L13: P14 | M13: P14 | N13: P14 | O13: P14 | P13: F | Q13: F | R13: P06 | S13: P06 | T13: P06 | U13: P06 | V13: F | W13: F | X13: P06 | Y13: P06 | Z13: P06 | AA13: P06 | AB13: F | AC13: F | AD13: P06 | AE13: P06 | AF13: P06 | AG13: P06 | AH13: F | AI13: F | AK13: =FEB!AJ13 -> 0 | AL13: =COUNTIF(E13:AI13, "UA") -> 0 | AM13: =AK13-AL13 -> 0 | AP13: =COUNTIF(E13:AI13, "U") -> 0 | AQ13: =AO13-AP13 -> 0 | AS13: =COUNTIF(E13:AI13,"P*")+COUNTIF(E13:AI13,"H*")+COUNTIF(E13:AI13,"T*")-COUNTIF(E13:AI13,"H")-COUNTIF(E13:AI13,"P") -> 20
C14: Samuel Neves | D14: NEVES, SAMUEL | E14: P14 | F14: P14 | G14: P14 | H14: F | I14: F | J14: P06 | K14: P06 | L14: P06 | M14: P06 | N14: F | O14: F | P14: P14 | Q14: P14 | R14: P14 | S14: P14 | T14: F | U14: F | V14: P06 | W14: P06 | X14: P06 | Y14: P06 | Z14: F | AA14: F | AB14: P06 | AC14: P06 | AD14: P06 | AE14: P06 | AF14: F | AG14: F | AH14: UA | AI14: UA | AK14: =FEB!AJ14 -> 11 | AL14: =COUNTIF(E14:AI14, "UA") -> 2 | AM14: =AK14-AL14 -> 9 | AP14: =COUNTIF(E14:AI14, "U") -> 0 | AQ14: =AO14-AP14 -> 0 | AS14: =COUNTIF(E14:AI14,"P*")+COUNTIF(E14:AI14,"H*")+COUNTIF(E14:AI14,"T*")-COUNTIF(E14:AI14,"H")-COUNTIF(E14:AI14,"P") -> 19
C15: Ricardo Medeiros | D15: MEDEIROS, RICARDO | E15: P22 | F15: F | G15: F | H15: P14 | I15: P14 | J15: P14 | K15: P14 | L15: F | M15: F | N15: P06 | O15: P06 | P15: P06 | Q15: P06 | R15: F | S15: F | T15: P14 | U15: P14 | V15: P14 | W15: P14 | X15: F | Y15: F | Z15: P06 | AA15: P06 | AB15: P06 | AC15: P06 | AD15: F | AE15: F | AF15: P06 | AG15: P06 | AH15: P06 | AI15: P06 | AK15: =FEB!AJ15 -> 0 | AL15: =COUNTIF(E15:AI15, "UA") -> 0 | AM15: =AK15-AL15 -> 0 | AP15: =COUNTIF(E15:AI15, "U") -> 0 | AQ15: =AO15-AP15 -> 0 | AS15: =COUNTIF(E15:AI15,"P*")+COUNTIF(E15:AI15,"H*")+COUNTIF(E15:AI15,"T*")-COUNTIF(E15:AI15,"H")-COUNTIF(E15:AI15,"P") -> 21
C16: Joana Pinheiro | D16: PINHEIRO, JOANA | E16: F | F16: P22 | G16: P22 | H16: P22 | I16: P22 | J16: F | K16: F | L16: P14 | M16: P14 | N16: P14 | O16: P14 | P16: F | Q16: F | R16: P06 | S16: P06 | T16: P06 | U16: P06 | V16: F | W16: F | X16: P14 | Y16: P14 | Z16: P14 | AA16: P14 | AB16: F | AC16: F | AD16: P06 | AE16: P06 | AF16: P06 | AG16: P06 | AH16: F | AI16: F | AK16: =FEB!AJ16 -> 0 | AL16: =COUNTIF(E16:AI16, "UA") -> 0 | AM16: =AK16-AL16 -> 0 | AP16: =COUNTIF(E16:AI16, "U") -> 0 | AQ16: =AO16-AP16 -> 0 | AS16: =COUNTIF(E16:AI16,"P*")+COUNTIF(E16:AI16,"H*")+COUNTIF(E16:AI16,"T*")-COUNTIF(E16:AI16,"H")-COUNTIF(E16:AI16,"P") -> 20
C17: Bruna Lima | D17: LIMA, BRUNA | E17: P06 | F17: P06 | G17: P06 | H17: F | I17: F | J17: P22 | K17: P22 | L17: P22 | M17: P22 | N17: F | O17: F | P17: P14 | Q17: P14 | R17: P14 | S17: P14 | T17: F | U17: F | V17: P06 | W17: P06 | X17: P06 | Y17: P06 | Z17: F | AA17: F | AB17: P14 | AC17: P14 | AD17: P14 | AE17: P14 | AF17: F | AG17: F | AH17: P06 | AI17: P06 | AK17: =FEB!AJ17 -> 0 | AL17: =COUNTIF(E17:AI17, "UA") -> 0 | AM17: =AK17-AL17 -> 0 | AP17: =COUNTIF(E17:AI17, "U") -> 0 | AQ17: =AO17-AP17 -> 0 | AS17: =COUNTIF(E17:AI17,"P*")+COUNTIF(E17:AI17,"H*")+COUNTIF(E17:AI17,"T*")-COUNTIF(E17:AI17,"H")-COUNTIF(E17:AI17,"P") -> 21
C18: Ivo Latourrette | D18: LATOURRETTE, IVO | E18: P06 | F18: F | G18: F | H18: P06 | I18: P06 | J18: P06 | K18: P06 | L18: F | M18: F | N18: P22 | O18: P22 | P18: P22 | Q18: P22 | R18: F | S18: F | T18: P14 | U18: P14 | V18: P14 | W18: P14 | X18: F | Y18: F | Z18: UA | AA18: UA | AB18: UA | AC18: UA | AD18: F | AE18: B | AF18: B* | AG18: UA | AH18: UA | AI18: UA | AK18: =FEB!AJ18 -> 13 | AL18: =COUNTIF(E18:AI18, "UA") -> 7 | AM18: =AK18-AL18 -> 6 | AP18: =COUNTIF(E18:AI18, "U") -> 0 | AQ18: =AO18-AP18 -> 0 | AS18: =COUNTIF(E18:AI18,"P*")+COUNTIF(E18:AI18,"H*")+COUNTIF(E18:AI18,"T*")-COUNTIF(E18:AI18,"H")-COUNTIF(E18:AI18,"P") -> 13
C19: Inês Coelho | D19: COELHO, INES | E19: F | F19: P06 | G19: P06 | H19: P06 | I19: P06 | J19: F | K19: F | L19: P14 | M19: P14 | N19: P14 | O19: P14 | P19: F | Q19: F | R19: P22 | S19: P22 | T19: P22 | U19: P22 | V19: F | W19: F | X19: P14 | Y19: P14 | Z19: P14 | AA19: P14 | AB19: F | AC19: F | AD19: P06 | AE19: P06 | AF19: P06 | AG19: P06 | AH19: F | AI19: F | AK19: =FEB!AJ19 -> 0 | AL19: =COUNTIF(E19:AI19, "UA") -> 0 | AM19: =AK19-AL19 -> 0 | AP19: =COUNTIF(E19:AI19, "U") -> 0 | AQ19: =AO19-AP19 -> 0 | AS19: =COUNTIF(E19:AI19,"P*")+COUNTIF(E19:AI19,"H*")+COUNTIF(E19:AI19,"T*")-COUNTIF(E19:AI19,"H")-COUNTIF(E19:AI19,"P") -> 20
C20: Jose Alves | D20: ALVES, JOSE | E20: P14 | F20: P14 | G20: P14 | H20: F | I20: F | J20: P06 | K20: P06 | L20: P06 | M20: P06 | N20: F | O20: F | P20: P14 | Q20: P14 | R20: P14 | S20: P14 | T20: F | U20: F | V20: P22 | W20: P22 | X20: P22 | Y20: P22 | Z20: F | AA20: F | AB20: P14 | AC20: P14 | AD20: P14 | AE20: P14 | AF20: F | AG20: F | AH20: P06 | AI20: P06 | AK20: =FEB!AJ20 -> 0 | AL20: =COUNTIF(E20:AI20, "UA") -> 0 | AM20: =AK20-AL20 -> 0 | AP20: =COUNTIF(E20:AI20, "U") -> 0 | AQ20: =AO20-AP20 -> 0 | AS20: =COUNTIF(E20:AI20,"P*")+COUNTIF(E20:AI20,"H*")+COUNTIF(E20:AI20,"T*")-COUNTIF(E20:AI20,"H")-COUNTIF(E20:AI20,"P") -> 21
C21: Alefe Sobral | D21: SOBRAL, ALEFE | E21: P06 | F21: F | G21: F | H21: P14 | I21: P14 | J21: P14 | K21: P14 | L21: F | M21: F | N21: P06 | O21: P06 | P21: P06 | Q21: P06 | R21: F | S21: F | T21: P14 | U21: P14 | V21: P14 | W21: P14 | X21: F | Y21: F | Z21: P22 | AA21: P22 | AB21: P22 | AC21: P22 | AD21: F | AE21: F | AF21: P14 | AG21: P14 | AH21: P14 | AI21: P14 | AK21: =FEB!AJ21 -> 0 | AL21: =COUNTIF(E21:AI21, "UA") -> 0 | AM21: =AK21-AL21 -> 0 | AP21: =COUNTIF(E21:AI21, "U") -> 0 | AQ21: =AO21-AP21 -> 0 | AS21: =COUNTIF(E21:AI21,"P*")+COUNTIF(E21:AI21,"H*")+COUNTIF(E21:AI21,"T*")-COUNTIF(E21:AI21,"H")-COUNTIF(E21:AI21,"P") -> 21
C22: Gonçalo Pereira | D22: PEREIRA, GONCALO | E22: F | F22: P06 | G22: P06 | H22: P06 | I22: P06 | J22: F | K22: F | L22: P14 | M22: P14 | N22: P14 | O22: P14 | P22: F | Q22: F | R22: P06 | S22: P06 | T22: P06 | U22: P06 | V22: F | W22: F | X22: UA | Y22: P14 | Z22: P14 | AA22: P14 | AB22: F | AC22: F | AD22: P22 | AE22: P22 | AF22: P22 | AG22: P22 | AH22: F | AI22: F | AK22: =FEB!AJ22 -> 1 | AL22: =COUNTIF(E22:AI22, "UA") -> 1 | AM22: =AK22-AL22 -> 0 | AP22: =COUNTIF(E22:AI22, "U") -> 0 | AQ22: =AO22-AP22 -> 0 | AS22: =COUNTIF(E22:AI22,"P*")+COUNTIF(E22:AI22,"H*")+COUNTIF(E22:AI22,"T*")-COUNTIF(E22:AI22,"H")-COUNTIF(E22:AI22,"P") -> 19
