Workbook

Sheet JAN
A1: LGSP - Lufthansa Ground Services Portugal NIF : 509 842 593 Atividade: CAE 52230.R3 Sede e local de trabalho: Avenida da Boavista ED.Burgo, 1837 sala 13.4/ Horario de Funcionamento: 24/7 IRT : Nao Aplicavel
A2: 46023 | B2: =IF(COLUMN(A1)<=DAY(EOMONTH($A$2,0)),COLUMN(A1),"") -> 1 | C2: =IF(COLUMN(B1)<=DAY(EOMONTH($A$2,0)),COLUMN(B1),"") -> 2 | D2: =IF(COLUMN(C1)<=DAY(EOMONTH($A$2,0)),COLUMN(C1),"") -> 3 | E2: =IF(COLUMN(D1)<=DAY(EOMONTH($A$2,0)),COLUMN(D1),"") -> 4 | F2: =IF(COLUMN(E1)<=DAY(EOMONTH($A$2,0)),COLUMN(E1),"") -> 5 | G2: =IF(COLUMN(F1)<=DAY(EOMONTH($A$2,0)),COLUMN(F1),"") -> 6 | H2: =IF(COLUMN(G1)<=DAY(EOMONTH($A$2,0)),COLUMN(G1),"") -> 7 | I2: =IF(COLUMN(H1)<=DAY(EOMONTH($A$2,0)),COLUMN(H1),"") -> 8 | ... AF2: =IF(COLUMN(AE1)<=DAY(EOMONTH($A$2,0)),COLUMN(AE1),"") -> 31 | AH2: Ferias 2025 | AL2: Ferias 2026
B3: =UPPER(LEFT(TEXT(DATE(YEAR($A$2),MONTH($A$2),B2),"DDD"),2)) -> TH | C3: =UPPER(LEFT(TEXT(DATE(YEAR($A$2),MONTH($A$2),C2),"DDD"),2)) -> FR | D3: =UPPER(LEFT(TEXT(DATE(YEAR($A$2),MONTH($A$2),D2),"DDD"),2)) -> SA | E3: =UPPER(LEFT(TEXT(DATE(YEAR($A$2),MONTH($A$2),E2),"DDD"),2)) -> SU | F3: =UPPER(LEFT(TEXT(DATE(YEAR($A$2),MONTH($A$2),F2),"DDD"),2)) -> MO | G3: =UPPER(LEFT(TEXT(DATE(YEAR($A$2),MONTH($A$2),G2),"DDD"),2)) -> TU | H3: =UPPER(LEFT(TEXT(DATE(YEAR($A$2),MONTH($A$2),H2),"DDD"),2)) -> WE | I3: =UPPER(LEFT(TEXT(DATE(YEAR($A$2),MONTH($A$2),I2),"DDD"),2)) -> TH | ... AF3: =UPPER(LEFT(TEXT(DATE(YEAR($A$2),MONTH($A$2),AF2),"DDD"),2)) -> SA | AH3: 2025 | AI3: Used | AJ3: Left | AL3: 2026 | AM3: Used | AN3: Left
A4: LUISA TAVARES | B4: H | C4: UA | D4: F | E4: F | F4: P09 | G4: P09 | H4: P09 | I4: P09 | J4: P09 | K4: F | L4: F | M4: P08 | N4: P09 | O4: P06 | P4: P09 | Q4: P09 | R4: F | S4: F | T4: P09 | U4: P09 | V4: P09 | W4: P09 | X4: P09 | Y4: F | Z4: F | AA4: P09 | AB4: P09 | AC4: P09 | AD4: P09 | AE4: P09 | AF4: F | AH4: 4 | AI4: =COUNTIF(B4:AF4,"UA") -> 1 | AJ4: =AH4-AI4 -> 3 | AL4: 22 | AM4: =COUNTIF(B4:AF4,"U") -> 0 | AN4: =AL4-AM4 -> 22
A5: FABIO FILIPE PEREIRA | B5: H | C5: P09 | D5: F | E5: F | F5: P09 | G5: P09 | H5: P09 | I5: P09 | J5: P09 | K5: F | L5: F | M5: P09 | N5: P09 | O5: P09 | P5: P09 | Q5: P09 | R5: F | S5: F | T5: P09 | U5: P09 | V5: P09 | W5: P09 | X5: P09 | Y5: F | Z5: F | AA5: P09 | AB5: P09 | AC5: P09 | AD5: P09 | AE5: P06 | AF5: F | AH5: 0 | AI5: =COUNTIF(B5:AF5,"UA") -> 0 | AJ5: =AH5-AI5 -> 0 | AL5: 22 | AM5: =COUNTIF(B5:AF5,"U") -> 0 | AN5: =AL5-AM5 -> 22
A6: ARNOLD LUANZAMBI | B6: H | C6: P09 | D6: F | E6: F | F6: P09 | G6: P09 | H6: P09 | I6: P09 | J6: P09 | K6: F | L6: F | M6: P09 | N6: P09 | O6: P09 | P6: P09 | Q6: P09 | R6: F | S6: F | T6: P09 | U6: P09 | V6: P09 | W6: P09 | X6: P09 | Y6: F | Z6: F | AA6: P09 | AB6: P09 | AC6: P09 | AD6: P09 | AE6: P09 | AF6: F | AH6: 8 | AI6: =COUNTIF(B6:AF6,"UA") -> 0 | AJ6: =AH6-AI6 -> 8 | AL6: 22 | AM6: =COUNTIF(B6:AF6,"U") -> 0 | AN6: =AL6-AM6 -> 22
A7: BEATRIZ SEIXAS | B7: F | C7: P06 | D7: P06 | E7: P06 | F7: P06 | G7: P06 | H7: F | I7: F | J7: P14 | K7: P14 | L7: P14 | M7: P14 | N7: F | O7: P06 | P7: P06 | Q7: P06 | R7: F | S7: F | T7: F | U7: P14 | V7: P14 | W7: P14 | X7: P14 | Y7: P14 | Z7: P14 | AA7: F | AB7: F | AC7: U | AD7: U | AE7: U | AF7: U | AH7: 0 | AI7: =COUNTIF(B7:AF7,"UA") -> 0 | AJ7: =AH7-AI7 -> 0 | AL7: 22 | AM7: =COUNTIF(B7:AF7,"U") -> 4 | AN7: =AL7-AM7 -> 18
A8: PAULO COSTA | B8: F | C8: F | D8: P14 | E8: P14 | F8: P14 | G8: P14 | H8: P14 | I8: F | J8: F | K8: P06 | L8: P06 | M8: P06 | N8: P06 | O8: F | P8: F | Q8: P14 | R8: P14 | S8: P14 | T8: P14 | U8: F | V8: F | W8: P06 | X8: P06 | Y8: P06 | Z8: P06 | AA8: P06 | AB8: F | AC8: F | AD8: UA | AE8: B | AF8: UA | AH8: 18 | AI8: =COUNTIF(B8:AF8,"UA") -> 2 | AJ8: =AH8-AI8 -> 16 | AL8: 22 | AM8: =COUNTIF(B8:AF8,"U") -> 0 | AN8: =AL8-AM8 -> 22
A9: PEDRO SOARES | B9: H | C9: F | D9: F | E9: UA | F9: UA | G9: UA | H9: UA | I9: UA | J9: F | K9: F | L9: P14 | M9: P14 | N9: P14 | O9: P14 | P9: F | Q9: F | R9: P06 | S9: P06 | T9: P06 | U9: P06 | V9: F | W9: F | X9: P14 | Y9: P14 | Z9: P14 | AA9: P14 | AB9: P14 | AC9: F | AD9: F | AE9: P14 | AF9: P14 | AH9: 5 | AI9: =COUNTIF(B9:AF9,"UA") -> 5 | AJ9: =AH9-AI9 -> 0 | AL9: 22 | AM9: =COUNTIF(B9:AF9,"U") -> 0 | AN9: =AL9-AM9 -> 22
A10: JOSE ALEXANDRE FERREIRA | B10: P14 | C10: P14 | D10: P14 | E10: F | F10: F | G10: P06 | H10: P06 | I10: P06 | J10: P06 | K10: P06 | L10: F | M10: F | N10: P14 | O10: P14 | P10: P14 | Q10: P14 | R10: F | S10: F | T10: P06 | U10: P06 | V10: P06 | W10: P06 | X10: P06 | Y10: F | Z10: F | AA10: F | AB10: P14 | AC10: P14 | AD10: P14 | AE10: F | AF10: P06 | AH10: 0 | AI10: =COUNTIF(B10:AF10,"UA") -> 0 | AJ10: =AH10-AI10 -> 0 | AL10: 22 | AM10: =COUNTIF(B10:AF10,"U") -> 0 | AN10: =AL10-AM10 -> 22
A11: RICHARD JESUS | B11: P06 | C11: P06 | D11: P06 | E11: F | F11: F | G11: P14 | H11: P14 | I11: P14 | J11: P14 | K11: P14 | L11: F | M11: F | N11: P06 | O11: P06 | P11: P06 | Q11: P06 | R11: F | S11: F | T11: P14 | U11: P14 | V11: P14 | W11: P14 | X11: P14 | Y11: F | Z11: F | AA11: P06 | AB11: P06 | AC11: P06 | AD11: P06 | AE11: F | AF11: F | AH11: 7 | AI11: =COUNTIF(B11:AF11,"UA") -> 0 | AJ11: =AH11-AI11 -> 7 | AL11: 22 | AM11: =COUNTIF(B11:AF11,"U") -> 0 | AN11: =AL11-AM11 -> 22
A13: Total P06 | B13: =COUNTIF(B4:B11,"P06") -> 1 | C13: =COUNTIF(C4:C11,"P06") -> 2 | D13: =COUNTIF(D4:D11,"P06") -> 2 | E13: =COUNTIF(E4:E11,"P06") -> 1 | F13: =COUNTIF(F4:F11,"P06") -> 1 | G13: =COUNTIF(G4:G11,"P06") -> 2 | H13: =COUNTIF(H4:H11,"P06") -> 1 | I13: =COUNTIF(I4:I11,"P06") -> 1 | ... AF13: =COUNTIF(AF4:AF11,"P06") -> 1
A14: Total P14 | B14: =COUNTIF(B4:B11,"P14") -> 1 | C14: =COUNTIF(C4:C11,"P14") -> 1 | D14: =COUNTIF(D4:D11,"P14") -> 2 | E14: =COUNTIF(E4:E11,"P14") -> 1 | F14: =COUNTIF(F4:F11,"P14") -> 1 | G14: =COUNTIF(G4:G11,"P14") -> 2 | H14: =COUNTIF(H4:H11,"P14") -> 2 | I14: =COUNTIF(I4:I11,"P14") -> 1 | ... AF14: =COUNTIF(AF4:AF11,"P14") -> 1
F16: Horario | H16: Pausa | M16: F | N16: Folga | S16: FJ | T16: Falta Justificada | Z16: Provisório
E17: P06 | F17: 06:00-14:00 | H17: 10:00-10:30 | M17: A | N17: Folga de compensacao | S17: FINJ | T17: Falta Injustificada
E18: P08 | F18: 08:00-16:00 | H18: 12:00-12:30 | M18: H | N18: Feriado | S18: M | T18: Licenca
E19: P09 | F19: 09:00-17:00 | H19: 13:00-13:30 | M19: U | N19: Ferias | S19: P | T19: Licenca
E20: P14 | F20: 14:00-22:00 | H20: 18:00-18:30 | M20: UA | N20: Ferias do ano anterior | S20: S1 | T20: Licenca
E21: P22 | F21: 22:00-06:00 | H21: 02:00-02:30 | M21: H | N21: Feriado nao aprovado | S21: K | T21: Ausente
M22: U | N22: Dia de ferias nao aprovado | S22: K1 | T22: Ausente
M23: B | N23: Birthday | S23: K2 | T23: Ausente
M24: B* | N24: Birthday - dia alternativo | S24: K6 | T24: Ausente
M25: TR | N25: Training | S25: E | T25: Ausente
M26: S3 | N26: Ausencia Especial | S26: EM | T26: Ausente
M27: TB | N27: Team Building | S27: J | T27: Ausente
M28: R | N28: Viagem em Servico | S28: NO | T28: Ausente
M29: D | N29: Viagem em Servico Alemanha | S29: CM1 | T29: Ausente
M30: SE | N30: Servico Especial | S30: V | T30: Solidariedade

Sheet FEB
A1: LGSP - Lufthansa Ground Services Portugal NIF : 509 842 593 Atividade: CAE 52230.R3 Sede e local de trabalho: Avenida da Boavista ED.Burgo, 1837 sala 13.4/ Horario de Funcionamento: 24/7 IRT : Nao Aplicavel
A2: 46054 | B2: =IF(COLUMN(A1)<=DAY(EOMONTH($A$2,0)),COLUMN(A1),"") -> 1 | C2: =IF(COLUMN(B1)<=DAY(EOMONTH($A$2,0)),COLUMN(B1),"") -> 2 | D2: =IF(COLUMN(C1)<=DAY(EOMONTH($A$2,0)),COLUMN(C1),"") -> 3 | E2: =IF(COLUMN(D1)<=DAY(EOMONTH($A$2,0)),COLUMN(D1),"") -> 4 | F2: =IF(COLUMN(E1)<=DAY(EOMONTH($A$2,0)),COLUMN(E1),"") -> 5 | G2: =IF(COLUMN(F1)<=DAY(EOMONTH($A$2,0)),COLUMN(F1),"") -> 6 | H2: =IF(COLUMN(G1)<=DAY(EOMONTH($A$2,0)),COLUMN(G1),"") -> 7 | I2: =IF(COLUMN(H1)<=DAY(EOMONTH($A$2,0)),COLUMN(H1),"") -> 8 | ... AC2: =IF(COLUMN(AB1)<=DAY(EOMONTH($A$2,0)),COLUMN(AB1),"") -> 28 | AE2: Ferias 2025 | AI2: Ferias 2026
B3: =UPPER(LEFT(TEXT(DATE(YEAR($A$2),MONTH($A$2),B2),"DDD"),2)) -> SU | C3: =UPPER(LEFT(TEXT(DATE(YEAR($A$2),MONTH($A$2),C2),"DDD"),2)) -> MO | D3: =UPPER(LEFT(TEXT(DATE(YEAR($A$2),MONTH($A$2),D2),"DDD"),2)) -> TU | E3: =UPPER(LEFT(TEXT(DATE(YEAR($A$2),MONTH($A$2),E2),"DDD"),2)) -> WE | F3: =UPPER(LEFT(TEXT(DATE(YEAR($A$2),MONTH($A$2),F2),"DDD"),2)) -> TH | G3: =UPPER(LEFT(TEXT(DATE(YEAR($A$2),MONTH($A$2),G2),"DDD"),2)) -> FR | H3: =UPPER(LEFT(TEXT(DATE(YEAR($A$2),MONTH($A$2),H2),"DDD"),2)) -> SA | I3: =UPPER(LEFT(TEXT(DATE(YEAR($A$2),MONTH($A$2),I2),"DDD"),2)) -> SU | ... AC3: =UPPER(LEFT(TEXT(DATE(YEAR($A$2),MONTH($A$2),AC2),"DDD"),2)) -> SA | AE3: 2025 | AF3: Used | AG3: Left | AI3: 2026 | AJ3: Used | AK3: Left
A4: LUISA TAVARES | B4: F | C4: P09 | D4: P09 | E4: P09 | F4: P09 | G4: P09 | H4: F | I4: F | J4: P09 | K4: P09 | L4: P09 | M4: P09 | N4: P09 | O4: F | P4: F | Q4: P09 | R4: H | S4: P09 | T4: P09 | U4: P09 | V4: F | W4: F | X4: P09 | Y4: P09 | Z4: P09 | AA4: P09 | AB4: P09 | AC4: F | AE4: =JAN!AJ4 -> 3 | AF4: =COUNTIF(B4:AC4,"UA") -> 0 | AG4: =AE4-AF4 -> 3 | AI4: =JAN!AN4 -> 22 | AJ4: =COUNTIF(B4:AC4,"U") -> 0 | AK4: =AI4-AJ4 -> 22
A5: FABIO FILIPE PEREIRA | B5: F | C5: P09 | D5: P09 | E5: P09 | F5: P09 | G5: P09 | H5: F | I5: F | J5: P09 | K5: P09 | L5: P09 | M5: P09 | N5: P09 | O5: F | P5: F | Q5: P09 | R5: H | S5: P09 | T5: P09 | U5: P09 | V5: F | W5: F | X5: P09 | Y5: P09 | Z5: P09 | AA5: P09 | AB5: P09 | AC5: F | AE5: =JAN!AJ5 -> 0 | AF5: =COUNTIF(B5:AC5,"UA") -> 0 | AG5: =AE5-AF5 -> 0 | AI5: =JAN!AN5 -> 22 | AJ5: =COUNTIF(B5:AC5,"U") -> 0 | AK5: =AI5-AJ5 -> 22
A6: ARNOLD LUANZAMBI | B6: F | C6: P09 | D6: P09 | E6: P09 | F6: P09 | G6: P09 | H6: F | I6: F | J6: P09 | K6: P09 | L6: P09 | M6: P09 | N6: P09 | O6: F | P6: F | Q6: P09 | R6: H | S6: P09 | T6: P09 | U6: P09 | V6: F | W6: F | X6: P09 | Y6: P09 | Z6: P09 | AA6: P09 | AB6: P09 | AC6: F | AE6: =JAN!AJ6 -> 8 | AF6: =COUNTIF(B6:AC6,"UA") -> 0 | AG6: =AE6-AF6 -> 8 | AI6: =JAN!AN6 -> 22 | AJ6: =COUNTIF(B6:AC6,"U") -> 0 | AK6: =AI6-AJ6 -> 22
A7: BEATRIZ SEIXAS | B7: F | C7: F | D7: P14 | E7: P14 | F7: P14 | G7: P14 | H7: F | I7: F | J7: P06 | K7: P06 | L7: P06 | M7: P06 | N7: F | O7: F | P7: P14 | Q7: P14 | R7: P14 | S7: P14 | T7: P14 | U7: F | V7: F | W7: P06 | X7: P06 | Y7: P06 | Z7: P06 | AA7: F | AB7: F | AC7: P14 | AE7: =JAN!AJ7 -> 0 | AF7: =COUNTIF(B7:AC7,"UA") -> 0 | AG7: =AE7-AF7 -> 0 | AI7: =JAN!AN7 -> 18 | AJ7: =COUNTIF(B7:AC7,"U") -> 0 | AK7: =AI7-AJ7 -> 18
A8: PAULO COSTA | B8: UA | C8: F | D8: F | E8: UA | F8: UA | G8: UA | H8: UA | I8: F | J8: F | K8: UA | L8: UA | M8: UA | N8: P06 | O8: P06 | P8: F | Q8: F | R8: H | S8: P14 | T8: P14 | U8: P14 | V8: F | W8: F | X8: P06 | Y8: P06 | Z8: P06 | AA8: P06 | AB8: P06 | AC8: F | AE8: =JAN!AJ8 -> 16 | AF8: =COUNTIF(B8:AC8,"UA") -> 8 | AG8: =AE8-AF8 -> 8 | AI8: =JAN!AN8 -> 22 | AJ8: =COUNTIF(B8:AC8,"U") -> 0 | AK8: =AI8-AJ8 -> 22
A9: PEDRO SOARES | B9: P14 | C9: P14 | D9: F | E9: F | F9: P06 | G9: P06 | H9: P06 | I9: P06 | J9: F | K9: F | L9: P14 | M9: P14 | N9: P14 | O9: P14 | P9: F | Q9: F | R9: P06 | S9: P06 | T9: P06 | U9: P06 | V9: P06 | W9: F | X9: F | Y9: P14 | Z9: P14 | AA9: P14 | AB9: P14 | AC9: F | AE9: =JAN!AJ9 -> 0 | AF9: =COUNTIF(B9:AC9,"UA") -> 0 | AG9: =AE9-AF9 -> 0 | AI9: =JAN!AN9 -> 22 | AJ9: =COUNTIF(B9:AC9,"U") -> 0 | AK9: =AI9-AJ9 -> 22
A10: JOSE ALEXANDRE FERREIRA | B10: P06 | C10: P06 | D10: P06 | E10: P06 | F10: F | G10: F | H10: P14 | I10: P14 | J10: P14 | K10: P14 | L10: P14 | M10: F | N10: F | O10: P06 | P10: P06 | Q10: P06 | R10: H | S10: F | T10: F | U10: P14 | V10: P14 | W10: P14 | X10: P14 | Y10: F | Z10: F | AA10: P06 | AB10: P06 | AC10: P06 | AE10: =JAN!AJ10 -> 0 | AF10: =COUNTIF(B10:AC10,"UA") -> 0 | AG10: =AE10-AF10 -> 0 | AI10: =JAN!AN10 -> 22 | AJ10: =COUNTIF(B10:AC10,"U") -> 0 | AK10: =AI10-AJ10 -> 22
A11: RICHARD JESUS | B11: P14 | C11: P14 | D11: P14 | E11: P14 | F11: F | G11: F | H11: P06 | I11: P06 | J11: P06 | K11: P06 | L11: F | M11: F | N11: UA | O11: UA | P11: UA | Q11: UA | R11: F | S11: F | T11: UA | U11: UA | V11: UA | W11: P06 | X11: F | Y11: F | Z11: P14 | AA11: P14 | AB11: P14 | AC11: P14 | AE11: =JAN!AJ11 -> 7 | AF11: =COUNTIF(B11:AC11,"UA") -> 7 | AG11: =AE11-AF11 -> 0 | AI11: =JAN!AN11 -> 22 | AJ11: =COUNTIF(B11:AC11,"U") -> 0 | AK11: =AI11-AJ11 -> 22
A13: Total P06 | B13: =COUNTIF(B4:B11,"P06") -> 1 | C13: =COUNTIF(C4:C11,"P06") -> 1 | D13: =COUNTIF(D4:D11,"P06") -> 1 | E13: =COUNTIF(E4:E11,"P06") -> 1 | F13: =COUNTIF(F4:F11,"P06") -> 1 | G13: =COUNTIF(G4:G11,"P06") -> 1 | H13: =COUNTIF(H4:H11,"P06") -> 2 | I13: =COUNTIF(I4:I11,"P06") -> 2 | ... AC13: =COUNTIF(AC4:AC11,"P06") -> 1
A14: Total P14 | B14: =COUNTIF(B4:B11,"P14") -> 2 | C14: =COUNTIF(C4:C11,"P14") -> 2 | D14: =COUNTIF(D4:D11,"P14") -> 2 | E14: =COUNTIF(E4:E11,"P14") -> 2 | F14: =COUNTIF(F4:F11,"P14") -> 1 | G14: =COUNTIF(G4:G11,"P14") -> 1 | H14: =COUNTIF(H4:H11,"P14") -> 1 | I14: =COUNTIF(I4:I11,"P14") -> 1 | ... AC14: =COUNTIF(AC4:AC11,"P14") -> 2
F16: Horario | H16: Pausa | M16: F | N16: Folga | S16: FJ | T16: Falta Justificada | Z16: Provisório
E17: P06 | F17: 06:00-14:00 | H17: 10:00-10:30 | M17: A | N17: Folga de compensacao | S17: FINJ | T17: Falta Injustificada
E18: P08 | F18: 08:00-16:00 | H18: 12:00-12:30 | M18: H | N18: Feriado | S18: M | T18: Licenca
E19: P09 | F19: 09:00-17:00 | H19: 13:00-13:30 | M19: U | N19: Ferias | S19: P | T19: Licenca
E20: P14 | F20: 14:00-22:00 | H20: 18:00-18:30 | M20: UA | N20: Ferias do ano anterior | S20: S1 | T20: Licenca
E21: P22 | F21: 22:00-06:00 | H21: 02:00-02:30 | M21: H | N21: Feriado nao aprovado | S21: K | T21: Ausente
M22: U | N22: Dia de ferias nao aprovado | S22: K1 | T22: Ausente
M23: B | N23: Birthday | S23: K2 | T23: Ausente
M24: B* | N24: Birthday - dia alternativo | S24: K6 | T24: Ausente
M25: TR | N25: Training | S25: E | T25: Ausente
M26: S3 | N26: Ausencia Especial | S26: EM | T26: Ausente
M27: TB | N27: Team Building | S27: J | T27: Ausente
M28: R | N28: Viagem em Servico | S28: NO | T28: Ausente
M29: D | N29: Viagem em Servico Alemanha | S29: CM1 | T29: Ausente
M30: SE | N30: Servico Especial | S30: V | T30: Solidariedade

Sheet MAR
A1: LGSP - Lufthansa Ground Services Portugal NIF : 509 842 593 Atividade: CAE 52230.R3 Sede e local de trabalho: Avenida da Boavista ED.Burgo, 1837 sala 13.4/ Horario de Funcionamento: 24/7 IRT : Nao Aplicavel
A2: 46082 | B2: =IF(COLUMN(A1)<=DAY(EOMONTH($A$2,0)),COLUMN(A1),"") -> 1 | C2: =IF(COLUMN(B1)<=DAY(EOMONTH($A$2,0)),COLUMN(B1),"") -> 2 | D2: =IF(COLUMN(C1)<=DAY(EOMONTH($A$2,0)),COLUMN(C1),"") -> 3 | E2: =IF(COLUMN(D1)<=DAY(EOMONTH($A$2,0)),COLUMN(D1),"") -> 4 | F2: =IF(COLUMN(E1)<=DAY(EOMONTH($A$2,0)),COLUMN(E1),"") -> 5 | G2: =IF(COLUMN(F1)<=DAY(EOMONTH($A$2,0)),COLUMN(F1),"") -> 6 | H2: =IF(COLUMN(G1)<=DAY(EOMONTH($A$2,0)),COLUMN(G1),"") -> 7 | I2: =IF(COLUMN(H1)<=DAY(EOMONTH($A$2,0)),COLUMN(H1),"") -> 8 | ... AF2: =IF(COLUMN(AE1)<=DAY(EOMONTH($A$2,0)),COLUMN(AE1),"") -> 31 | AH2: Ferias 2025 | AL2: Ferias 2026
B3: =UPPER(LEFT(TEXT(DATE(YEAR($A$2),MONTH($A$2),B2),"DDD"),2)) -> SU | C3: =UPPER(LEFT(TEXT(DATE(YEAR($A$2),MONTH($A$2),C2),"DDD"),2)) -> MO | D3: =UPPER(LEFT(TEXT(DATE(YEAR($A$2),MONTH($A$2),D2),"DDD"),2)) -> TU | E3: =UPPER(LEFT(TEXT(DATE(YEAR($A$2),MONTH($A$2),E2),"DDD"),2)) -> WE | F3: =UPPER(LEFT(TEXT(DATE(YEAR($A$2),MONTH($A$2),F2),"DDD"),2)) -> TH | G3: =UPPER(LEFT(TEXT(DATE(YEAR($A$2),MONTH($A$2),G2),"DDD"),2)) -> FR | H3: =UPPER(LEFT(TEXT(DATE(YEAR($A$2),MONTH($A$2),H2),"DDD"),2)) -> SA | I3: =UPPER(LEFT(TEXT(DATE(YEAR($A$2),MONTH($A$2),I2),"DDD"),2)) -> SU | ... AF3: =UPPER(LEFT(TEXT(DATE(YEAR($A$2),MONTH($A$2),AF2),"DDD"),2)) -> TU | AH3: 2025 | AI3: Used | AJ3: Left | AL3: 2026 | AM3: Used | AN3: Left
A4: LUISA TAVARES | B4: F | C4: P09 | D4: P09 | E4: P09 | F4: P09 | G4: P09 | H4: F | I4: F | J4: P09 | K4: P09 | L4: P09 | M4: P09 | N4: P09 | O4: F | P4: F | Q4: P09 | R4: P09 | S4: P09 | T4: P09 | U4: P09 | V4: F | W4: F | X4: P09 | Y4: P09 | Z4: P09 | AA4: P09 | AB4: P09 | AC4: F | AD4: F | AE4: P09 | AF4: P09 | AH4: =FEB!AG4 -> 3 | AI4: =COUNTIF(B4:AF4,"UA") -> 0 | AJ4: =AH4-AI4 -> 3 | AL4: =FEB!AK4 -> 22 | AM4: =COUNTIF(B4:AF4,"U") -> 0 | AN4: =AL4-AM4 -> 22
A5: FABIO FILIPE PEREIRA | B5: F | C5: P09 | D5: P09 | E5: P09 | F5: P09 | G5: P09 | H5: F | I5: F | J5: P09 | K5: P09 | L5: P09 | M5: P09 | N5: P09 | O5: F | P5: F | Q5: P09 | R5: P09 | S5: P09 | T5: P09 | U5: P09 | V5: F | W5: F | X5: P09 | Y5: P09 | Z5: P09 | AA5: P09 | AB5: P09 | AC5: F | AD5: F | AE5: P09 | AF5: P09 | AH5: =FEB!AG5 -> 0 | AI5: =COUNTIF(B5:AF5,"UA") -> 0 | AJ5: =AH5-AI5 -> 0 | AL5: =FEB!AK5 -> 22 | AM5: =COUNTIF(B5:AF5,"U") -> 0 | AN5: =AL5-AM5 -> 22
A6: ARNOLD LUANZAMBI | B6: F | C6: P09 | D6: P09 | E6: P09 | F6: P09 | G6: P09 | H6: F | I6: F | J6: P09 | K6: P09 | L6: P09 | M6: P09 | N6: P09 | O6: F | P6: F | Q6: P09 | R6: P09 | S6: P09 | T6: P09 | U6: P09 | V6: F | W6: F | X6: P09 | Y6: P09 | Z6: P09 | AA6: P09 | AB6: P09 | AC6: F | AD6: F | AE6: P09 | AF6: P09 | AH6: =FEB!AG6 -> 8 | AI6: =COUNTIF(B6:AF6,"UA") -> 0 | AJ6: =AH6-AI6 -> 8 | AL6: =FEB!AK6 -> 22 | AM6: =COUNTIF(B6:AF6,"U") -> 0 | AN6: =AL6-AM6 -> 22
A7: BEATRIZ SEIXAS | B7: P14 | C7: P14 | D7: P14 | E7: P14 | F7: F | G7: F | H7: P06 | I7: P06 | J7: P06 | K7: P06 | L7: F | M7: F | N7: P14 | O7: P14 | P7: P14 | Q7: P14 | R7: F | S7: F | T7: P06 | U7: P06 | V7: P06 | W7: P06 | X7: P06 | Y7: F | Z7: F | AA7: P14 | AB7: P14 | AC7: P14 | AD7: P14 | AE7: F | AF7: F | AH7: =FEB!AG7 -> 0 | AI7: =COUNTIF(B7:AF7,"UA") -> 0 | AJ7: =AH7-AI7 -> 0 | AL7: =FEB!AK7 -> 18 | AM7: =COUNTIF(B7:AF7,"U") -> 0 | AN7: =AL7-AM7 -> 18
A8: PAULO COSTA | B8: F | C8: P14 | D8: P14 | E8: P14 | F8: P14 | G8: F | H8: F | I8: P06 | J8: P06 | K8: P06 | L8: P06 | M8: F | N8: F | O8: P14 | P8: P14 | Q8: P14 | R8: P14 | S8: P14 | T8: F | U8: F | V8: P06 | W8: P06 | X8: P06 | Y8: P06 | Z8: F | AA8: F | AB8: P14 | AC8: P14 | AD8: P14 | AE8: P14 | AF8: F | AH8: =FEB!AG8 -> 8 | AI8: =COUNTIF(B8:AF8,"UA") -> 0 | AJ8: =AH8-AI8 -> 8 | AL8: =FEB!AK8 -> 22 | AM8: =COUNTIF(B8:AF8,"U") -> 0 | AN8: =AL8-AM8 -> 22
A9: PEDRO SOARES | B9: F | C9: P06 | D9: P06 | E9: P06 | F9: P06 | G9: P06 | H9: F | I9: F | J9: P14 | K9: P14 | L9: P14 | M9: P14 | N9: F | O9: F | P9: P06 | Q9: P06 | R9: P06 | S9: P06 | T9: P06 | U9: F | V9: F | W9: P14 | X9: P14 | Y9: P14 | Z9: P14 | AA9: F | AB9: F | AC9: P06 | AD9: P06 | AE9: P06 | AF9: P06 | AH9: =FEB!AG9 -> 0 | AI9: =COUNTIF(B9:AF9,"UA") -> 0 | AJ9: =AH9-AI9 -> 0 | AL9: =FEB!AK9 -> 22 | AM9: =COUNTIF(B9:AF9,"U") -> 0 | AN9: =AL9-AM9 -> 22
A10: JOSE ALEXANDRE FERREIRA | B10: P06 | C10: P06 | D10: F | E10: F | F10: P14 | G10: P14 | H10: P14 | I10: P14 | J10: F | K10: F | L10: P06 | M10: P06 | N10: P06 | O10: P06 | P10: F | Q10: F | R10: P14 | S10: P14 | T10: P14 | U10: P14 | V10: P14 | W10: F | X10: F | Y10: P06 | Z10: P06 | AA10: P06 | AB10: P06 | AC10: F | AD10: F | AE10: P14 | AF10: P14 | AH10: =FEB!AG10 -> 0 | AI10: =COUNTIF(B10:AF10,"UA") -> 0 | AJ10: =AH10-AI10 -> 0 | AL10: =FEB!AK10 -> 22 | AM10: =COUNTIF(B10:AF10,"U") -> 0 | AN10: =AL10-AM10 -> 22
A11: RICHARD JESUS | B11: P14 | C11: F | D11: F | E11: P06 | F11: P06 | G11: P06 | H11: P06 | I11: F | J11: F | K11: P14 | L11: P14 | M11: P14 | N11: P14 | O11: F | P11: F | Q11: P06 | R11: P06 | S11: P06 | T11: P06 | U11: P06 | V11: F | W11: F | X11: P14 | Y11: P14 | Z11: P14 | AA11: P14 | AB11: F | AC11: F | AD11: P06 | AE11: P06 | AF11: P06 | AH11: =FEB!AG11 -> 0 | AI11: =COUNTIF(B11:AF11,"UA") -> 0 | AJ11: =AH11-AI11 -> 0 | AL11: =FEB!AK11 -> 22 | AM11: =COUNTIF(B11:AF11,"U") -> 0 | AN11: =AL11-AM11 -> 22
A13: Total P06 | B13: =COUNTIF(B4:B11,"P06") -> 1 | C13: =COUNTIF(C4:C11,"P06") -> 2 | D13: =COUNTIF(D4:D11,"P06") -> 1 | E13: =COUNTIF(E4:E11,"P06") -> 2 | F13: =COUNTIF(F4:F11,"P06") -> 2 | G13: =COUNTIF(G4:G11,"P06") -> 2 | H13: =COUNTIF(H4:H11,"P06") -> 2 | I13: =COUNTIF(I4:I11,"P06") -> 2 | ... AF13: =COUNTIF(AF4:AF11,"P06") -> 2
A14: Total P14 | B14: =COUNTIF(B4:B11,"P14") -> 2 | C14: =COUNTIF(C4:C11,"P14") -> 2 | D14: =COUNTIF(D4:D11,"P14") -> 2 | E14: =COUNTIF(E4:E11,"P14") -> 2 | F14: =COUNTIF(F4:F11,"P14") -> 2 | G14: =COUNTIF(G4:G11,"P14") -> 1 | H14: =COUNTIF(H4:H11,"P14") -> 1 | I14: =COUNTIF(I4:I11,"P14") -> 1 | ... AF14: =COUNTIF(AF4:AF11,"P14") -> 1
F16: Horario | H16: Pausa | M16: F | N16: Folga | S16: FJ | T16: Falta Justificada | Z16: Provisório
E17: P06 | F17: 06:00-14:00 | H17: 10:00-10:30 | M17: A | N17: Folga de compensacao | S17: FINJ | T17: Falta Injustificada
E18: P08 | F18: 08:00-16:00 | H18: 12:00-12:30 | M18: H | N18: Feriado | S18: M | T18: Licenca
E19: P09 | F19: 09:00-17:00 | H19: 13:00-13:30 | M19: U | N19: Ferias | S19: P | T19: Licenca
E20: P14 | F20: 14:00-22:00 | H20: 18:00-18:30 | M20: UA | N20: Ferias do ano anterior | S20: S1 | T20: Licenca
E21: P22 | F21: 22:00-06:00 | H21: 02:00-02:30 | M21: H | N21: Feriado nao aprovado | S21: K | T21: Ausente
M22: U | N22: Dia de ferias nao aprovado | S22: K1 | T22: Ausente
M23: B | N23: Birthday | S23: K2 | T23: Ausente
M24: B* | N24: Birthday - dia alternativo | S24: K6 | T24: Ausente
M25: TR | N25: Training | S25: E | T25: Ausente
M26: S3 | N26: Ausencia Especial | S26: EM | T26: Ausente
M27: TB | N27: Team Building | S27: J | T27: Ausente
M28: R | N28: Viagem em Servico | S28: NO | T28: Ausente
M29: D | N29: Viagem em Servico Alemanha | S29: CM1 | T29: Ausente
M30: SE | N30: Servico Especial | S30: V | T30: Solidariedade

Sheet APR
A1: LGSP - Lufthansa Ground Services Portugal NIF : 509 842 593 Atividade: CAE 52230.R3 Sede e local de trabalho: Avenida da Boavista ED.Burgo, 1837 sala 13.4/ Horario de Funcionamento: 24/7 IRT : Nao Aplicavel
A2: 46113 | B2: =IF(COLUMN(A1)<=DAY(EOMONTH($A$2,0)),COLUMN(A1),"") -> 1 | C2: =IF(COLUMN(B1)<=DAY(EOMONTH($A$2,0)),COLUMN(B1),"") -> 2 | D2: =IF(COLUMN(C1)<=DAY(EOMONTH($A$2,0)),COLUMN(C1),"") -> 3 | E2: =IF(COLUMN(D1)<=DAY(EOMONTH($A$2,0)),COLUMN(D1),"") -> 4 | F2: =IF(COLUMN(E1)<=DAY(EOMONTH($A$2,0)),COLUMN(E1),"") -> 5 | G2: =IF(COLUMN(F1)<=DAY(EOMONTH($A$2,0)),COLUMN(F1),"") -> 6 | H2: =IF(COLUMN(G1)<=DAY(EOMONTH($A$2,0)),COLUMN(G1),"") -> 7 | I2: =IF(COLUMN(H1)<=DAY(EOMONTH($A$2,0)),COLUMN(H1),"") -> 8 | ... AE2: =IF(COLUMN(AD1)<=DAY(EOMONTH($A$2,0)),COLUMN(AD1),"") -> 30 | AG2: Ferias 2025 | AK2: Ferias 2026
B3: =UPPER(LEFT(TEXT(DATE(YEAR($A$2),MONTH($A$2),B2),"DDD"),2)) -> WE | C3: =UPPER(LEFT(TEXT(DATE(YEAR($A$2),MONTH($A$2),C2),"DDD"),2)) -> TH | D3: =UPPER(LEFT(TEXT(DATE(YEAR($A$2),MONTH($A$2),D2),"DDD"),2)) -> FR | E3: =UPPER(LEFT(TEXT(DATE(YEAR($A$2),MONTH($A$2),E2),"DDD"),2)) -> SA | F3: =UPPER(LEFT(TEXT(DATE(YEAR($A$2),MONTH($A$2),F2),"DDD"),2)) -> SU | G3: =UPPER(LEFT(TEXT(DATE(YEAR($A$2),MONTH($A$2),G2),"DDD"),2)) -> MO | H3: =UPPER(LEFT(TEXT(DATE(YEAR($A$2),MONTH($A$2),H2),"DDD"),2)) -> TU | I3: =UPPER(LEFT(TEXT(DATE(YEAR($A$2),MONTH($A$2),I2),"DDD"),2)) -> WE | ... AE3: =UPPER(LEFT(TEXT(DATE(YEAR($A$2),MONTH($A$2),AE2),"DDD"),2)) -> TH | AG3: 2025 | AH3: Used | AI3: Left | AK3: 2026 | AL3: Used | AM3: Left
A4: LUISA TAVARES | B4: P08 | C4: P08 | D4: H | E4: F | F4: F | G4: P08 | H4: P08 | I4: P08 | J4: P08 | K4: P08 | L4: F | M4: F | N4: P08 | O4: P08 | P4: P08 | Q4: P08 | R4: P08 | S4: F | T4: F | U4: P08 | V4: P08 | W4: P08 | X4: P08 | Y4: B | Z4: F | AA4: F | AB4: P08 | AC4: P08 | AD4: P08 | AE4: P08 | AG4: =MAR!AJ4 -> 3 | AH4: =COUNTIF(B4:AE4,"UA") -> 0 | AI4: =AG4-AH4 -> 3 | AK4: =MAR!AN4 -> 22 | AL4: =COUNTIF(B4:AE4,"U") -> 0 | AM4: =AK4-AL4 -> 22
A5: FABIO FILIPE PEREIRA | B5: P09 | C5: P09 | D5: H | E5: F | F5: F | G5: P09 | H5: P09 | I5: P09 | J5: P09 | K5: P09 | L5: F | M5: F | N5: P09 | O5: P09 | P5: P09 | Q5: P09 | R5: P09 | S5: F | T5: F | U5: P09 | V5: P09 | W5: P09 | X5: P09 | Y5: P09 | Z5: F | AA5: F | AB5: P09 | AC5: P09 | AD5: P09 | AE5: P09 | AG5: =MAR!AJ5 -> 0 | AH5: =COUNTIF(B5:AE5,"UA") -> 0 | AI5: =AG5-AH5 -> 0 | AK5: =MAR!AN5 -> 22 | AL5: =COUNTIF(B5:AE5,"U") -> 0 | AM5: =AK5-AL5 -> 22
A6: ARNOLD LUANZAMBI | B6: UA | C6: UA | D6: H | E6: F | F6: F | G6: UA | H6: UA | I6: UA | J6: B | K6: UA | L6: F | M6: F | N6: UA | O6: UA | P6: U | Q6: U | R6: U | S6: F | T6: F | U6: P09 | V6: P09 | W6: P09 | X6: P09 | Y6: P09 | Z6: F | AA6: F | AB6: P09 | AC6: P09 | AD6: P09 | AE6: P09 | AG6: =MAR!AJ6 -> 8 | AH6: =COUNTIF(B6:AE6,"UA") -> 8 | AI6: =AG6-AH6 -> 0 | AK6: =MAR!AN6 -> 22 | AL6: =COUNTIF(B6:AE6,"U") -> 3 | AM6: =AK6-AL6 -> 19
A7: BEATRIZ SEIXAS | B7: P06 | C7: P06 | D7: H | E7: P06 | F7: F | G7: F | H7: P14 | I7: P14 | J7: P14 | K7: P14 | L7: P14 | M7: F | N7: F | O7: P06 | P7: P06 | Q7: P06 | R7: P06 | S7: F | T7: F | U7: P14 | V7: P14 | W7: P14 | X7: P14 | Y7: P14 | Z7: F | AA7: F | AB7: P06 | AC7: P06 | AD7: P06 | AE7: P06 | AG7: =MAR!AJ7 -> 0 | AH7: =COUNTIF(B7:AE7,"UA") -> 0 | AI7: =AG7-AH7 -> 0 | AK7: =MAR!AN7 -> 18 | AL7: =COUNTIF(B7:AE7,"U") -> 0 | AM7: =AK7-AL7 -> 18
A8: PAULO COSTA | B8: F | C8: P14 | D8: P14 | E8: P14 | F8: P14 | G8: F | H8: F | I8: P06 | J8: P06 | K8: P06 | L8: P06 | M8: P06 | N8: F | O8: F | P8: P14 | Q8: P14 | R8: P14 | S8: P14 | T8: F | U8: F | V8: P06 | W8: P06 | X8: P06 | Y8: P06 | Z8: F | AA8: F | AB8: P14 | AC8: P14 | AD8: P14 | AE8: P14 | AG8: =MAR!AJ8 -> 8 | AH8: =COUNTIF(B8:AE8,"UA") -> 0 | AI8: =AG8-AH8 -> 8 | AK8: =MAR!AN8 -> 22 | AL8: =COUNTIF(B8:AE8,"U") -> 0 | AM8: =AK8-AL8 -> 22
A9: PEDRO SOARES | B9: F | C9: F | D9: P06 | E9: P06 | F9: P06 | G9: P06 | H9: P06 | I9: F | J9: F | K9: P14 | L9: P14 | M9: P14 | N9: P14 | O9: F | P9: F | Q9: P06 | R9: P06 | S9: P06 | T9: P06 | U9: F | V9: F | W9: P14 | X9: P14 | Y9: P14 | Z9: H | AA9: F | AB9: F | AC9: P06 | AD9: P06 | AE9: P06 | AG9: =MAR!AJ9 -> 0 | AH9: =COUNTIF(B9:AE9,"UA") -> 0 | AI9: =AG9-AH9 -> 0 | AK9: =MAR!AN9 -> 22 | AL9: =COUNTIF(B9:AE9,"U") -> 0 | AM9: =AK9-AL9 -> 22
A10: JOSE ALEXANDRE FERREIRA | B10: P14 | C10: P14 | D10: H | E10: F | F10: F | G10: P06 | H10: P06 | I10: P06 | J10: P06 | K10: F | L10: F | M10: P14 | N10: P14 | O10: P14 | P10: P14 | Q10: F | R10: F | S10: P06 | T10: P06 | U10: P06 | V10: P06 | W10: P06 | X10: F | Y10: F | Z10: P14 | AA10: P14 | AB10: P14 | AC10: P14 | AD10: F | AE10: F | AG10: =MAR!AJ10 -> 0 | AH10: =COUNTIF(B10:AE10,"UA") -> 0 | AI10: =AG10-AH10 -> 0 | AK10: =MAR!AN10 -> 22 | AL10: =COUNTIF(B10:AE10,"U") -> 0 | AM10: =AK10-AL10 -> 22
A11: RICHARD JESUS | B11: P06 | C11: P06 | D11: F | E11: F | F11: H | G11: P14 | H11: P14 | I11: P14 | J11: F | K11: F | L11: P06 | M11: P06 | N11: P06 | O11: P06 | P11: F | Q11: F | R11: P14 | S11: P14 | T11: P14 | U11: P14 | V11: F | W11: F | X11: P06 | Y11: P06 | Z11: P06 | AA11: P06 | AB11: P06 | AC11: F | AD11: F | AE11: P14 | AG11: =MAR!AJ11 -> 0 | AH11: =COUNTIF(B11:AE11,"UA") -> 0 | AI11: =AG11-AH11 -> 0 | AK11: =MAR!AN11 -> 22 | AL11: =COUNTIF(B11:AE11,"U") -> 0 | AM11: =AK11-AL11 -> 22
A13: Total P06 | B13: =COUNTIF(B4:B11,"P06") -> 2 | C13: =COUNTIF(C4:C11,"P06") -> 2 | D13: =COUNTIF(D4:D11,"P06") -> 1 | E13: =COUNTIF(E4:E11,"P06") -> 2 | F13: =COUNTIF(F4:F11,"P06") -> 1 | G13: =COUNTIF(G4:G11,"P06") -> 2 | H13: =COUNTIF(H4:H11,"P06") -> 2 | I13: =COUNTIF(I4:I11,"P06") -> 2 | ... AE13: =COUNTIF(AE4:AE11,"P06") -> 2
A14: Total P14 | B14: =COUNTIF(B4:B11,"P14") -> 1 | C14: =COUNTIF(C4:C11,"P14") -> 2 | D14: =COUNTIF(D4:D11,"P14") -> 1 | E14: =COUNTIF(E4:E11,"P14") -> 1 | F14: =COUNTIF(F4:F11,"P14") -> 1 | G14: =COUNTIF(G4:G11,"P14") -> 1 | H14: =COUNTIF(H4:H11,"P14") -> 2 | I14: =COUNTIF(I4:I11,"P14") -> 2 | ... AE14: =COUNTIF(AE4:AE11,"P14") -> 2
F16: Horario | H16: Pausa | M16: F | N16: Folga | S16: FJ | T16: Falta Justificada | Z16: Provisório
E17: P06 | F17: 06:00-14:00 | H17: 10:00-10:30 | M17: A | N17: Folga de compensacao | S17: FINJ | T17: Falta Injustificada
E18: P08 | F18: 08:00-16:00 | H18: 12:00-12:30 | M18: H | N18: Feriado | S18: M | T18: Licenca
E19: P09 | F19: 09:00-17:00 | H19: 13:00-13:30 | M19: U | N19: Ferias | S19: P | T19: Licenca
E20: P14 | F20: 14:00-22:00 | H20: 18:00-18:30 | M20: UA | N20: Ferias do ano anterior | S20: S1 | T20: Licenca
E21: P22 | F21: 22:00-06:00 | H21: 02:00-02:30 | M21: H | N21: Feriado nao aprovado | S21: K | T21: Ausente
M22: U | N22: Dia de ferias nao aprovado | S22: K1 | T22: Ausente
M23: B | N23: Birthday | S23: K2 | T23: Ausente
M24: B* | N24: Birthday - dia alternativo | S24: K6 | T24: Ausente
M25: TR | N25: Training | S25: E | T25: Ausente
M26: S3 | N26: Ausencia Especial | S26: EM | T26: Ausente
M27: TB | N27: Team Building | S27: J | T27: Ausente
M28: R | N28: Viagem em Servico | S28: NO | T28: Ausente
M29: D | N29: Viagem em Servico Alemanha | S29: CM1 | T29: Ausente
M30: SE | N30: Servico Especial | S30: V | T30: Solidariedade

Sheet MAY
A1: LGSP - Lufthansa Ground Services Portugal NIF : 509 842 593 Atividade: CAE 52230.R3 Sede e local de trabalho: Avenida da Boavista ED.Burgo, 1837 sala 13.4/ Horario de Funcionamento: 24/7 IRT : Nao Aplicavel
A2: 46143 | B2: =IF(COLUMN(A1)<=DAY(EOMONTH($A$2,0)),COLUMN(A1),"") -> 1 | C2: =IF(COLUMN(B1)<=DAY(EOMONTH($A$2,0)),COLUMN(B1),"") -> 2 | D2: =IF(COLUMN(C1)<=DAY(EOMONTH($A$2,0)),COLUMN(C1),"") -> 3 | E2: =IF(COLUMN(D1)<=DAY(EOMONTH($A$2,0)),COLUMN(D1),"") -> 4 | F2: =IF(COLUMN(E1)<=DAY(EOMONTH($A$2,0)),COLUMN(E1),"") -> 5 | G2: =IF(COLUMN(F1)<=DAY(EOMONTH($A$2,0)),COLUMN(F1),"") -> 6 | H2: =IF(COLUMN(G1)<=DAY(EOMONTH($A$2,0)),COLUMN(G1),"") -> 7 | I2: =IF(COLUMN(H1)<=DAY(EOMONTH($A$2,0)),COLUMN(H1),"") -> 8 | ... AF2: =IF(COLUMN(AE1)<=DAY(EOMONTH($A$2,0)),COLUMN(AE1),"") -> 31 | AH2: Ferias 2026
B3: =UPPER(LEFT(TEXT(DATE(YEAR($A$2),MONTH($A$2),B2),"DDD"),2)) -> FR | C3: =UPPER(LEFT(TEXT(DATE(YEAR($A$2),MONTH($A$2),C2),"DDD"),2)) -> SA | D3: =UPPER(LEFT(TEXT(DATE(YEAR($A$2),MONTH($A$2),D2),"DDD"),2)) -> SU | E3: =UPPER(LEFT(TEXT(DATE(YEAR($A$2),MONTH($A$2),E2),"DDD"),2)) -> MO | F3: =UPPER(LEFT(TEXT(DATE(YEAR($A$2),MONTH($A$2),F2),"DDD"),2)) -> TU | G3: =UPPER(LEFT(TEXT(DATE(YEAR($A$2),MONTH($A$2),G2),"DDD"),2)) -> WE | H3: =UPPER(LEFT(TEXT(DATE(YEAR($A$2),MONTH($A$2),H2),"DDD"),2)) -> TH | I3: =UPPER(LEFT(TEXT(DATE(YEAR($A$2),MONTH($A$2),I2),"DDD"),2)) -> FR | ... AF3: =UPPER(LEFT(TEXT(DATE(YEAR($A$2),MONTH($A$2),AF2),"DDD"),2)) -> SU | AH3: 2026 | AI3: Used | AJ3: Left
A4: LUISA TAVARES | B4: H | C4: F | D4: F | E4: P08 | F4: P08 | G4: P08 | H4: P08 | I4: P08 | J4: F | K4: F | L4: P08 | M4: P08 | N4: P08 | O4: P08 | P4: P08 | Q4: F | R4: F | S4: P08 | T4: P08 | U4: P08 | V4: P08 | W4: P08 | X4: F | Y4: F | Z4: P08 | AA4: P08 | AB4: P08 | AC4: P08 | AD4: P08 | AE4: F | AF4: F | AH4: =APR!AM4 -> 22 | AI4: =COUNTIF(B4:AF4,"U") -> 0 | AJ4: =AH4-AI4 -> 22
A5: FABIO FILIPE PEREIRA | B5: H | C5: F | D5: F | E5: P09 | F5: P09 | G5: P09 | H5: P09 | I5: P09 | J5: F | K5: F | L5: P09 | M5: P09 | N5: P09 | O5: P09 | P5: P09 | Q5: F | R5: F | S5: P09 | T5: P09 | U5: P09 | V5: P09 | W5: P09 | X5: F | Y5: F | Z5: P09 | AA5: P09 | AB5: P09 | AC5: P09 | AD5: P09 | AE5: F | AF5: F | AH5: =APR!AM5 -> 22 | AI5: =COUNTIF(B5:AF5,"U") -> 0 | AJ5: =AH5-AI5 -> 22
A6: ARNOLD LUANZAMBI | B6: H | C6: F | D6: F | E6: P09 | F6: P09 | G6: P09 | H6: P09 | I6: P09 | J6: F | K6: F | L6: P09 | M6: P09 | N6: P09 | O6: P09 | P6: P09 | Q6: F | R6: F | S6: P09 | T6: P09 | U6: P09 | V6: P09 | W6: P09 | X6: F | Y6: F | Z6: P09 | AA6: P09 | AB6: P09 | AC6: P09 | AD6: P09 | AE6: F | AF6: F | AH6: =APR!AM6 -> 19 | AI6: =COUNTIF(B6:AF6,"U") -> 0 | AJ6: =AH6-AI6 -> 19
A7: BEATRIZ SEIXAS | B7: F | C7: F | D7: P14 | E7: P14 | F7: P14 | G7: P14 | H7: F | I7: F | J7: P06 | K7: P06 | L7: P06 | M7: P06 | N7: F | O7: F | P7: P14 | Q7: P14 | R7: P14 | S7: P14 | T7: P14 | U7: F | V7: F | W7: P06 | X7: P06 | Y7: P06 | Z7: P06 | AA7: F | AB7: F | AC7: P14 | AD7: P14 | AE7: P14 | AF7: P14 | AH7: =APR!AM7 -> 18 | AI7: =COUNTIF(B7:AF7,"U") -> 0 | AJ7: =AH7-AI7 -> 18
A8: PAULO COSTA | B8: F | C8: F | D8: P06 | E8: P06 | F8: P06 | G8: P06 | H8: P06 | I8: F | J8: F | K8: P14 | L8: P14 | M8: P14 | N8: P14 | O8: F | P8: F | Q8: P06 | R8: P06 | S8: P06 | T8: P06 | U8: P06 | V8: F | W8: F | X8: P14 | Y8: P14 | Z8: P14 | AA8: P14 | AB8: F | AC8: F | AD8: P06 | AE8: P06 | AF8: P06 | AH8: =APR!AM8 -> 22 | AI8: =COUNTIF(B8:AF8,"U") -> 0 | AJ8: =AH8-AI8 -> 22
A9: PEDRO SOARES | B9: P06 | C9: P06 | D9: F | E9: F | F9: P14 | G9: P14 | H9: P14 | I9: P14 | J9: F | K9: F | L9: P06 | M9: P06 | N9: P06 | O9: P06 | P9: P06 | Q9: F | R9: F | S9: P14 | T9: P14 | U9: P14 | V9: P14 | W9: F | X9: F | Y9: P06 | Z9: P06 | AA9: P06 | AB9: P06 | AC9: F | AD9: F | AE9: P14 | AF9: P14 | AH9: =APR!AM9 -> 22 | AI9: =COUNTIF(B9:AF9,"U") -> 0 | AJ9: =AH9-AI9 -> 22
A10: JOSE ALEXANDRE FERREIRA | B10: H | C10: P06 | D10: P06 | E10: P06 | F10: F | G10: F | H10: P14 | I10: P14 | J10: P14 | K10: P14 | L10: P14 | M10: F | N10: F | O10: P06 | P10: P06 | Q10: P06 | R10: P06 | S10: F | T10: F | U10: P14 | V10: P14 | W10: P14 | X10: P14 | Y10: F | Z10: F | AA10: P06 | AB10: P06 | AC10: P06 | AD10: P06 | AE10: B* | AF10: F | AH10: =APR!AM10 -> 22 | AI10: =COUNTIF(B10:AF10,"U") -> 0 | AJ10: =AH10-AI10 -> 22
A11: RICHARD JESUS | B11: P14 | C11: P14 | D11: P14 | E11: F | F11: F | G11: P06 | H11: P06 | I11: P06 | J11: P06 | K11: F | L11: F | M11: P14 | N11: P14 | O11: P14 | P11: P14 | Q11: P14 | R11: F | S11: F | T11: P06 | U11: P06 | V11: P06 | W11: P06 | X11: F | Y11: F | Z11: P14 | AA11: P14 | AB11: P14 | AC11: P14 | AD11: P14 | AE11: F | AF11: F | AH11: =APR!AM11 -> 22 | AI11: =COUNTIF(B11:AF11,"U") -> 0 | AJ11: =AH11-AI11 -> 22
A13: Total P06 | B13: =COUNTIF(B4:B11,"P06") -> 1 | C13: =COUNTIF(C4:C11,"P06") -> 2 | D13: =COUNTIF(D4:D11,"P06") -> 2 | E13: =COUNTIF(E4:E11,"P06") -> 2 | F13: =COUNTIF(F4:F11,"P06") -> 1 | G13: =COUNTIF(G4:G11,"P06") -> 2 | H13: =COUNTIF(H4:H11,"P06") -> 2 | I13: =COUNTIF(I4:I11,"P06") -> 1 | ... AF13: =COUNTIF(AF4:AF11,"P06") -> 1
A14: Total P14 | B14: =COUNTIF(B4:B11,"P14") -> 1 | C14: =COUNTIF(C4:C11,"P14") -> 1 | D14: =COUNTIF(D4:D11,"P14") -> 2 | E14: =COUNTIF(E4:E11,"P14") -> 1 | F14: =COUNTIF(F4:F11,"P14") -> 2 | G14: =COUNTIF(G4:G11,"P14") -> 2 | H14: =COUNTIF(H4:H11,"P14") -> 2 | I14: =COUNTIF(I4:I11,"P14") -> 2 | ... AF14: =COUNTIF(AF4:AF11,"P14") -> 2
F16: Horario | H16: Pausa | M16: F | N16: Folga | S16: FJ | T16: Falta Justificada | Z16: Provisório
E17: P06 | F17: 06:00-14:00 | H17: 10:00-10:30 | M17: A | N17: Folga de compensacao | S17: FINJ | T17: Falta Injustificada
E18: P08 | F18: 08:00-16:00 | H18: 12:00-12:30 | M18: H | N18: Feriado | S18: M | T18: Licenca
E19: P09 | F19: 09:00-17:00 | H19: 13:00-13:30 | M19: U | N19: Ferias | S19: P | T19: Licenca
E20: P14 | F20: 14:00-22:00 | H20: 18:00-18:30 | M20: UA | N20: Ferias do ano anterior | S20: S1 | T20: Licenca
E21: P22 | F21: 22:00-06:00 | H21: 02:00-02:30 | M21: H | N21: Feriado nao aprovado | S21: K | T21: Ausente
M22: U | N22: Dia de ferias nao aprovado | S22: K1 | T22: Ausente
M23: B | N23: Birthday | S23: K2 | T23: Ausente
M24: B* | N24: Birthday - dia alternativo | S24: K6 | T24: Ausente
M25: TR | N25: Training | S25: E | T25: Ausente
M26: S3 | N26: Ausencia Especial | S26: EM | T26: Ausente
M27: TB | N27: Team Building | S27: J | T27: Ausente
M28: R | N28: Viagem em Servico | S28: NO | T28: Ausente
M29: D | N29: Viagem em Servico Alemanha | S29: CM1 | T29: Ausente
M30: SE | N30: Servico Especial | S30: V | T30: Solidariedade

Sheet JUN
A1: LGSP - Lufthansa Ground Services Portugal NIF : 509 842 593 Atividade: CAE 52230.R3 Sede e local de trabalho: Avenida da Boavista ED.Burgo, 1837 sala 13.4/ Horario de Funcionamento: 24/7 IRT : Nao Aplicavel
A2: 46174 | B2: =IF(COLUMN(A1)<=DAY(EOMONTH($A$2,0)),COLUMN(A1),"") -> 1 | C2: =IF(COLUMN(B1)<=DAY(EOMONTH($A$2,0)),COLUMN(B1),"") -> 2 | D2: =IF(COLUMN(C1)<=DAY(EOMONTH($A$2,0)),COLUMN(C1),"") -> 3 | E2: =IF(COLUMN(D1)<=DAY(EOMONTH($A$2,0)),COLUMN(D1),"") -> 4 | F2: =IF(COLUMN(E1)<=DAY(EOMONTH($A$2,0)),COLUMN(E1),"") -> 5 | G2: =IF(COLUMN(F1)<=DAY(EOMONTH($A$2,0)),COLUMN(F1),"") -> 6 | H2: =IF(COLUMN(G1)<=DAY(EOMONTH($A$2,0)),COLUMN(G1),"") -> 7 | I2: =IF(COLUMN(H1)<=DAY(EOMONTH($A$2,0)),COLUMN(H1),"") -> 8 | ... AE2: =IF(COLUMN(AD1)<=DAY(EOMONTH($A$2,0)),COLUMN(AD1),"") -> 30 | AG2: Ferias 2026
B3: =UPPER(LEFT(TEXT(DATE(YEAR($A$2),MONTH($A$2),B2),"DDD"),2)) -> MO | C3: =UPPER(LEFT(TEXT(DATE(YEAR($A$2),MONTH($A$2),C2),"DDD"),2)) -> TU | D3: =UPPER(LEFT(TEXT(DATE(YEAR($A$2),MONTH($A$2),D2),"DDD"),2)) -> WE | E3: =UPPER(LEFT(TEXT(DATE(YEAR($A$2),MONTH($A$2),E2),"DDD"),2)) -> TH | F3: =UPPER(LEFT(TEXT(DATE(YEAR($A$2),MONTH($A$2),F2),"DDD"),2)) -> FR | G3: =UPPER(LEFT(TEXT(DATE(YEAR($A$2),MONTH($A$2),G2),"DDD"),2)) -> SA | H3: =UPPER(LEFT(TEXT(DATE(YEAR($A$2),MONTH($A$2),H2),"DDD"),2)) -> SU | I3: =UPPER(LEFT(TEXT(DATE(YEAR($A$2),MONTH($A$2),I2),"DDD"),2)) -> MO | ... AE3: =UPPER(LEFT(TEXT(DATE(YEAR($A$2),MONTH($A$2),AE2),"DDD"),2)) -> TU | AG3: 2026 | AH3: Used | AI3: Left
A4: LUISA TAVARES | B4: P08 | C4: P08 | D4: P08 | E4: H | F4: P08 | G4: F | H4: F | I4: P08 | J4: P08 | K4: H | L4: P08 | M4: P08 | N4: F | O4: F | P4: P08 | Q4: P08 | R4: P08 | S4: P08 | T4: P08 | U4: F | V4: F | W4: P08 | X4: P08 | Y4: H | Z4: P08 | AA4: P08 | AB4: F | AC4: F | AD4: P08 | AE4: P08 | AG4: =MAY!AJ4 -> 22 | AH4: =COUNTIF(B4:AE4,"U") -> 0 | AI4: =AG4-AH4 -> 22
A5: FABIO FILIPE PEREIRA | B5: P09 | C5: P09 | D5: P09 | E5: H | F5: P09 | G5: F | H5: F | I5: P09 | J5: P09 | K5: H | L5: P09 | M5: P09 | N5: F | O5: F | P5: P09 | Q5: P09 | R5: P09 | S5: P09 | T5: P09 | U5: F | V5: F | W5: P09 | X5: P09 | Y5: H | Z5: P09 | AA5: P09 | AB5: F | AC5: F | AD5: P09 | AE5: P09 | AG5: =MAY!AJ5 -> 22 | AH5: =COUNTIF(B5:AE5,"U") -> 0 | AI5: =AG5-AH5 -> 22
A6: ARNOLD LUANZAMBI | B6: P09 | C6: P09 | D6: P09 | E6: H | F6: P09 | G6: F | H6: F | I6: P09 | J6: P09 | K6: H | L6: P09 | M6: P09 | N6: F | O6: F | P6: P09 | Q6: P09 | R6: P09 | S6: P09 | T6: P09 | U6: F | V6: F | W6: P09 | X6: P09 | Y6: H | Z6: P09 | AA6: P09 | AB6: F | AC6: F | AD6: P09 | AE6: P09 | AG6: =MAY!AJ6 -> 19 | AH6: =COUNTIF(B6:AE6,"U") -> 0 | AI6: =AG6-AH6 -> 19
A7: BEATRIZ SEIXAS | B7: F | C7: F | D7: P14 | E7: P14 | F7: P14 | G7: P14 | H7: F | I7: F | J7: P06 | K7: P06 | L7: P06 | M7: P06 | N7: F | O7: F | P7: P14 | Q7: P14 | R7: P14 | S7: P14 | T7: P14 | U7: F | V7: F | W7: P06 | X7: P06 | Y7: H | Z7: P06 | AA7: F | AB7: F | AC7: P14 | AD7: P14 | AE7: P14 | AG7: =MAY!AJ7 -> 18 | AH7: =COUNTIF(B7:AE7,"U") -> 0 | AI7: =AG7-AH7 -> 18
A8: PAULO COSTA | B8: P06 | C8: F | D8: F | E8: H | F8: P14 | G8: P14 | H8: P14 | I8: F | J8: F | K8: H | L8: P06 | M8: P06 | N8: P06 | O8: F | P8: F | Q8: P14 | R8: P14 | S8: P14 | T8: P14 | U8: P14 | V8: F | W8: F | X8: P06 | Y8: P06 | Z8: P06 | AA8: P06 | AB8: F | AC8: F | AD8: P14 | AE8: P14 | AG8: =MAY!AJ8 -> 22 | AH8: =COUNTIF(B8:AE8,"U") -> 0 | AI8: =AG8-AH8 -> 22
A9: PEDRO SOARES | B9: P14 | C9: P14 | D9: P14 | E9: F | F9: F | G9: P06 | H9: P06 | I9: P06 | J9: P06 | K9: F | L9: F | M9: P14 | N9: P14 | O9: P14 | P9: P14 | Q9: F | R9: F | S9: P06 | T9: P06 | U9: P06 | V9: P06 | W9: P06 | X9: F | Y9: F | Z9: P14 | AA9: P14 | AB9: P14 | AC9: P14 | AD9: F | AE9: F | AG9: =MAY!AJ9 -> 22 | AH9: =COUNTIF(B9:AE9,"U") -> 0 | AI9: =AG9-AH9 -> 22
A10: JOSE ALEXANDRE FERREIRA | B10: F | C10: P06 | D10: P06 | E10: P06 | F10: P06 | G10: F | H10: F | I10: P14 | J10: P14 | K10: P14 | L10: P14 | M10: F | N10: F | O10: P06 | P10: P06 | Q10: P06 | R10: P06 | S10: P06 | T10: F | U10: F | V10: P14 | W10: P14 | X10: P14 | Y10: P14 | Z10: F | AA10: F | AB10: P06 | AC10: P06 | AD10: P06 | AE10: P06 | AG10: =MAY!AJ10 -> 22 | AH10: =COUNTIF(B10:AE10,"U") -> 0 | AI10: =AG10-AH10 -> 22
A11: RICHARD JESUS | B11: P06 | C11: P06 | D11: P06 | E11: H | F11: F | G11: F | H11: P14 | I11: P14 | J11: P14 | K11: H | L11: F | M11: F | N11: P06 | O11: P06 | P11: P06 | Q11: P06 | R11: P06 | S11: F | T11: F | U11: P14 | V11: P14 | W11: P14 | X11: P14 | Y11: F | Z11: F | AA11: P06 | AB11: P06 | AC11: P06 | AD11: P06 | AE11: F | AG11: =MAY!AJ11 -> 22 | AH11: =COUNTIF(B11:AE11,"U") -> 0 | AI11: =AG11-AH11 -> 22
A13: Total P06 | B13: =COUNTIF(B4:B11,"P06") -> 2 | C13: =COUNTIF(C4:C11,"P06") -> 2 | D13: =COUNTIF(D4:D11,"P06") -> 2 | E13: =COUNTIF(E4:E11,"P06") -> 1 | F13: =COUNTIF(F4:F11,"P06") -> 1 | G13: =COUNTIF(G4:G11,"P06") -> 1 | H13: =COUNTIF(H4:H11,"P06") -> 1 | I13: =COUNTIF(I4:I11,"P06") -> 1 | ... AE13: =COUNTIF(AE4:AE11,"P06") -> 1
A14: Total P14 | B14: =COUNTIF(B4:B11,"P14") -> 1 | C14: =COUNTIF(C4:C11,"P14") -> 1 | D14: =COUNTIF(D4:D11,"P14") -> 2 | E14: =COUNTIF(E4:E11,"P14") -> 1 | F14: =COUNTIF(F4:F11,"P14") -> 2 | G14: =COUNTIF(G4:G11,"P14") -> 2 | H14: =COUNTIF(H4:H11,"P14") -> 2 | I14: =COUNTIF(I4:I11,"P14") -> 2 | ... AE14: =COUNTIF(AE4:AE11,"P14") -> 2
F16: Horario | H16: Pausa | M16: F | N16: Folga | S16: FJ | T16: Falta Justificada | Z16: Provisório
E17: P06 | F17: 06:00-14:00 | H17: 10:00-10:30 | M17: A | N17: Folga de compensacao | S17: FINJ | T17: Falta Injustificada
E18: P08 | F18: 08:00-16:00 | H18: 12:00-12:30 | M18: H | N18: Feriado | S18: M | T18: Licenca
E19: P09 | F19: 09:00-17:00 | H19: 13:00-13:30 | M19: U | N19: Ferias | S19: P | T19: Licenca
E20: P14 | F20: 14:00-22:00 | H20: 18:00-18:30 | M20: UA | N20: Ferias do ano anterior | S20: S1 | T20: Licenca
E21: P22 | F21: 22:00-06:00 | H21: 02:00-02:30 | M21: H | N21: Feriado nao aprovado | S21: K | T21: Ausente
M22: U | N22: Dia de ferias nao aprovado | S22: K1 | T22: Ausente
M23: B | N23: Birthday | S23: K2 | T23: Ausente
M24: B* | N24: Birthday - dia alternativo | S24: K6 | T24: Ausente
M25: TR | N25: Training | S25: E | T25: Ausente
M26: S3 | N26: Ausencia Especial | S26: EM | T26: Ausente
M27: TB | N27: Team Building | S27: J | T27: Ausente
M28: R | N28: Viagem em Servico | S28: NO | T28: Ausente
M29: D | N29: Viagem em Servico Alemanha | S29: CM1 | T29: Ausente
M30: SE | N30: Servico Especial | S30: V | T30: Solidariedade

Sheet JUL
A1: LGSP - Lufthansa Ground Services Portugal NIF : 509 842 593 Atividade: CAE 52230.R3 Sede e local de trabalho: Avenida da Boavista ED.Burgo, 1837 sala 13.4/ Horario de Funcionamento: 24/7 IRT : Nao Aplicavel
A2: 46204 | B2: =IF(COLUMN(A1)<=DAY(EOMONTH($A$2,0)),COLUMN(A1),"") -> 1 | C2: =IF(COLUMN(B1)<=DAY(EOMONTH($A$2,0)),COLUMN(B1),"") -> 2 | D2: =IF(COLUMN(C1)<=DAY(EOMONTH($A$2,0)),COLUMN(C1),"") -> 3 | E2: =IF(COLUMN(D1)<=DAY(EOMONTH($A$2,0)),COLUMN(D1),"") -> 4 | F2: =IF(COLUMN(E1)<=DAY(EOMONTH($A$2,0)),COLUMN(E1),"") -> 5 | G2: =IF(COLUMN(F1)<=DAY(EOMONTH($A$2,0)),COLUMN(F1),"") -> 6 | H2: =IF(COLUMN(G1)<=DAY(EOMONTH($A$2,0)),COLUMN(G1),"") -> 7 | I2: =IF(COLUMN(H1)<=DAY(EOMONTH($A$2,0)),COLUMN(H1),"") -> 8 | ... AF2: =IF(COLUMN(AE1)<=DAY(EOMONTH($A$2,0)),COLUMN(AE1),"") -> 31 | AH2: Ferias 2026
B3: =UPPER(LEFT(TEXT(DATE(YEAR($A$2),MONTH($A$2),B2),"DDD"),2)) -> WE | C3: =UPPER(LEFT(TEXT(DATE(YEAR($A$2),MONTH($A$2),C2),"DDD"),2)) -> TH | D3: =UPPER(LEFT(TEXT(DATE(YEAR($A$2),MONTH($A$2),D2),"DDD"),2)) -> FR | E3: =UPPER(LEFT(TEXT(DATE(YEAR($A$2),MONTH($A$2),E2),"DDD"),2)) -> SA | F3: =UPPER(LEFT(TEXT(DATE(YEAR($A$2),MONTH($A$2),F2),"DDD"),2)) -> SU | G3: =UPPER(LEFT(TEXT(DATE(YEAR($A$2),MONTH($A$2),G2),"DDD"),2)) -> MO | H3: =UPPER(LEFT(TEXT(DATE(YEAR($A$2),MONTH($A$2),H2),"DDD"),2)) -> TU | I3: =UPPER(LEFT(TEXT(DATE(YEAR($A$2),MONTH($A$2),I2),"DDD"),2)) -> WE | ... AF3: =UPPER(LEFT(TEXT(DATE(YEAR($A$2),MONTH($A$2),AF2),"DDD"),2)) -> FR | AH3: 2026 | AI3: Used | AJ3: Left
A4: LUISA TAVARES | B4: P08 | C4: P08 | D4: P08 | E4: F | F4: F | G4: P08 | H4: P08 | I4: P08 | J4: P08 | K4: P08 | L4: F | M4: F | N4: P08 | O4: P08 | P4: P08 | Q4: P08 | R4: P08 | S4: F | T4: F | U4: P08 | V4: P08 | W4: P08 | X4: P08 | Y4: P08 | Z4: F | AA4: F | AB4: P08 | AC4: P08 | AD4: P08 | AE4: P08 | AF4: P08 | AH4: =JUN!AI4 -> 22 | AI4: =COUNTIF(B4:AF4,"U") -> 0 | AJ4: =AH4-AI4 -> 22
A5: FABIO FILIPE PEREIRA | B5: P09 | C5: P09 | D5: P09 | E5: F | F5: F | G5: P09 | H5: P09 | I5: P09 | J5: P09 | K5: P09 | L5: F | M5: F | N5: P09 | O5: P09 | P5: P09 | Q5: P09 | R5: P09 | S5: F | T5: F | U5: P09 | V5: P09 | W5: P09 | X5: P09 | Y5: P09 | Z5: F | AA5: F | AB5: P09 | AC5: P09 | AD5: P09 | AE5: P09 | AF5: P09 | AH5: =JUN!AI5 -> 22 | AI5: =COUNTIF(B5:AF5,"U") -> 0 | AJ5: =AH5-AI5 -> 22
A6: ARNOLD LUANZAMBI | B6: P09 | C6: P09 | D6: P09 | E6: F | F6: F | G6: P09 | H6: P09 | I6: P09 | J6: P09 | K6: P09 | L6: F | M6: F | N6: P09 | O6: P09 | P6: P09 | Q6: P09 | R6: P09 | S6: F | T6: F | U6: P09 | V6: P09 | W6: P09 | X6: P09 | Y6: P09 | Z6: F | AA6: F | AB6: P09 | AC6: P09 | AD6: P09 | AE6: P09 | AF6: P09 | AH6: =JUN!AI6 -> 19 | AI6: =COUNTIF(B6:AF6,"U") -> 0 | AJ6: =AH6-AI6 -> 19
A7: BEATRIZ SEIXAS | B7: P14 | C7: F | D7: F | E7: P06 | F7: P06 | G7: P06 | H7: P06 | I7: F | J7: F | K7: P14 | L7: P14 | M7: P14 | N7: P14 | O7: P14 | P7: F | Q7: F | R7: P06 | S7: P06 | T7: P06 | U7: P06 | V7: F | W7: F | X7: P14 | Y7: P14 | Z7: P14 | AA7: P14 | AB7: F | AC7: F | AD7: P06 | AE7: P06 | AF7: P06 | AH7: =JUN!AI7 -> 18 | AI7: =COUNTIF(B7:AF7,"U") -> 0 | AJ7: =AH7-AI7 -> 18
A8: PAULO COSTA | B8: P14 | C8: P14 | D8: P14 | E8: F | F8: F | G8: P06 | H8: P06 | I8: P06 | J8: P06 | K8: P06 | L8: F | M8: F | N8: P14 | O8: P14 | P8: P14 | Q8: P14 | R8: F | S8: F | T8: P06 | U8: P06 | V8: P06 | W8: P06 | X8: P06 | Y8: F | Z8: F | AA8: P14 | AB8: P14 | AC8: P14 | AD8: P14 | AE8: F | AF8: F | AH8: =JUN!AI8 -> 22 | AI8: =COUNTIF(B8:AF8,"U") -> 0 | AJ8: =AH8-AI8 -> 22
A9: PEDRO SOARES | B9: P06 | C9: P06 | D9: P06 | E9: P06 | F9: F | G9: F | H9: P14 | I9: P14 | J9: P14 | K9: P14 | L9: F | M9: F | N9: P06 | O9: P06 | P9: P06 | Q9: P06 | R9: P06 | S9: F | T9: F | U9: P14 | V9: P14 | W9: P14 | X9: P14 | Y9: F | Z9: F | AA9: P06 | AB9: P06 | AC9: P06 | AD9: P06 | AE9: F | AF9: F | AH9: =JUN!AI9 -> 22 | AI9: =COUNTIF(B9:AF9,"U") -> 0 | AJ9: =AH9-AI9 -> 22
A10: JOSE ALEXANDRE FERREIRA | B10: F | C10: F | D10: P14 | E10: P14 | F10: P14 | G10: P14 | H10: P14 | I10: F | J10: F | K10: P06 | L10: P06 | M10: P06 | N10: P06 | O10: F | P10: F | Q10: P14 | R10: P14 | S10: P14 | T10: P14 | U10: F | V10: F | W10: P06 | X10: P06 | Y10: P06 | Z10: P06 | AA10: P06 | AB10: F | AC10: F | AD10: P14 | AE10: P14 | AF10: P14 | AH10: =JUN!AI10 -> 22 | AI10: =COUNTIF(B10:AF10,"U") -> 0 | AJ10: =AH10-AI10 -> 22
A11: RICHARD JESUS | B11: F | C11: P06 | D11: P06 | E11: P06 | F11: P06 | G11: F | H11: F | I11: P14 | J11: P14 | K11: P14 | L11: P14 | M11: P14 | N11: F | O11: F | P11: P06 | Q11: P06 | R11: P06 | S11: P06 | T11: F | U11: F | V11: P14 | W11: P14 | X11: P14 | Y11: P14 | Z11: F | AA11: F | AB11: P06 | AC11: P06 | AD11: P06 | AE11: P06 | AF11: P06 | AH11: =JUN!AI11 -> 22 | AI11: =COUNTIF(B11:AF11,"U") -> 0 | AJ11: =AH11-AI11 -> 22
A13: Total P06 | B13: =COUNTIF(B4:B11,"P06") -> 1 | C13: =COUNTIF(C4:C11,"P06") -> 2 | D13: =COUNTIF(D4:D11,"P06") -> 2 | E13: =COUNTIF(E4:E11,"P06") -> 3 | F13: =COUNTIF(F4:F11,"P06") -> 2 | G13: =COUNTIF(G4:G11,"P06") -> 2 | H13: =COUNTIF(H4:H11,"P06") -> 2 | I13: =COUNTIF(I4:I11,"P06") -> 1 | ... AF13: =COUNTIF(AF4:AF11,"P06") -> 2
A14: Total P14 | B14: =COUNTIF(B4:B11,"P14") -> 2 | C14: =COUNTIF(C4:C11,"P14") -> 1 | D14: =COUNTIF(D4:D11,"P14") -> 2 | E14: =COUNTIF(E4:E11,"P14") -> 1 | F14: =COUNTIF(F4:F11,"P14") -> 1 | G14: =COUNTIF(G4:G11,"P14") -> 1 | H14: =COUNTIF(H4:H11,"P14") -> 2 | I14: =COUNTIF(I4:I11,"P14") -> 2 | ... AF14: =COUNTIF(AF4:AF11,"P14") -> 1
F16: Horario | H16: Pausa | M16: F | N16: Folga | S16: FJ | T16: Falta Justificada | Z16: Provisório
E17: P06 | F17: 06:00-14:00 | H17: 10:00-10:30 | M17: A | N17: Folga de compensacao | S17: FINJ | T17: Falta Injustificada
E18: P08 | F18: 08:00-16:00 | H18: 12:00-12:30 | M18: H | N18: Feriado | S18: M | T18: Licenca
E19: P09 | F19: 09:00-17:00 | H19: 13:00-13:30 | M19: U | N19: Ferias | S19: P | T19: Licenca
E20: P14 | F20: 14:00-22:00 | H20: 18:00-18:30 | M20: UA | N20: Ferias do ano anterior | S20: S1 | T20: Licenca
E21: P22 | F21: 22:00-06:00 | H21: 02:00-02:30 | M21: H | N21: Feriado nao aprovado | S21: K | T21: Ausente
M22: U | N22: Dia de ferias nao aprovado | S22: K1 | T22: Ausente
M23: B | N23: Birthday | S23: K2 | T23: Ausente
M24: B* | N24: Birthday - dia alternativo | S24: K6 | T24: Ausente
M25: TR | N25: Training | S25: E | T25: Ausente
M26: S3 | N26: Ausencia Especial | S26: EM | T26: Ausente
M27: TB | N27: Team Building | S27: J | T27: Ausente
M28: R | N28: Viagem em Servico | S28: NO | T28: Ausente
M29: D | N29: Viagem em Servico Alemanha | S29: CM1 | T29: Ausente
M30: SE | N30: Servico Especial | S30: V | T30: Solidariedade

Sheet AUG
A1: LGSP - Lufthansa Ground Services Portugal NIF : 509 842 593 Atividade: CAE 52230.R3 Sede e local de trabalho: Avenida da Boavista ED.Burgo, 1837 sala 13.4/ Horario de Funcionamento: 24/7 IRT : Nao Aplicavel
A2: 46235 | B2: =IF(COLUMN(A1)<=DAY(EOMONTH($A$2,0)),COLUMN(A1),"") -> 1 | C2: =IF(COLUMN(B1)<=DAY(EOMONTH($A$2,0)),COLUMN(B1),"") -> 2 | D2: =IF(COLUMN(C1)<=DAY(EOMONTH($A$2,0)),COLUMN(C1),"") -> 3 | E2: =IF(COLUMN(D1)<=DAY(EOMONTH($A$2,0)),COLUMN(D1),"") -> 4 | F2: =IF(COLUMN(E1)<=DAY(EOMONTH($A$2,0)),COLUMN(E1),"") -> 5 | G2: =IF(COLUMN(F1)<=DAY(EOMONTH($A$2,0)),COLUMN(F1),"") -> 6 | H2: =IF(COLUMN(G1)<=DAY(EOMONTH($A$2,0)),COLUMN(G1),"") -> 7 | I2: =IF(COLUMN(H1)<=DAY(EOMONTH($A$2,0)),COLUMN(H1),"") -> 8 | ... AF2: =IF(COLUMN(AE1)<=DAY(EOMONTH($A$2,0)),COLUMN(AE1),"") -> 31 | AH2: Ferias 2026
B3: =UPPER(LEFT(TEXT(DATE(YEAR($A$2),MONTH($A$2),B2),"DDD"),2)) -> SA | C3: =UPPER(LEFT(TEXT(DATE(YEAR($A$2),MONTH($A$2),C2),"DDD"),2)) -> SU | D3: =UPPER(LEFT(TEXT(DATE(YEAR($A$2),MONTH($A$2),D2),"DDD"),2)) -> MO | E3: =UPPER(LEFT(TEXT(DATE(YEAR($A$2),MONTH($A$2),E2),"DDD"),2)) -> TU | F3: =UPPER(LEFT(TEXT(DATE(YEAR($A$2),MONTH($A$2),F2),"DDD"),2)) -> WE | G3: =UPPER(LEFT(TEXT(DATE(YEAR($A$2),MONTH($A$2),G2),"DDD"),2)) -> TH | H3: =UPPER(LEFT(TEXT(DATE(YEAR($A$2),MONTH($A$2),H2),"DDD"),2)) -> FR | I3: =UPPER(LEFT(TEXT(DATE(YEAR($A$2),MONTH($A$2),I2),"DDD"),2)) -> SA | ... AF3: =UPPER(LEFT(TEXT(DATE(YEAR($A$2),MONTH($A$2),AF2),"DDD"),2)) -> MO | AH3: 2026 | AI3: Used | AJ3: Left
A4: LUISA TAVARES | B4: F | C4: F | D4: P08 | E4: P08 | F4: P08 | G4: P08 | H4: P08 | I4: F | J4: F | K4: P08 | L4: P08 | M4: P08 | N4: P08 | O4: P08 | P4: F | Q4: F | R4: P08 | S4: P08 | T4: P08 | U4: P08 | V4: P08 | W4: F | X4: F | Y4: P08 | Z4: P08 | AA4: P08 | AB4: P08 | AC4: P08 | AD4: F | AE4: F | AF4: P08 | AH4: =JUL!AJ4 -> 22 | AI4: =COUNTIF(B4:AF4,"U") -> 0 | AJ4: =AH4-AI4 -> 22
A5: FABIO FILIPE PEREIRA | B5: F | C5: F | D5: P09 | E5: P09 | F5: P09 | G5: P09 | H5: P09 | I5: F | J5: F | K5: P09 | L5: P09 | M5: P09 | N5: P09 | O5: P09 | P5: F | Q5: F | R5: P09 | S5: P09 | T5: P09 | U5: P09 | V5: P09 | W5: F | X5: F | Y5: P09 | Z5: P09 | AA5: P09 | AB5: P09 | AC5: P09 | AD5: F | AE5: F | AF5: P09 | AH5: =JUL!AJ5 -> 22 | AI5: =COUNTIF(B5:AF5,"U") -> 0 | AJ5: =AH5-AI5 -> 22
A6: ARNOLD LUANZAMBI | B6: F | C6: F | D6: P09 | E6: P09 | F6: P09 | G6: P09 | H6: P09 | I6: F | J6: F | K6: P09 | L6: P09 | M6: P09 | N6: P09 | O6: P09 | P6: F | Q6: F | R6: P09 | S6: P09 | T6: P09 | U6: P09 | V6: P09 | W6: F | X6: F | Y6: P09 | Z6: P09 | AA6: P09 | AB6: P09 | AC6: P09 | AD6: F | AE6: F | AF6: P09 | AH6: =JUL!AJ6 -> 19 | AI6: =COUNTIF(B6:AF6,"U") -> 0 | AJ6: =AH6-AI6 -> 19
A7: BEATRIZ SEIXAS | B7: P06 | C7: P06 | D7: F | E7: F | F7: P14 | G7: P14 | H7: P14 | I7: P14 | J7: F | K7: F | L7: P06 | M7: P06 | N7: P06 | O7: P06 | P7: F | Q7: F | R7: P14 | S7: P14 | T7: P14 | U7: P14 | V7: P14 | W7: F | X7: F | Y7: P06 | Z7: P06 | AA7: P06 | AB7: P06 | AC7: F | AD7: F | AE7: P14 | AF7: P14 | AH7: =JUL!AJ7 -> 18 | AI7: =COUNTIF(B7:AF7,"U") -> 0 | AJ7: =AH7-AI7 -> 18
A8: PAULO COSTA | B8: P06 | C8: P06 | D8: P06 | E8: P06 | F8: F | G8: F | H8: P14 | I8: P14 | J8: P14 | K8: P14 | L8: P14 | M8: F | N8: F | O8: P06 | P8: P06 | Q8: P06 | R8: P06 | S8: F | T8: F | U8: P14 | V8: P14 | W8: P14 | X8: P14 | Y8: F | Z8: F | AA8: P06 | AB8: P06 | AC8: P06 | AD8: P06 | AE8: P06 | AF8: F | AH8: =JUL!AJ8 -> 22 | AI8: =COUNTIF(B8:AF8,"U") -> 0 | AJ8: =AH8-AI8 -> 22
A9: PEDRO SOARES | B9: P14 | C9: P14 | D9: P14 | E9: P14 | F9: F | G9: F | H9: P06 | I9: P06 | J9: P06 | K9: P06 | L9: F | M9: F | N9: P14 | O9: P14 | P9: P14 | Q9: P14 | R9: F | S9: F | T9: P06 | U9: P06 | V9: P06 | W9: P06 | X9: P06 | Y9: F | Z9: F | AA9: P14 | AB9: P14 | AC9: P14 | AD9: P14 | AE9: F | AF9: F | AH9: =JUL!AJ9 -> 22 | AI9: =COUNTIF(B9:AF9,"U") -> 0 | AJ9: =AH9-AI9 -> 22
A10: JOSE ALEXANDRE FERREIRA | B10: P14 | C10: F | D10: F | E10: P06 | F10: P06 | G10: P06 | H10: P06 | I10: F | J10: F | K10: P14 | L10: P14 | M10: P14 | N10: P14 | O10: P14 | P10: F | Q10: F | R10: P06 | S10: P06 | T10: P06 | U10: P06 | V10: F | W10: F | X10: P14 | Y10: P14 | Z10: P14 | AA10: P14 | AB10: F | AC10: F | AD10: P06 | AE10: P06 | AF10: P06 | AH10: =JUL!AJ10 -> 22 | AI10: =COUNTIF(B10:AF10,"U") -> 0 | AJ10: =AH10-AI10 -> 22
A11: RICHARD JESUS | B11: F | C11: F | D11: P14 | E11: P14 | F11: P14 | G11: P14 | H11: F | I11: F | J11: P06 | K11: P06 | L11: P06 | M11: P06 | N11: P06 | O11: F | P11: F | Q11: P14 | R11: P14 | S11: P14 | T11: P14 | U11: F | V11: F | W11: P06 | X11: P06 | Y11: P06 | Z11: P06 | AA11: F | AB11: F | AC11: P14 | AD11: P14 | AE11: P14 | AF11: P14 | AH11: =JUL!AJ11 -> 22 | AI11: =COUNTIF(B11:AF11,"U") -> 0 | AJ11: =AH11-AI11 -> 22
A13: Total P06 | B13: =COUNTIF(B4:B11,"P06") -> 2 | C13: =COUNTIF(C4:C11,"P06") -> 2 | D13: =COUNTIF(D4:D11,"P06") -> 1 | E13: =COUNTIF(E4:E11,"P06") -> 2 | F13: =COUNTIF(F4:F11,"P06") -> 1 | G13: =COUNTIF(G4:G11,"P06") -> 1 | H13: =COUNTIF(H4:H11,"P06") -> 2 | I13: =COUNTIF(I4:I11,"P06") -> 1 | ... AF13: =COUNTIF(AF4:AF11,"P06") -> 1
A14: Total P14 | B14: =COUNTIF(B4:B11,"P14") -> 2 | C14: =COUNTIF(C4:C11,"P14") -> 1 | D14: =COUNTIF(D4:D11,"P14") -> 2 | E14: =COUNTIF(E4:E11,"P14") -> 2 | F14: =COUNTIF(F4:F11,"P14") -> 2 | G14: =COUNTIF(G4:G11,"P14") -> 2 | H14: =COUNTIF(H4:H11,"P14") -> 2 | I14: =COUNTIF(I4:I11,"P14") -> 2 | ... AF14: =COUNTIF(AF4:AF11,"P14") -> 2
F16: Horario | H16: Pausa | M16: F | N16: Folga | S16: FJ | T16: Falta Justificada | Z16: Provisório
E17: P06 | F17: 06:00-14:00 | H17: 10:00-10:30 | M17: A | N17: Folga de compensacao | S17: FINJ | T17: Falta Injustificada
E18: P08 | F18: 08:00-16:00 | H18: 12:00-12:30 | M18: H | N18: Feriado | S18: M | T18: Licenca
E19: P09 | F19: 09:00-17:00 | H19: 13:00-13:30 | M19: U | N19: Ferias | S19: P | T19: Licenca
E20: P14 | F20: 14:00-22:00 | H20: 18:00-18:30 | M20: UA | N20: Ferias do ano anterior | S20: S1 | T20: Licenca
E21: P22 | F21: 22:00-06:00 | H21: 02:00-02:30 | M21: H | N21: Feriado nao aprovado | S21: K | T21: Ausente
M22: U | N22: Dia de ferias nao aprovado | S22: K1 | T22: Ausente
M23: B | N23: Birthday | S23: K2 | T23: Ausente
M24: B* | N24: Birthday - dia alternativo | S24: K6 | T24: Ausente
M25: TR | N25: Training | S25: E | T25: Ausente
M26: S3 | N26: Ausencia Especial | S26: EM | T26: Ausente
M27: TB | N27: Team Building | S27: J | T27: Ausente
M28: R | N28: Viagem em Servico | S28: NO | T28: Ausente
M29: D | N29: Viagem em Servico Alemanha | S29: CM1 | T29: Ausente
M30: SE | N30: Servico Especial | S30: V | T30: Solidariedade

Sheet SEP
A1: LGSP - Lufthansa Ground Services Portugal NIF : 509 842 593 Atividade: CAE 52230.R3 Sede e local de trabalho: Avenida da Boavista ED.Burgo, 1837 sala 13.4/ Horario de Funcionamento: 24/7 IRT : Nao Aplicavel
A2: 46266 | B2: =IF(COLUMN(A1)<=DAY(EOMONTH($A$2,0)),COLUMN(A1),"") -> 1 | C2: =IF(COLUMN(B1)<=DAY(EOMONTH($A$2,0)),COLUMN(B1),"") -> 2 | D2: =IF(COLUMN(C1)<=DAY(EOMONTH($A$2,0)),COLUMN(C1),"") -> 3 | E2: =IF(COLUMN(D1)<=DAY(EOMONTH($A$2,0)),COLUMN(D1),"") -> 4 | F2: =IF(COLUMN(E1)<=DAY(EOMONTH($A$2,0)),COLUMN(E1),"") -> 5 | G2: =IF(COLUMN(F1)<=DAY(EOMONTH($A$2,0)),COLUMN(F1),"") -> 6 | H2: =IF(COLUMN(G1)<=DAY(EOMONTH($A$2,0)),COLUMN(G1),"") -> 7 | I2: =IF(COLUMN(H1)<=DAY(EOMONTH($A$2,0)),COLUMN(H1),"") -> 8 | ... AE2: =IF(COLUMN(AD1)<=DAY(EOMONTH($A$2,0)),COLUMN(AD1),"") -> 30 | AG2: Ferias 2026
B3: =UPPER(LEFT(TEXT(DATE(YEAR($A$2),MONTH($A$2),B2),"DDD"),2)) -> TU | C3: =UPPER(LEFT(TEXT(DATE(YEAR($A$2),MONTH($A$2),C2),"DDD"),2)) -> WE | D3: =UPPER(LEFT(TEXT(DATE(YEAR($A$2),MONTH($A$2),D2),"DDD"),2)) -> TH | E3: =UPPER(LEFT(TEXT(DATE(YEAR($A$2),MONTH($A$2),E2),"DDD"),2)) -> FR | F3: =UPPER(LEFT(TEXT(DATE(YEAR($A$2),MONTH($A$2),F2),"DDD"),2)) -> SA | G3: =UPPER(LEFT(TEXT(DATE(YEAR($A$2),MONTH($A$2),G2),"DDD"),2)) -> SU | H3: =UPPER(LEFT(TEXT(DATE(YEAR($A$2),MONTH($A$2),H2),"DDD"),2)) -> MO | I3: =UPPER(LEFT(TEXT(DATE(YEAR($A$2),MONTH($A$2),I2),"DDD"),2)) -> TU | ... AE3: =UPPER(LEFT(TEXT(DATE(YEAR($A$2),MONTH($A$2),AE2),"DDD"),2)) -> WE | AG3: 2026 | AH3: Used | AI3: Left
A4: LUISA TAVARES | B4: P08 | C4: P08 | D4: P08 | E4: P08 | F4: F | G4: F | H4: P08 | I4: P08 | J4: P08 | K4: P08 | L4: P08 | M4: F | N4: F | O4: P08 | P4: P08 | Q4: P08 | R4: P08 | S4: P08 | T4: F | U4: F | V4: P08 | W4: P08 | X4: P08 | Y4: P08 | Z4: P08 | AA4: F | AB4: F | AC4: P08 | AD4: P08 | AE4: P08 | AG4: =AUG!AJ4 -> 22 | AH4: =COUNTIF(B4:AE4,"U") -> 0 | AI4: =AG4-AH4 -> 22
A5: FABIO FILIPE PEREIRA | B5: P09 | C5: P09 | D5: P09 | E5: P09 | F5: F | G5: F | H5: P09 | I5: P09 | J5: P09 | K5: P09 | L5: P09 | M5: F | N5: F | O5: P09 | P5: P09 | Q5: P09 | R5: B | S5: P09 | T5: F | U5: F | V5: P09 | W5: P09 | X5: P09 | Y5: P09 | Z5: P09 | AA5: F | AB5: F | AC5: P09 | AD5: P09 | AE5: P09 | AG5: =AUG!AJ5 -> 22 | AH5: =COUNTIF(B5:AE5,"U") -> 0 | AI5: =AG5-AH5 -> 22
A6: ARNOLD LUANZAMBI | B6: P09 | C6: P09 | D6: P09 | E6: P09 | F6: F | G6: F | H6: P09 | I6: P09 | J6: P09 | K6: P09 | L6: P09 | M6: F | N6: F | O6: P09 | P6: P09 | Q6: P09 | R6: P09 | S6: P09 | T6: F | U6: F | V6: P09 | W6: P09 | X6: P09 | Y6: P09 | Z6: P09 | AA6: F | AB6: F | AC6: P09 | AD6: P09 | AE6: P09 | AG6: =AUG!AJ6 -> 19 | AH6: =COUNTIF(B6:AE6,"U") -> 0 | AI6: =AG6-AH6 -> 19
A7: BEATRIZ SEIXAS | B7: P14 | C7: P14 | D7: F | E7: F | F7: P14 | G7: P14 | H7: P14 | I7: P14 | J7: F | K7: F | L7: P06 | M7: P06 | N7: P06 | O7: P06 | P7: F | Q7: F | R7: P14 | S7: P14 | T7: P14 | U7: P14 | V7: F | W7: F | X7: P06 | Y7: P06 | Z7: P06 | AA7: P06 | AB7: P06 | AC7: F | AD7: F | AE7: P14 | AG7: =AUG!AJ7 -> 18 | AH7: =COUNTIF(B7:AE7,"U") -> 0 | AI7: =AG7-AH7 -> 18
A8: PAULO COSTA | B8: F | C8: P14 | D8: P14 | E8: P14 | F8: P14 | G8: F | H8: F | I8: P06 | J8: P06 | K8: P06 | L8: P06 | M8: P06 | N8: F | O8: F | P8: P14 | Q8: P14 | R8: P14 | S8: P14 | T8: F | U8: F | V8: P06 | W8: P06 | X8: P06 | Y8: P06 | Z8: P06 | AA8: F | AB8: F | AC8: P14 | AD8: P14 | AE8: P14 | AG8: =AUG!AJ8 -> 22 | AH8: =COUNTIF(B8:AE8,"U") -> 0 | AI8: =AG8-AH8 -> 22
A9: PEDRO SOARES | B9: P06 | C9: P06 | D9: P06 | E9: P06 | F9: F | G9: F | H9: P14 | I9: P14 | J9: P14 | K9: P14 | L9: P14 | M9: F | N9: F | O9: P06 | P9: P06 | Q9: P06 | R9: P06 | S9: F | T9: F | U9: P14 | V9: P14 | W9: P14 | X9: P14 | Y9: F | Z9: F | AA9: P06 | AB9: P06 | AC9: P06 | AD9: P06 | AE9: P06 | AG9: =AUG!AJ9 -> 22 | AH9: =COUNTIF(B9:AE9,"U") -> 0 | AI9: =AG9-AH9 -> 22
A10: JOSE ALEXANDRE FERREIRA | B10: P06 | C10: P06 | D10: F | E10: F | F10: P06 | G10: P06 | H10: P06 | I10: P06 | J10: F | K10: F | L10: P14 | M10: P14 | N10: P14 | O10: P14 | P10: P14 | Q10: F | R10: F | S10: P06 | T10: P06 | U10: P06 | V10: P06 | W10: F | X10: F | Y10: P14 | Z10: P14 | AA10: P14 | AB10: P14 | AC10: P14 | AD10: F | AE10: F | AG10: =AUG!AJ10 -> 22 | AH10: =COUNTIF(B10:AE10,"U") -> 0 | AI10: =AG10-AH10 -> 22
A11: RICHARD JESUS | B11: F | C11: F | D11: P06 | E11: P06 | F11: P06 | G11: P06 | H11: P06 | I11: F | J11: F | K11: P14 | L11: P14 | M11: P14 | N11: P14 | O11: F | P11: F | Q11: P06 | R11: P06 | S11: P06 | T11: P06 | U11: F | V11: F | W11: P14 | X11: P14 | Y11: P14 | Z11: P14 | AA11: P14 | AB11: F | AC11: F | AD11: P06 | AE11: P06 | AG11: =AUG!AJ11 -> 22 | AH11: =COUNTIF(B11:AE11,"U") -> 0 | AI11: =AG11-AH11 -> 22
A13: Total P06 | B13: =COUNTIF(B4:B11,"P06") -> 2 | C13: =COUNTIF(C4:C11,"P06") -> 2 | D13: =COUNTIF(D4:D11,"P06") -> 2 | E13: =COUNTIF(E4:E11,"P06") -> 2 | F13: =COUNTIF(F4:F11,"P06") -> 2 | G13: =COUNTIF(G4:G11,"P06") -> 2 | H13: =COUNTIF(H4:H11,"P06") -> 2 | I13: =COUNTIF(I4:I11,"P06") -> 2 | ... AE13: =COUNTIF(AE4:AE11,"P06") -> 2
A14: Total P14 | B14: =COUNTIF(B4:B11,"P14") -> 1 | C14: =COUNTIF(C4:C11,"P14") -> 2 | D14: =COUNTIF(D4:D11,"P14") -> 1 | E14: =COUNTIF(E4:E11,"P14") -> 1 | F14: =COUNTIF(F4:F11,"P14") -> 2 | G14: =COUNTIF(G4:G11,"P14") -> 1 | H14: =COUNTIF(H4:H11,"P14") -> 2 | I14: =COUNTIF(I4:I11,"P14") -> 2 | ... AE14: =COUNTIF(AE4:AE11,"P14") -> 2
